[2025-08-01 09:08:55 +0000] [85123] [INFO] Starting gunicorn 23.0.0
[2025-08-01 09:08:55 +0000] [85123] [INFO] Listening at: http://127.0.0.1:8000 (85123)
[2025-08-01 09:08:55 +0000] [85123] [INFO] Using worker: sync
[2025-08-01 09:08:55 +0000] [85124] [INFO] Booting worker with pid: 85124
[2025-08-01 09:08:55 +0000] [85125] [INFO] Booting worker with pid: 85125
[2025-08-01 09:08:55 +0000] [85126] [INFO] Booting worker with pid: 85126
[2025-08-01 09:08:55 +0000] [85127] [INFO] Booting worker with pid: 85127
[2025-08-01 09:09:09 +0000] [85123] [INFO] Handling signal: int
[2025-08-01 09:09:09 +0000] [85124] [INFO] Worker exiting (pid: 85124)
[2025-08-01 09:09:09 +0000] [85125] [INFO] Worker exiting (pid: 85125)
[2025-08-01 09:09:09 +0000] [85126] [INFO] Worker exiting (pid: 85126)
[2025-08-01 09:09:09 +0000] [85127] [INFO] Worker exiting (pid: 85127)
[2025-08-01 09:09:10 +0000] [85123] [INFO] Shutting down: Master
[2025-08-01 09:09:15 +0000] [85132] [INFO] Starting gunicorn 23.0.0
[2025-08-01 09:09:15 +0000] [85132] [INFO] Listening at: http://127.0.0.1:8000 (85132)
[2025-08-01 09:09:15 +0000] [85132] [INFO] Using worker: sync
[2025-08-01 09:09:15 +0000] [85133] [INFO] Booting worker with pid: 85133
[2025-08-01 09:09:15 +0000] [85134] [INFO] Booting worker with pid: 85134
[2025-08-01 09:09:15 +0000] [85135] [INFO] Booting worker with pid: 85135
[2025-08-01 09:09:15 +0000] [85136] [INFO] Booting worker with pid: 85136
[2025-08-01 09:09:41 +0000] [85141] [INFO] Starting gunicorn 23.0.0
[2025-08-01 09:09:41 +0000] [85141] [ERROR] Connection in use: ('127.0.0.1', 8000)
[2025-08-01 09:09:41 +0000] [85141] [ERROR] connection to ('127.0.0.1', 8000) failed: [Errno 98] Address already in use
[2025-08-01 09:09:42 +0000] [85141] [ERROR] Connection in use: ('127.0.0.1', 8000)
[2025-08-01 09:09:42 +0000] [85141] [ERROR] connection to ('127.0.0.1', 8000) failed: [Errno 98] Address already in use
[2025-08-01 09:09:43 +0000] [85141] [ERROR] Connection in use: ('127.0.0.1', 8000)
[2025-08-01 09:09:43 +0000] [85141] [ERROR] connection to ('127.0.0.1', 8000) failed: [Errno 98] Address already in use
[2025-08-01 09:09:44 +0000] [85141] [ERROR] Connection in use: ('127.0.0.1', 8000)
[2025-08-01 09:09:44 +0000] [85141] [ERROR] connection to ('127.0.0.1', 8000) failed: [Errno 98] Address already in use
[2025-08-01 09:09:45 +0000] [85141] [ERROR] Connection in use: ('127.0.0.1', 8000)
[2025-08-01 09:09:45 +0000] [85141] [ERROR] connection to ('127.0.0.1', 8000) failed: [Errno 98] Address already in use
[2025-08-01 09:09:46 +0000] [85141] [ERROR] Can't connect to ('127.0.0.1', 8000)
[2025-08-01 09:19:47 +0000] [85132] [ERROR] Worker (pid:85135) was sent SIGHUP!
[2025-08-01 09:19:47 +0000] [86184] [INFO] Booting worker with pid: 86184
[2025-08-01 09:19:47 +0000] [85132] [ERROR] Worker (pid:85134) was sent SIGHUP!
[2025-08-01 09:19:47 +0000] [85132] [ERROR] Worker (pid:85136) was sent SIGHUP!
[2025-08-01 09:19:47 +0000] [85132] [ERROR] Worker (pid:85133) was sent SIGHUP!
[2025-08-01 09:19:47 +0000] [85132] [INFO] Handling signal: hup
[2025-08-01 09:19:47 +0000] [85132] [INFO] Hang up: Master
[2025-08-01 09:19:47 +0000] [86185] [INFO] Booting worker with pid: 86185
[2025-08-01 09:19:47 +0000] [86187] [INFO] Booting worker with pid: 86187
[2025-08-01 09:19:47 +0000] [86186] [INFO] Booting worker with pid: 86186
[2025-08-01 09:19:47 +0000] [86188] [INFO] Booting worker with pid: 86188
[2025-08-01 09:19:50 +0000] [86184] [INFO] Worker exiting (pid: 86184)
[2025-08-01 09:19:50 +0000] [85132] [ERROR] Worker (pid:86184) was sent SIGTERM!
[2025-08-01 10:56:39 +0000] [85132] [INFO] Handling signal: term
[2025-08-01 10:56:39 +0000] [86186] [INFO] Worker exiting (pid: 86186)
[2025-08-01 10:56:39 +0000] [86185] [INFO] Worker exiting (pid: 86185)
[2025-08-01 10:56:39 +0000] [86187] [INFO] Worker exiting (pid: 86187)
[2025-08-01 10:56:39 +0000] [86188] [INFO] Worker exiting (pid: 86188)
[2025-08-01 10:56:40 +0000] [85132] [INFO] Shutting down: Master
[2025-08-01 11:18:15 +0000] [93395] [INFO] Starting gunicorn 23.0.0
[2025-08-01 11:18:15 +0000] [93395] [INFO] Listening at: http://127.0.0.1:8000 (93395)
[2025-08-01 11:18:15 +0000] [93395] [INFO] Using worker: sync
[2025-08-01 11:18:15 +0000] [93396] [INFO] Booting worker with pid: 93396
[2025-08-01 11:18:15 +0000] [93397] [INFO] Booting worker with pid: 93397
[2025-08-01 11:18:15 +0000] [93398] [INFO] Booting worker with pid: 93398
[2025-08-01 11:18:15 +0000] [93399] [INFO] Booting worker with pid: 93399
[2025-08-01 13:21:17 +0000] [93395] [ERROR] Worker (pid:93397) was sent SIGHUP!
[2025-08-01 13:21:17 +0000] [93395] [ERROR] Worker (pid:93398) was sent SIGHUP!
[2025-08-01 13:21:17 +0000] [93395] [ERROR] Worker (pid:93399) was sent SIGHUP!
[2025-08-01 13:21:17 +0000] [93395] [ERROR] Worker (pid:93396) was sent SIGHUP!
[2025-08-01 13:21:17 +0000] [93395] [INFO] Handling signal: hup
[2025-08-01 13:21:17 +0000] [93395] [INFO] Hang up: Master
[2025-08-01 13:21:17 +0000] [102908] [INFO] Booting worker with pid: 102908
[2025-08-01 13:21:17 +0000] [102909] [INFO] Booting worker with pid: 102909
[2025-08-01 13:21:17 +0000] [102910] [INFO] Booting worker with pid: 102910
[2025-08-01 13:21:17 +0000] [102911] [INFO] Booting worker with pid: 102911
[2025-08-01 16:02:19 +0000] [93395] [INFO] Handling signal: term
[2025-08-01 16:02:19 +0000] [102911] [INFO] Worker exiting (pid: 102911)
[2025-08-01 16:02:19 +0000] [102910] [INFO] Worker exiting (pid: 102910)
[2025-08-01 16:02:19 +0000] [102909] [INFO] Worker exiting (pid: 102909)
100 31 252 50 ようき
108 95 31 252 50 ずぶとい
みず みず None ドラゴン じめん
False False
ノーマル ノーマル
1.0 0.9 1.1 1.0
215 152.0 181.8 161.70000000000002 137.0
22
130
フィールド補正:1.0
130
攻撃補正
防御補正
天候補正:1
タイプ一致
タイプ一致1.5
タイプ相性補正: 1.0
基本ダメージ
22 130 181.8 137.0
ん？
115
ダメ計終了
215 152.0 181.8 161.70000000000002 137.0
108
100 31 252 50 ようき
108 95 31 252 50 ずぶとい
みず みず None ドラゴン じめん
False False
ノーマル ノーマル
1.0 0.9 1.1 1.0
215 152.0 181.8 161.70000000000002 137.0
22
130
フィールド補正:1.0
130
攻撃補正
防御補正
天候補正:1
タイプ一致
タイプ一致1.5
タイプ相性補正: 1.0
基本ダメージ
22 130 152 162
あれ
82
ダメ計終了
215 152.0 181.8 161.70000000000002 137.0
108
100 31 252 50 ようき
108 95 31 252 50 ずぶとい
みず みず None ドラゴン じめん
False False
ノーマル ノーマル
1.0 0.9 1.1 1.0
215 152.0 181.8 161.70000000000002 137.0
22
130
フィールド補正:1.0
130
攻撃補正
防御補正
天候補正:1
タイプ一致
タイプ一致1.5
タイプ相性補正: 1.0
基本ダメージ
22 130 181.8 137.0
ん？
115
ダメ計終了
215 152.0 181.8 161.70000000000002 137.0
108
[2025-08-01 16:02:19 +0000] [102908] [INFO] Worker exiting (pid: 102908)
100 31 252 50 てれや
108 95 0 0 50 がんばりや
みず みず None ドラゴン じめん
False False
ノーマル ノーマル
1.0 1.0 1.0 1.0
215 152.0 202.0 100.0 90.0
22
130
フィールド補正:1.0
130
攻撃補正
防御補正
天候補正:1
タイプ一致
タイプ一致1.5
タイプ相性補正: 1.0
基本ダメージ
22 130 202.0 90.0
ん？
195
ダメ計終了
215 152.0 202.0 100.0 90.0
108
100 31 252 50 ようき
108 95 31 252 50 ずぶとい
みず みず None ドラゴン じめん
False False
ノーマル ノーマル
1.0 0.9 1.1 1.0
215 152.0 181.8 161.70000000000002 137.0
22
130
フィールド補正:1.0
130
攻撃補正
防御補正
天候補正:1
タイプ一致
タイプ一致1.5
タイプ相性補正: 1.0
基本ダメージ
22 130 181.8 137.0
ん？
115
ダメ計終了
215 152.0 181.8 161.70000000000002 137.0
108
100 31 252 50 ようき
108 95 0 0 50 ずぶとい
みず みず None ドラゴン じめん
False False
ノーマル ノーマル
1.0 0.9 1.1 1.0
215 152.0 181.8 110.00000000000001 90.0
22
130
フィールド補正:1.0
130
攻撃補正
防御補正
天候補正:1
タイプ一致
タイプ一致1.5
タイプ相性補正: 1.0
基本ダメージ
22 130 181.8 90.0
ん？
175
ダメ計終了
215 152.0 181.8 110.00000000000001 90.0
108
[2025-08-01 16:02:20 +0000] [93395] [INFO] Shutting down: Master
[2025-08-01 16:05:03 +0000] [114364] [INFO] Starting gunicorn 23.0.0
[2025-08-01 16:05:03 +0000] [114364] [INFO] Listening at: http://127.0.0.1:8000 (114364)
[2025-08-01 16:05:03 +0000] [114364] [INFO] Using worker: sync
[2025-08-01 16:05:03 +0000] [114365] [INFO] Booting worker with pid: 114365
[2025-08-01 16:05:03 +0000] [114366] [INFO] Booting worker with pid: 114366
[2025-08-01 16:05:03 +0000] [114367] [INFO] Booting worker with pid: 114367
[2025-08-01 16:05:03 +0000] [114368] [INFO] Booting worker with pid: 114368
[2025-08-01 16:09:19 +0000] [114364] [INFO] Handling signal: term
[2025-08-01 16:09:19 +0000] [114365] [INFO] Worker exiting (pid: 114365)
[2025-08-01 16:09:19 +0000] [114367] [INFO] Worker exiting (pid: 114367)
[2025-08-01 16:09:19 +0000] [114366] [INFO] Worker exiting (pid: 114366)
[2025-08-01 16:09:19 +0000] [114368] [INFO] Worker exiting (pid: 114368)
[2025-08-01 16:09:20 +0000] [114364] [INFO] Shutting down: Master
[2025-08-01 16:09:45 +0000] [115077] [INFO] Starting gunicorn 23.0.0
[2025-08-01 16:09:45 +0000] [115077] [INFO] Listening at: http://127.0.0.1:8000 (115077)
[2025-08-01 16:09:45 +0000] [115077] [INFO] Using worker: sync
[2025-08-01 16:09:45 +0000] [115078] [INFO] Booting worker with pid: 115078
[2025-08-01 16:09:45 +0000] [115079] [INFO] Booting worker with pid: 115079
[2025-08-01 16:09:45 +0000] [115080] [INFO] Booting worker with pid: 115080
[2025-08-01 16:09:45 +0000] [115081] [INFO] Booting worker with pid: 115081
[2025-08-01 16:12:39 +0000] [115077] [INFO] Handling signal: term
[2025-08-01 16:12:39 +0000] [115078] [INFO] Worker exiting (pid: 115078)
[2025-08-01 16:12:39 +0000] [115079] [INFO] Worker exiting (pid: 115079)
[2025-08-01 16:12:39 +0000] [115081] [INFO] Worker exiting (pid: 115081)
[2025-08-01 16:12:39 +0000] [115080] [INFO] Worker exiting (pid: 115080)
[2025-08-01 16:12:40 +0000] [115077] [INFO] Shutting down: Master
[2025-08-01 16:12:48 +0000] [115133] [INFO] Starting gunicorn 23.0.0
[2025-08-01 16:12:48 +0000] [115133] [INFO] Listening at: http://127.0.0.1:8000 (115133)
[2025-08-01 16:12:48 +0000] [115133] [INFO] Using worker: sync
[2025-08-01 16:12:48 +0000] [115134] [INFO] Booting worker with pid: 115134
[2025-08-01 16:12:48 +0000] [115135] [INFO] Booting worker with pid: 115135
[2025-08-01 16:12:48 +0000] [115136] [INFO] Booting worker with pid: 115136
[2025-08-01 16:12:48 +0000] [115137] [INFO] Booting worker with pid: 115137
[2025-08-01 16:26:04 +0000] [115133] [ERROR] Worker (pid:115137) was sent SIGHUP!
[2025-08-01 16:26:04 +0000] [115133] [ERROR] Worker (pid:115134) was sent SIGHUP!
[2025-08-01 16:26:04 +0000] [115133] [ERROR] Worker (pid:115135) was sent SIGHUP!
[2025-08-01 16:26:04 +0000] [115133] [ERROR] Worker (pid:115136) was sent SIGHUP!
[2025-08-01 16:26:04 +0000] [115892] [INFO] Booting worker with pid: 115892
[2025-08-01 16:26:04 +0000] [115133] [INFO] Handling signal: hup
[2025-08-01 16:26:04 +0000] [115133] [INFO] Hang up: Master
[2025-08-01 16:26:04 +0000] [115894] [INFO] Booting worker with pid: 115894
[2025-08-01 16:26:04 +0000] [115897] [INFO] Booting worker with pid: 115897
[2025-08-01 16:26:04 +0000] [115895] [INFO] Booting worker with pid: 115895
[2025-08-01 16:26:04 +0000] [115896] [INFO] Booting worker with pid: 115896
[2025-08-01 16:26:09 +0000] [115892] [INFO] Worker exiting (pid: 115892)
[2025-08-01 16:26:09 +0000] [115133] [ERROR] Worker (pid:115892) was sent SIGTERM!
[2025-08-02 06:26:15 +0000] [115133] [INFO] Handling signal: term
[2025-08-02 06:26:15 +0000] [115896] [INFO] Worker exiting (pid: 115896)
[2025-08-02 06:26:15 +0000] [115894] [INFO] Worker exiting (pid: 115894)
[2025-08-02 06:26:15 +0000] [115897] [INFO] Worker exiting (pid: 115897)
[2025-08-02 06:26:15 +0000] [115895] [INFO] Worker exiting (pid: 115895)
[2025-08-02 06:26:17 +0000] [115133] [INFO] Shutting down: Master
[2025-08-02 06:27:16 +0000] [175664] [INFO] Starting gunicorn 23.0.0
[2025-08-02 06:27:16 +0000] [175664] [INFO] Listening at: http://127.0.0.1:8000 (175664)
[2025-08-02 06:27:16 +0000] [175664] [INFO] Using worker: sync
[2025-08-02 06:27:16 +0000] [175665] [INFO] Booting worker with pid: 175665
[2025-08-02 06:27:16 +0000] [175666] [INFO] Booting worker with pid: 175666
[2025-08-02 06:27:16 +0000] [175667] [INFO] Booting worker with pid: 175667
[2025-08-02 06:27:16 +0000] [175668] [INFO] Booting worker with pid: 175668
[2025-08-02 07:02:55 +0000] [175664] [INFO] Handling signal: term
[2025-08-02 07:02:55 +0000] [175666] [INFO] Worker exiting (pid: 175666)
[2025-08-02 07:02:55 +0000] [175668] [INFO] Worker exiting (pid: 175668)
100 31 252 50 ようき
155 125 31 252 50 ずぶとい
みず みず None あく じめん
False False
ノーマル ノーマル
1.0 0.9 1.1 1.0
262 152.0 181.8 194.70000000000002 132.0
22
130
フィールド補正:1.0
130
攻撃補正
防御補正
天候補正:1
タイプ一致
タイプ一致1.5
タイプ相性補正: 2.0
基本ダメージ
22 130 181.8 132.0
ん？
240
ダメ計終了
262 152.0 181.8 194.70000000000002 132.0
155
[2025-08-02 07:02:55 +0000] [175665] [INFO] Worker exiting (pid: 175665)
100 31 252 50 ようき
155 125 31 252 50 ずぶとい
みず みず None あく じめん
False False
ノーマル ノーマル
1.0 0.9 1.1 1.0
262 152.0 181.8 194.70000000000002 132.0
22
130
フィールド補正:1.0
130
攻撃補正
防御補正
天候補正:1
タイプ一致
タイプ一致1.5
タイプ相性補正: 2.0
基本ダメージ
22 130 181.8 132.0
ん？
240
ダメ計終了
262 152.0 181.8 194.70000000000002 132.0
155
[2025-08-02 07:02:55 +0000] [175667] [INFO] Worker exiting (pid: 175667)
100 31 252 50 ようき
155 125 31 252 50 ずぶとい
ノーマル みず None あく じめん
False False
ノーマル ノーマル
1.0 0.9 1.1 1.0
262 152.0 181.8 194.70000000000002 132.0
22
130
フィールド補正:1.0
130
攻撃補正
防御補正
天候補正:1
タイプ一致1.0
タイプ相性補正: 1.0
基本ダメージ
22 130 181.8 132.0
ん？
80
ダメ計終了
262 152.0 181.8 194.70000000000002 132.0
155
[2025-08-02 07:02:56 +0000] [175664] [INFO] Shutting down: Master
[2025-08-02 07:04:06 +0000] [178578] [INFO] Starting gunicorn 23.0.0
[2025-08-02 07:04:06 +0000] [178578] [INFO] Listening at: http://127.0.0.1:8000 (178578)
[2025-08-02 07:04:06 +0000] [178578] [INFO] Using worker: sync
[2025-08-02 07:04:06 +0000] [178579] [INFO] Booting worker with pid: 178579
[2025-08-02 07:04:06 +0000] [178580] [INFO] Booting worker with pid: 178580
[2025-08-02 07:04:06 +0000] [178581] [INFO] Booting worker with pid: 178581
[2025-08-02 07:04:06 +0000] [178582] [INFO] Booting worker with pid: 178582
[2025-08-02 07:04:08,878] ERROR in app: Exception on / [GET]
Traceback (most recent call last):
  File "/home/pipohkr01/xcobs2/venv/lib/python3.11/site-packages/flask/app.py", line 1511, in wsgi_app
    response = self.full_dispatch_request()
               ^^^^^^^^^^^^^^^^^^^^^^^^^^^^
  File "/home/pipohkr01/xcobs2/venv/lib/python3.11/site-packages/flask/app.py", line 919, in full_dispatch_request
    rv = self.handle_user_exception(e)
         ^^^^^^^^^^^^^^^^^^^^^^^^^^^^^
  File "/home/pipohkr01/xcobs2/venv/lib/python3.11/site-packages/flask/app.py", line 917, in full_dispatch_request
    rv = self.dispatch_request()
         ^^^^^^^^^^^^^^^^^^^^^^^
  File "/home/pipohkr01/xcobs2/venv/lib/python3.11/site-packages/flask/app.py", line 902, in dispatch_request
    return self.ensure_sync(self.view_functions[rule.endpoint])(**view_args)  # type: ignore[no-any-return]
           ^^^^^^^^^^^^^^^^^^^^^^^^^^^^^^^^^^^^^^^^^^^^^^^^^^^^^^^^^^^^^^^^^
  File "/home/pipohkr01/xcobs2/dmg_clc/app.py", line 786, in index
    return render_template('cobs2.html', **context)
           ^^^^^^^^^^^^^^^^^^^^^^^^^^^^^^^^^^^^^^^^
  File "/home/pipohkr01/xcobs2/venv/lib/python3.11/site-packages/flask/templating.py", line 150, in render_template
    return _render(app, template, context)
           ^^^^^^^^^^^^^^^^^^^^^^^^^^^^^^^
  File "/home/pipohkr01/xcobs2/venv/lib/python3.11/site-packages/flask/templating.py", line 131, in _render
    rv = template.render(context)
         ^^^^^^^^^^^^^^^^^^^^^^^^
  File "/home/pipohkr01/xcobs2/venv/lib/python3.11/site-packages/jinja2/environment.py", line 1295, in render
    self.environment.handle_exception()
  File "/home/pipohkr01/xcobs2/venv/lib/python3.11/site-packages/jinja2/environment.py", line 942, in handle_exception
    raise rewrite_traceback_stack(source=source)
  File "/home/pipohkr01/xcobs2/dmg_clc/templates/cobs2.html", line 1, in top-level template code
    {% extends "base.html" %}
  File "/home/pipohkr01/xcobs2/dmg_clc/templates/base.html", line 56, in top-level template code
    {% block content %}{% endblock %}
    ^^^^^^^^^^^^^^^^^^^^^^^^^
  File "/home/pipohkr01/xcobs2/dmg_clc/templates/cobs2.html", line 6, in block 'content'
    {% include "partials/cobs2_content.html" %}
    ^^^^^^^^^^^^^^^^^^^^^^^^^
  File "/home/pipohkr01/xcobs2/venv/lib/python3.11/site-packages/jinja2/environment.py", line 942, in handle_exception
    raise rewrite_traceback_stack(source=source)
  File "/home/pipohkr01/xcobs2/dmg_clc/templates/partials/cobs2_content.html", line 160, in template
    <option  value="さみしがり"{% if char_At==’さみしがり’ %}selected{% endif %}>さみしがり</option>
    ^^^^^^^^^^^^^^^^^^^^^^^
jinja2.exceptions.TemplateSyntaxError: unexpected char '’' at 7172
[2025-08-02 07:04:21,436] ERROR in app: Exception on / [GET]
Traceback (most recent call last):
  File "/home/pipohkr01/xcobs2/venv/lib/python3.11/site-packages/flask/app.py", line 1511, in wsgi_app
    response = self.full_dispatch_request()
               ^^^^^^^^^^^^^^^^^^^^^^^^^^^^
  File "/home/pipohkr01/xcobs2/venv/lib/python3.11/site-packages/flask/app.py", line 919, in full_dispatch_request
    rv = self.handle_user_exception(e)
         ^^^^^^^^^^^^^^^^^^^^^^^^^^^^^
  File "/home/pipohkr01/xcobs2/venv/lib/python3.11/site-packages/flask/app.py", line 917, in full_dispatch_request
    rv = self.dispatch_request()
         ^^^^^^^^^^^^^^^^^^^^^^^
  File "/home/pipohkr01/xcobs2/venv/lib/python3.11/site-packages/flask/app.py", line 902, in dispatch_request
    return self.ensure_sync(self.view_functions[rule.endpoint])(**view_args)  # type: ignore[no-any-return]
           ^^^^^^^^^^^^^^^^^^^^^^^^^^^^^^^^^^^^^^^^^^^^^^^^^^^^^^^^^^^^^^^^^
  File "/home/pipohkr01/xcobs2/dmg_clc/app.py", line 786, in index
    return render_template('cobs2.html', **context)
           ^^^^^^^^^^^^^^^^^^^^^^^^^^^^^^^^^^^^^^^^
  File "/home/pipohkr01/xcobs2/venv/lib/python3.11/site-packages/flask/templating.py", line 150, in render_template
    return _render(app, template, context)
           ^^^^^^^^^^^^^^^^^^^^^^^^^^^^^^^
  File "/home/pipohkr01/xcobs2/venv/lib/python3.11/site-packages/flask/templating.py", line 131, in _render
    rv = template.render(context)
         ^^^^^^^^^^^^^^^^^^^^^^^^
  File "/home/pipohkr01/xcobs2/venv/lib/python3.11/site-packages/jinja2/environment.py", line 1295, in render
    self.environment.handle_exception()
  File "/home/pipohkr01/xcobs2/venv/lib/python3.11/site-packages/jinja2/environment.py", line 942, in handle_exception
    raise rewrite_traceback_stack(source=source)
  File "/home/pipohkr01/xcobs2/dmg_clc/templates/cobs2.html", line 1, in top-level template code
    {% extends "base.html" %}
  File "/home/pipohkr01/xcobs2/dmg_clc/templates/base.html", line 56, in top-level template code
    {% block content %}{% endblock %}
    ^^^^^^^^^^^^^^^^^^^^^^^^^
  File "/home/pipohkr01/xcobs2/dmg_clc/templates/cobs2.html", line 6, in block 'content'
    {% include "partials/cobs2_content.html" %}
    ^^^^^^^^^^^^^^^^^^^^^^^^^
  File "/home/pipohkr01/xcobs2/venv/lib/python3.11/site-packages/jinja2/environment.py", line 942, in handle_exception
    raise rewrite_traceback_stack(source=source)
  File "/home/pipohkr01/xcobs2/dmg_clc/templates/partials/cobs2_content.html", line 160, in template
    <option  value="さみしがり"{% if char_At==’さみしがり’ %}selected{% endif %}>さみしがり</option>
    ^^^^^^^^^^^^^^^^^^^^^^^
jinja2.exceptions.TemplateSyntaxError: unexpected char '’' at 7172
[2025-08-02 07:04:23,107] ERROR in app: Exception on / [GET]
Traceback (most recent call last):
  File "/home/pipohkr01/xcobs2/venv/lib/python3.11/site-packages/flask/app.py", line 1511, in wsgi_app
    response = self.full_dispatch_request()
               ^^^^^^^^^^^^^^^^^^^^^^^^^^^^
  File "/home/pipohkr01/xcobs2/venv/lib/python3.11/site-packages/flask/app.py", line 919, in full_dispatch_request
    rv = self.handle_user_exception(e)
         ^^^^^^^^^^^^^^^^^^^^^^^^^^^^^
  File "/home/pipohkr01/xcobs2/venv/lib/python3.11/site-packages/flask/app.py", line 917, in full_dispatch_request
    rv = self.dispatch_request()
         ^^^^^^^^^^^^^^^^^^^^^^^
  File "/home/pipohkr01/xcobs2/venv/lib/python3.11/site-packages/flask/app.py", line 902, in dispatch_request
    return self.ensure_sync(self.view_functions[rule.endpoint])(**view_args)  # type: ignore[no-any-return]
           ^^^^^^^^^^^^^^^^^^^^^^^^^^^^^^^^^^^^^^^^^^^^^^^^^^^^^^^^^^^^^^^^^
  File "/home/pipohkr01/xcobs2/dmg_clc/app.py", line 786, in index
    return render_template('cobs2.html', **context)
           ^^^^^^^^^^^^^^^^^^^^^^^^^^^^^^^^^^^^^^^^
  File "/home/pipohkr01/xcobs2/venv/lib/python3.11/site-packages/flask/templating.py", line 150, in render_template
    return _render(app, template, context)
           ^^^^^^^^^^^^^^^^^^^^^^^^^^^^^^^
  File "/home/pipohkr01/xcobs2/venv/lib/python3.11/site-packages/flask/templating.py", line 131, in _render
    rv = template.render(context)
         ^^^^^^^^^^^^^^^^^^^^^^^^
  File "/home/pipohkr01/xcobs2/venv/lib/python3.11/site-packages/jinja2/environment.py", line 1295, in render
    self.environment.handle_exception()
  File "/home/pipohkr01/xcobs2/venv/lib/python3.11/site-packages/jinja2/environment.py", line 942, in handle_exception
    raise rewrite_traceback_stack(source=source)
  File "/home/pipohkr01/xcobs2/dmg_clc/templates/cobs2.html", line 1, in top-level template code
    {% extends "base.html" %}
  File "/home/pipohkr01/xcobs2/dmg_clc/templates/base.html", line 56, in top-level template code
    {% block content %}{% endblock %}
    ^^^^^^^^^^^^^^^^^^^^^^^^^
  File "/home/pipohkr01/xcobs2/dmg_clc/templates/cobs2.html", line 6, in block 'content'
    {% include "partials/cobs2_content.html" %}
    ^^^^^^^^^^^^^^^^^^^^^^^^^
  File "/home/pipohkr01/xcobs2/venv/lib/python3.11/site-packages/jinja2/environment.py", line 942, in handle_exception
    raise rewrite_traceback_stack(source=source)
  File "/home/pipohkr01/xcobs2/dmg_clc/templates/partials/cobs2_content.html", line 160, in template
    <option  value="さみしがり"{% if char_At==’さみしがり’ %}selected{% endif %}>さみしがり</option>
    ^^^^^^^^^^^^^^^^^^^^^^^
jinja2.exceptions.TemplateSyntaxError: unexpected char '’' at 7172
[2025-08-02 07:08:55,455] ERROR in app: Exception on / [GET]
Traceback (most recent call last):
  File "/home/pipohkr01/xcobs2/venv/lib/python3.11/site-packages/flask/app.py", line 1511, in wsgi_app
    response = self.full_dispatch_request()
               ^^^^^^^^^^^^^^^^^^^^^^^^^^^^
  File "/home/pipohkr01/xcobs2/venv/lib/python3.11/site-packages/flask/app.py", line 919, in full_dispatch_request
    rv = self.handle_user_exception(e)
         ^^^^^^^^^^^^^^^^^^^^^^^^^^^^^
  File "/home/pipohkr01/xcobs2/venv/lib/python3.11/site-packages/flask/app.py", line 917, in full_dispatch_request
    rv = self.dispatch_request()
         ^^^^^^^^^^^^^^^^^^^^^^^
  File "/home/pipohkr01/xcobs2/venv/lib/python3.11/site-packages/flask/app.py", line 902, in dispatch_request
    return self.ensure_sync(self.view_functions[rule.endpoint])(**view_args)  # type: ignore[no-any-return]
           ^^^^^^^^^^^^^^^^^^^^^^^^^^^^^^^^^^^^^^^^^^^^^^^^^^^^^^^^^^^^^^^^^
  File "/home/pipohkr01/xcobs2/dmg_clc/app.py", line 786, in index
    return render_template('cobs2.html', **context)
           ^^^^^^^^^^^^^^^^^^^^^^^^^^^^^^^^^^^^^^^^
  File "/home/pipohkr01/xcobs2/venv/lib/python3.11/site-packages/flask/templating.py", line 150, in render_template
    return _render(app, template, context)
           ^^^^^^^^^^^^^^^^^^^^^^^^^^^^^^^
  File "/home/pipohkr01/xcobs2/venv/lib/python3.11/site-packages/flask/templating.py", line 131, in _render
    rv = template.render(context)
         ^^^^^^^^^^^^^^^^^^^^^^^^
  File "/home/pipohkr01/xcobs2/venv/lib/python3.11/site-packages/jinja2/environment.py", line 1295, in render
    self.environment.handle_exception()
  File "/home/pipohkr01/xcobs2/venv/lib/python3.11/site-packages/jinja2/environment.py", line 942, in handle_exception
    raise rewrite_traceback_stack(source=source)
  File "/home/pipohkr01/xcobs2/dmg_clc/templates/cobs2.html", line 1, in top-level template code
    {% extends "base.html" %}
  File "/home/pipohkr01/xcobs2/dmg_clc/templates/base.html", line 56, in top-level template code
    {% block content %}{% endblock %}
    ^^^^^^^^^^^^^^^^^^^^^^^^^
  File "/home/pipohkr01/xcobs2/dmg_clc/templates/cobs2.html", line 6, in block 'content'
    {% include "partials/cobs2_content.html" %}
    ^^^^^^^^^^^^^^^^^^^^^^^^^
  File "/home/pipohkr01/xcobs2/venv/lib/python3.11/site-packages/jinja2/environment.py", line 942, in handle_exception
    raise rewrite_traceback_stack(source=source)
  File "/home/pipohkr01/xcobs2/dmg_clc/templates/partials/cobs2_content.html", line 160, in template
    <option  value="さみしがり"{% if char_At==’さみしがり’ %}selected{% endif %}>さみしがり</option>
    ^^^^^^^^^^^^^^^^^^^^^^^
jinja2.exceptions.TemplateSyntaxError: unexpected char '’' at 7172
[2025-08-02 07:10:38 +0000] [178578] [INFO] Handling signal: term
[2025-08-02 07:10:38 +0000] [178579] [INFO] Worker exiting (pid: 178579)
[2025-08-02 07:10:38 +0000] [178580] [INFO] Worker exiting (pid: 178580)
[2025-08-02 07:10:38 +0000] [178581] [INFO] Worker exiting (pid: 178581)
[2025-08-02 07:10:38 +0000] [178582] [INFO] Worker exiting (pid: 178582)
[2025-08-02 07:10:39 +0000] [178578] [INFO] Shutting down: Master
[2025-08-02 07:11:00 +0000] [179335] [INFO] Starting gunicorn 23.0.0
[2025-08-02 07:11:00 +0000] [179335] [INFO] Listening at: http://127.0.0.1:8000 (179335)
[2025-08-02 07:11:00 +0000] [179335] [INFO] Using worker: sync
[2025-08-02 07:11:00 +0000] [179336] [INFO] Booting worker with pid: 179336
[2025-08-02 07:11:00 +0000] [179337] [INFO] Booting worker with pid: 179337
[2025-08-02 07:11:00 +0000] [179338] [INFO] Booting worker with pid: 179338
[2025-08-02 07:11:00 +0000] [179339] [INFO] Booting worker with pid: 179339
[2025-08-02 07:11:05,494] ERROR in app: Exception on / [GET]
Traceback (most recent call last):
  File "/home/pipohkr01/xcobs2/venv/lib/python3.11/site-packages/flask/app.py", line 1511, in wsgi_app
    response = self.full_dispatch_request()
               ^^^^^^^^^^^^^^^^^^^^^^^^^^^^
  File "/home/pipohkr01/xcobs2/venv/lib/python3.11/site-packages/flask/app.py", line 919, in full_dispatch_request
    rv = self.handle_user_exception(e)
         ^^^^^^^^^^^^^^^^^^^^^^^^^^^^^
  File "/home/pipohkr01/xcobs2/venv/lib/python3.11/site-packages/flask/app.py", line 917, in full_dispatch_request
    rv = self.dispatch_request()
         ^^^^^^^^^^^^^^^^^^^^^^^
  File "/home/pipohkr01/xcobs2/venv/lib/python3.11/site-packages/flask/app.py", line 902, in dispatch_request
    return self.ensure_sync(self.view_functions[rule.endpoint])(**view_args)  # type: ignore[no-any-return]
           ^^^^^^^^^^^^^^^^^^^^^^^^^^^^^^^^^^^^^^^^^^^^^^^^^^^^^^^^^^^^^^^^^
  File "/home/pipohkr01/xcobs2/dmg_clc/app.py", line 786, in index
    return render_template('cobs2.html', **context)
           ^^^^^^^^^^^^^^^^^^^^^^^^^^^^^^^^^^^^^^^^
  File "/home/pipohkr01/xcobs2/venv/lib/python3.11/site-packages/flask/templating.py", line 150, in render_template
    return _render(app, template, context)
           ^^^^^^^^^^^^^^^^^^^^^^^^^^^^^^^
  File "/home/pipohkr01/xcobs2/venv/lib/python3.11/site-packages/flask/templating.py", line 131, in _render
    rv = template.render(context)
         ^^^^^^^^^^^^^^^^^^^^^^^^
  File "/home/pipohkr01/xcobs2/venv/lib/python3.11/site-packages/jinja2/environment.py", line 1295, in render
    self.environment.handle_exception()
  File "/home/pipohkr01/xcobs2/venv/lib/python3.11/site-packages/jinja2/environment.py", line 942, in handle_exception
    raise rewrite_traceback_stack(source=source)
  File "/home/pipohkr01/xcobs2/dmg_clc/templates/cobs2.html", line 1, in top-level template code
    {% extends "base.html" %}
  File "/home/pipohkr01/xcobs2/dmg_clc/templates/base.html", line 56, in top-level template code
    {% block content %}{% endblock %}
    ^^^^^^^^^^^^^^^^^^^^^^^^^
  File "/home/pipohkr01/xcobs2/dmg_clc/templates/cobs2.html", line 6, in block 'content'
    {% include "partials/cobs2_content.html" %}
    ^^^^^^^^^^^^^^^^^^^^^^^^^
  File "/home/pipohkr01/xcobs2/venv/lib/python3.11/site-packages/jinja2/environment.py", line 942, in handle_exception
    raise rewrite_traceback_stack(source=source)
  File "/home/pipohkr01/xcobs2/dmg_clc/templates/partials/cobs2_content.html", line 283, in template
    <option  value="さみしがり"{% if char_Bl==’さみしがり’ %}selected{% endif %}>さみしがり</option>
    ^^^^^^^^^^^^^^^^^^^^^^^
jinja2.exceptions.TemplateSyntaxError: unexpected char '’' at 13331
[2025-08-02 07:11:07,112] ERROR in app: Exception on / [GET]
Traceback (most recent call last):
  File "/home/pipohkr01/xcobs2/venv/lib/python3.11/site-packages/flask/app.py", line 1511, in wsgi_app
    response = self.full_dispatch_request()
               ^^^^^^^^^^^^^^^^^^^^^^^^^^^^
  File "/home/pipohkr01/xcobs2/venv/lib/python3.11/site-packages/flask/app.py", line 919, in full_dispatch_request
    rv = self.handle_user_exception(e)
         ^^^^^^^^^^^^^^^^^^^^^^^^^^^^^
  File "/home/pipohkr01/xcobs2/venv/lib/python3.11/site-packages/flask/app.py", line 917, in full_dispatch_request
    rv = self.dispatch_request()
         ^^^^^^^^^^^^^^^^^^^^^^^
  File "/home/pipohkr01/xcobs2/venv/lib/python3.11/site-packages/flask/app.py", line 902, in dispatch_request
    return self.ensure_sync(self.view_functions[rule.endpoint])(**view_args)  # type: ignore[no-any-return]
           ^^^^^^^^^^^^^^^^^^^^^^^^^^^^^^^^^^^^^^^^^^^^^^^^^^^^^^^^^^^^^^^^^
  File "/home/pipohkr01/xcobs2/dmg_clc/app.py", line 786, in index
    return render_template('cobs2.html', **context)
           ^^^^^^^^^^^^^^^^^^^^^^^^^^^^^^^^^^^^^^^^
  File "/home/pipohkr01/xcobs2/venv/lib/python3.11/site-packages/flask/templating.py", line 150, in render_template
    return _render(app, template, context)
           ^^^^^^^^^^^^^^^^^^^^^^^^^^^^^^^
  File "/home/pipohkr01/xcobs2/venv/lib/python3.11/site-packages/flask/templating.py", line 131, in _render
    rv = template.render(context)
         ^^^^^^^^^^^^^^^^^^^^^^^^
  File "/home/pipohkr01/xcobs2/venv/lib/python3.11/site-packages/jinja2/environment.py", line 1295, in render
    self.environment.handle_exception()
  File "/home/pipohkr01/xcobs2/venv/lib/python3.11/site-packages/jinja2/environment.py", line 942, in handle_exception
    raise rewrite_traceback_stack(source=source)
  File "/home/pipohkr01/xcobs2/dmg_clc/templates/cobs2.html", line 1, in top-level template code
    {% extends "base.html" %}
  File "/home/pipohkr01/xcobs2/dmg_clc/templates/base.html", line 56, in top-level template code
    {% block content %}{% endblock %}
    ^^^^^^^^^^^^^^^^^^^^^^^^^
  File "/home/pipohkr01/xcobs2/dmg_clc/templates/cobs2.html", line 6, in block 'content'
    {% include "partials/cobs2_content.html" %}
    ^^^^^^^^^^^^^^^^^^^^^^^^^
  File "/home/pipohkr01/xcobs2/venv/lib/python3.11/site-packages/jinja2/environment.py", line 942, in handle_exception
    raise rewrite_traceback_stack(source=source)
  File "/home/pipohkr01/xcobs2/dmg_clc/templates/partials/cobs2_content.html", line 283, in template
    <option  value="さみしがり"{% if char_Bl==’さみしがり’ %}selected{% endif %}>さみしがり</option>
    ^^^^^^^^^^^^^^^^^^^^^^^
jinja2.exceptions.TemplateSyntaxError: unexpected char '’' at 13331
[2025-08-02 07:13:06 +0000] [179335] [INFO] Handling signal: term
[2025-08-02 07:13:06 +0000] [179339] [INFO] Worker exiting (pid: 179339)
[2025-08-02 07:13:06 +0000] [179336] [INFO] Worker exiting (pid: 179336)
[2025-08-02 07:13:06 +0000] [179338] [INFO] Worker exiting (pid: 179338)
[2025-08-02 07:13:06 +0000] [179337] [INFO] Worker exiting (pid: 179337)
[2025-08-02 07:13:07 +0000] [179335] [INFO] Shutting down: Master
[2025-08-02 07:13:26 +0000] [179379] [INFO] Starting gunicorn 23.0.0
[2025-08-02 07:13:26 +0000] [179379] [INFO] Listening at: http://127.0.0.1:8000 (179379)
[2025-08-02 07:13:26 +0000] [179379] [INFO] Using worker: sync
[2025-08-02 07:13:26 +0000] [179380] [INFO] Booting worker with pid: 179380
[2025-08-02 07:13:26 +0000] [179381] [INFO] Booting worker with pid: 179381
[2025-08-02 07:13:26 +0000] [179382] [INFO] Booting worker with pid: 179382
[2025-08-02 07:13:27 +0000] [179383] [INFO] Booting worker with pid: 179383
[2025-08-02 07:13:32,309] ERROR in app: Exception on / [GET]
Traceback (most recent call last):
  File "/home/pipohkr01/xcobs2/venv/lib/python3.11/site-packages/flask/app.py", line 1511, in wsgi_app
    response = self.full_dispatch_request()
               ^^^^^^^^^^^^^^^^^^^^^^^^^^^^
  File "/home/pipohkr01/xcobs2/venv/lib/python3.11/site-packages/flask/app.py", line 919, in full_dispatch_request
    rv = self.handle_user_exception(e)
         ^^^^^^^^^^^^^^^^^^^^^^^^^^^^^
  File "/home/pipohkr01/xcobs2/venv/lib/python3.11/site-packages/flask/app.py", line 917, in full_dispatch_request
    rv = self.dispatch_request()
         ^^^^^^^^^^^^^^^^^^^^^^^
  File "/home/pipohkr01/xcobs2/venv/lib/python3.11/site-packages/flask/app.py", line 902, in dispatch_request
    return self.ensure_sync(self.view_functions[rule.endpoint])(**view_args)  # type: ignore[no-any-return]
           ^^^^^^^^^^^^^^^^^^^^^^^^^^^^^^^^^^^^^^^^^^^^^^^^^^^^^^^^^^^^^^^^^
  File "/home/pipohkr01/xcobs2/dmg_clc/app.py", line 786, in index
    return render_template('cobs2.html', **context)
           ^^^^^^^^^^^^^^^^^^^^^^^^^^^^^^^^^^^^^^^^
  File "/home/pipohkr01/xcobs2/venv/lib/python3.11/site-packages/flask/templating.py", line 150, in render_template
    return _render(app, template, context)
           ^^^^^^^^^^^^^^^^^^^^^^^^^^^^^^^
  File "/home/pipohkr01/xcobs2/venv/lib/python3.11/site-packages/flask/templating.py", line 131, in _render
    rv = template.render(context)
         ^^^^^^^^^^^^^^^^^^^^^^^^
  File "/home/pipohkr01/xcobs2/venv/lib/python3.11/site-packages/jinja2/environment.py", line 1295, in render
    self.environment.handle_exception()
  File "/home/pipohkr01/xcobs2/venv/lib/python3.11/site-packages/jinja2/environment.py", line 942, in handle_exception
    raise rewrite_traceback_stack(source=source)
  File "/home/pipohkr01/xcobs2/dmg_clc/templates/cobs2.html", line 1, in top-level template code
    {% extends "base.html" %}
  File "/home/pipohkr01/xcobs2/dmg_clc/templates/base.html", line 56, in top-level template code
    {% block content %}{% endblock %}
    ^^^^^^^^^^^^^^^^^^^^^^^^^
  File "/home/pipohkr01/xcobs2/dmg_clc/templates/cobs2.html", line 6, in block 'content'
    {% include "partials/cobs2_content.html" %}
    ^^^^^^^^^^^^^^^^^^^^^^^^^
  File "/home/pipohkr01/xcobs2/venv/lib/python3.11/site-packages/jinja2/environment.py", line 942, in handle_exception
    raise rewrite_traceback_stack(source=source)
  File "/home/pipohkr01/xcobs2/dmg_clc/templates/partials/cobs2_content.html", line 283, in template
    <option  value="さみしがり"{% if char_Bl==’さみしがり’ %}selected{% endif %}>さみしがり</option>
    ^^^^^^^^^^^^^^^^^^^^^^^
jinja2.exceptions.TemplateSyntaxError: unexpected char '’' at 13333
[2025-08-02 07:13:33,585] ERROR in app: Exception on / [GET]
Traceback (most recent call last):
  File "/home/pipohkr01/xcobs2/venv/lib/python3.11/site-packages/flask/app.py", line 1511, in wsgi_app
    response = self.full_dispatch_request()
               ^^^^^^^^^^^^^^^^^^^^^^^^^^^^
  File "/home/pipohkr01/xcobs2/venv/lib/python3.11/site-packages/flask/app.py", line 919, in full_dispatch_request
    rv = self.handle_user_exception(e)
         ^^^^^^^^^^^^^^^^^^^^^^^^^^^^^
  File "/home/pipohkr01/xcobs2/venv/lib/python3.11/site-packages/flask/app.py", line 917, in full_dispatch_request
    rv = self.dispatch_request()
         ^^^^^^^^^^^^^^^^^^^^^^^
  File "/home/pipohkr01/xcobs2/venv/lib/python3.11/site-packages/flask/app.py", line 902, in dispatch_request
    return self.ensure_sync(self.view_functions[rule.endpoint])(**view_args)  # type: ignore[no-any-return]
           ^^^^^^^^^^^^^^^^^^^^^^^^^^^^^^^^^^^^^^^^^^^^^^^^^^^^^^^^^^^^^^^^^
  File "/home/pipohkr01/xcobs2/dmg_clc/app.py", line 786, in index
    return render_template('cobs2.html', **context)
           ^^^^^^^^^^^^^^^^^^^^^^^^^^^^^^^^^^^^^^^^
  File "/home/pipohkr01/xcobs2/venv/lib/python3.11/site-packages/flask/templating.py", line 150, in render_template
    return _render(app, template, context)
           ^^^^^^^^^^^^^^^^^^^^^^^^^^^^^^^
  File "/home/pipohkr01/xcobs2/venv/lib/python3.11/site-packages/flask/templating.py", line 131, in _render
    rv = template.render(context)
         ^^^^^^^^^^^^^^^^^^^^^^^^
  File "/home/pipohkr01/xcobs2/venv/lib/python3.11/site-packages/jinja2/environment.py", line 1295, in render
    self.environment.handle_exception()
  File "/home/pipohkr01/xcobs2/venv/lib/python3.11/site-packages/jinja2/environment.py", line 942, in handle_exception
    raise rewrite_traceback_stack(source=source)
  File "/home/pipohkr01/xcobs2/dmg_clc/templates/cobs2.html", line 1, in top-level template code
    {% extends "base.html" %}
  File "/home/pipohkr01/xcobs2/dmg_clc/templates/base.html", line 56, in top-level template code
    {% block content %}{% endblock %}
    ^^^^^^^^^^^^^^^^^^^^^^^^^
  File "/home/pipohkr01/xcobs2/dmg_clc/templates/cobs2.html", line 6, in block 'content'
    {% include "partials/cobs2_content.html" %}
    ^^^^^^^^^^^^^^^^^^^^^^^^^
  File "/home/pipohkr01/xcobs2/venv/lib/python3.11/site-packages/jinja2/environment.py", line 942, in handle_exception
    raise rewrite_traceback_stack(source=source)
  File "/home/pipohkr01/xcobs2/dmg_clc/templates/partials/cobs2_content.html", line 283, in template
    <option  value="さみしがり"{% if char_Bl==’さみしがり’ %}selected{% endif %}>さみしがり</option>
    ^^^^^^^^^^^^^^^^^^^^^^^
jinja2.exceptions.TemplateSyntaxError: unexpected char '’' at 13333
[2025-08-02 07:13:45,810] ERROR in app: Exception on / [GET]
Traceback (most recent call last):
  File "/home/pipohkr01/xcobs2/venv/lib/python3.11/site-packages/flask/app.py", line 1511, in wsgi_app
    response = self.full_dispatch_request()
               ^^^^^^^^^^^^^^^^^^^^^^^^^^^^
  File "/home/pipohkr01/xcobs2/venv/lib/python3.11/site-packages/flask/app.py", line 919, in full_dispatch_request
    rv = self.handle_user_exception(e)
         ^^^^^^^^^^^^^^^^^^^^^^^^^^^^^
  File "/home/pipohkr01/xcobs2/venv/lib/python3.11/site-packages/flask/app.py", line 917, in full_dispatch_request
    rv = self.dispatch_request()
         ^^^^^^^^^^^^^^^^^^^^^^^
  File "/home/pipohkr01/xcobs2/venv/lib/python3.11/site-packages/flask/app.py", line 902, in dispatch_request
    return self.ensure_sync(self.view_functions[rule.endpoint])(**view_args)  # type: ignore[no-any-return]
           ^^^^^^^^^^^^^^^^^^^^^^^^^^^^^^^^^^^^^^^^^^^^^^^^^^^^^^^^^^^^^^^^^
  File "/home/pipohkr01/xcobs2/dmg_clc/app.py", line 786, in index
    return render_template('cobs2.html', **context)
           ^^^^^^^^^^^^^^^^^^^^^^^^^^^^^^^^^^^^^^^^
  File "/home/pipohkr01/xcobs2/venv/lib/python3.11/site-packages/flask/templating.py", line 150, in render_template
    return _render(app, template, context)
           ^^^^^^^^^^^^^^^^^^^^^^^^^^^^^^^
  File "/home/pipohkr01/xcobs2/venv/lib/python3.11/site-packages/flask/templating.py", line 131, in _render
    rv = template.render(context)
         ^^^^^^^^^^^^^^^^^^^^^^^^
  File "/home/pipohkr01/xcobs2/venv/lib/python3.11/site-packages/jinja2/environment.py", line 1295, in render
    self.environment.handle_exception()
  File "/home/pipohkr01/xcobs2/venv/lib/python3.11/site-packages/jinja2/environment.py", line 942, in handle_exception
    raise rewrite_traceback_stack(source=source)
  File "/home/pipohkr01/xcobs2/dmg_clc/templates/cobs2.html", line 1, in top-level template code
    {% extends "base.html" %}
  File "/home/pipohkr01/xcobs2/dmg_clc/templates/base.html", line 56, in top-level template code
    {% block content %}{% endblock %}
    ^^^^^^^^^^^^^^^^^^^^^^^^^
  File "/home/pipohkr01/xcobs2/dmg_clc/templates/cobs2.html", line 6, in block 'content'
    {% include "partials/cobs2_content.html" %}
    ^^^^^^^^^^^^^^^^^^^^^^^^^
  File "/home/pipohkr01/xcobs2/venv/lib/python3.11/site-packages/jinja2/environment.py", line 942, in handle_exception
    raise rewrite_traceback_stack(source=source)
  File "/home/pipohkr01/xcobs2/dmg_clc/templates/partials/cobs2_content.html", line 283, in template
    <option  value="さみしがり"{% if char_Bl==’さみしがり’ %}selected{% endif %}>さみしがり</option>
    ^^^^^^^^^^^^^^^^^^^^^^^
jinja2.exceptions.TemplateSyntaxError: unexpected char '’' at 13333
[2025-08-02 07:14:04,111] ERROR in app: Exception on / [GET]
Traceback (most recent call last):
  File "/home/pipohkr01/xcobs2/venv/lib/python3.11/site-packages/flask/app.py", line 1511, in wsgi_app
    response = self.full_dispatch_request()
               ^^^^^^^^^^^^^^^^^^^^^^^^^^^^
  File "/home/pipohkr01/xcobs2/venv/lib/python3.11/site-packages/flask/app.py", line 919, in full_dispatch_request
    rv = self.handle_user_exception(e)
         ^^^^^^^^^^^^^^^^^^^^^^^^^^^^^
  File "/home/pipohkr01/xcobs2/venv/lib/python3.11/site-packages/flask/app.py", line 917, in full_dispatch_request
    rv = self.dispatch_request()
         ^^^^^^^^^^^^^^^^^^^^^^^
  File "/home/pipohkr01/xcobs2/venv/lib/python3.11/site-packages/flask/app.py", line 902, in dispatch_request
    return self.ensure_sync(self.view_functions[rule.endpoint])(**view_args)  # type: ignore[no-any-return]
           ^^^^^^^^^^^^^^^^^^^^^^^^^^^^^^^^^^^^^^^^^^^^^^^^^^^^^^^^^^^^^^^^^
  File "/home/pipohkr01/xcobs2/dmg_clc/app.py", line 786, in index
    return render_template('cobs2.html', **context)
           ^^^^^^^^^^^^^^^^^^^^^^^^^^^^^^^^^^^^^^^^
  File "/home/pipohkr01/xcobs2/venv/lib/python3.11/site-packages/flask/templating.py", line 150, in render_template
    return _render(app, template, context)
           ^^^^^^^^^^^^^^^^^^^^^^^^^^^^^^^
  File "/home/pipohkr01/xcobs2/venv/lib/python3.11/site-packages/flask/templating.py", line 131, in _render
    rv = template.render(context)
         ^^^^^^^^^^^^^^^^^^^^^^^^
  File "/home/pipohkr01/xcobs2/venv/lib/python3.11/site-packages/jinja2/environment.py", line 1295, in render
    self.environment.handle_exception()
  File "/home/pipohkr01/xcobs2/venv/lib/python3.11/site-packages/jinja2/environment.py", line 942, in handle_exception
    raise rewrite_traceback_stack(source=source)
  File "/home/pipohkr01/xcobs2/dmg_clc/templates/cobs2.html", line 1, in top-level template code
    {% extends "base.html" %}
  File "/home/pipohkr01/xcobs2/dmg_clc/templates/base.html", line 56, in top-level template code
    {% block content %}{% endblock %}
    ^^^^^^^^^^^^^^^^^^^^^^^^^
  File "/home/pipohkr01/xcobs2/dmg_clc/templates/cobs2.html", line 6, in block 'content'
    {% include "partials/cobs2_content.html" %}
    ^^^^^^^^^^^^^^^^^^^^^^^^^
  File "/home/pipohkr01/xcobs2/venv/lib/python3.11/site-packages/jinja2/environment.py", line 942, in handle_exception
    raise rewrite_traceback_stack(source=source)
  File "/home/pipohkr01/xcobs2/dmg_clc/templates/partials/cobs2_content.html", line 283, in template
    <option  value="さみしがり"{% if char_Bl==’さみしがり’ %}selected{% endif %}>さみしがり</option>
    ^^^^^^^^^^^^^^^^^^^^^^^
jinja2.exceptions.TemplateSyntaxError: unexpected char '’' at 13333
[2025-08-02 07:19:09 +0000] [179379] [INFO] Handling signal: term
[2025-08-02 07:19:09 +0000] [179381] [INFO] Worker exiting (pid: 179381)
[2025-08-02 07:19:09 +0000] [179380] [INFO] Worker exiting (pid: 179380)
[2025-08-02 07:19:09 +0000] [179382] [INFO] Worker exiting (pid: 179382)
[2025-08-02 07:19:09 +0000] [179383] [INFO] Worker exiting (pid: 179383)
[2025-08-02 07:19:10 +0000] [179379] [INFO] Shutting down: Master
[2025-08-02 07:19:15 +0000] [180129] [INFO] Starting gunicorn 23.0.0
[2025-08-02 07:19:15 +0000] [180129] [INFO] Listening at: http://127.0.0.1:8000 (180129)
[2025-08-02 07:19:15 +0000] [180129] [INFO] Using worker: sync
[2025-08-02 07:19:15 +0000] [180130] [INFO] Booting worker with pid: 180130
[2025-08-02 07:19:15 +0000] [180131] [INFO] Booting worker with pid: 180131
[2025-08-02 07:19:15 +0000] [180132] [INFO] Booting worker with pid: 180132
[2025-08-02 07:19:15 +0000] [180133] [INFO] Booting worker with pid: 180133
[2025-08-02 07:19:20,051] ERROR in app: Exception on / [GET]
Traceback (most recent call last):
  File "/home/pipohkr01/xcobs2/venv/lib/python3.11/site-packages/flask/app.py", line 1511, in wsgi_app
    response = self.full_dispatch_request()
               ^^^^^^^^^^^^^^^^^^^^^^^^^^^^
  File "/home/pipohkr01/xcobs2/venv/lib/python3.11/site-packages/flask/app.py", line 919, in full_dispatch_request
    rv = self.handle_user_exception(e)
         ^^^^^^^^^^^^^^^^^^^^^^^^^^^^^
  File "/home/pipohkr01/xcobs2/venv/lib/python3.11/site-packages/flask/app.py", line 917, in full_dispatch_request
    rv = self.dispatch_request()
         ^^^^^^^^^^^^^^^^^^^^^^^
  File "/home/pipohkr01/xcobs2/venv/lib/python3.11/site-packages/flask/app.py", line 902, in dispatch_request
    return self.ensure_sync(self.view_functions[rule.endpoint])(**view_args)  # type: ignore[no-any-return]
           ^^^^^^^^^^^^^^^^^^^^^^^^^^^^^^^^^^^^^^^^^^^^^^^^^^^^^^^^^^^^^^^^^
  File "/home/pipohkr01/xcobs2/dmg_clc/app.py", line 786, in index
    return render_template('cobs2.html', **context)
           ^^^^^^^^^^^^^^^^^^^^^^^^^^^^^^^^^^^^^^^^
  File "/home/pipohkr01/xcobs2/venv/lib/python3.11/site-packages/flask/templating.py", line 150, in render_template
    return _render(app, template, context)
           ^^^^^^^^^^^^^^^^^^^^^^^^^^^^^^^
  File "/home/pipohkr01/xcobs2/venv/lib/python3.11/site-packages/flask/templating.py", line 131, in _render
    rv = template.render(context)
         ^^^^^^^^^^^^^^^^^^^^^^^^
  File "/home/pipohkr01/xcobs2/venv/lib/python3.11/site-packages/jinja2/environment.py", line 1295, in render
    self.environment.handle_exception()
  File "/home/pipohkr01/xcobs2/venv/lib/python3.11/site-packages/jinja2/environment.py", line 942, in handle_exception
    raise rewrite_traceback_stack(source=source)
  File "/home/pipohkr01/xcobs2/dmg_clc/templates/cobs2.html", line 1, in top-level template code
    {% extends "base.html" %}
  File "/home/pipohkr01/xcobs2/dmg_clc/templates/base.html", line 56, in top-level template code
    {% block content %}{% endblock %}
    ^^^^^^^^^^^^^^^^^^^^^^^^^
  File "/home/pipohkr01/xcobs2/dmg_clc/templates/cobs2.html", line 6, in block 'content'
    {% include "partials/cobs2_content.html" %}
    ^^^^^^^^^^^^^^^^^^^^^^^^^
  File "/home/pipohkr01/xcobs2/venv/lib/python3.11/site-packages/jinja2/environment.py", line 942, in handle_exception
    raise rewrite_traceback_stack(source=source)
  File "/home/pipohkr01/xcobs2/dmg_clc/templates/partials/cobs2_content.html", line 284, in template
    <option  value="さみしがり"{% if char_Bl==’さみしがり’ %}selected{% endif %}>さみしがり</option>
    ^^^^^^^^^^^^^^^^^^^^^^^
jinja2.exceptions.TemplateSyntaxError: unexpected char '’' at 13335
[2025-08-02 07:19:21,826] ERROR in app: Exception on / [GET]
Traceback (most recent call last):
  File "/home/pipohkr01/xcobs2/venv/lib/python3.11/site-packages/flask/app.py", line 1511, in wsgi_app
    response = self.full_dispatch_request()
               ^^^^^^^^^^^^^^^^^^^^^^^^^^^^
  File "/home/pipohkr01/xcobs2/venv/lib/python3.11/site-packages/flask/app.py", line 919, in full_dispatch_request
    rv = self.handle_user_exception(e)
         ^^^^^^^^^^^^^^^^^^^^^^^^^^^^^
  File "/home/pipohkr01/xcobs2/venv/lib/python3.11/site-packages/flask/app.py", line 917, in full_dispatch_request
    rv = self.dispatch_request()
         ^^^^^^^^^^^^^^^^^^^^^^^
  File "/home/pipohkr01/xcobs2/venv/lib/python3.11/site-packages/flask/app.py", line 902, in dispatch_request
    return self.ensure_sync(self.view_functions[rule.endpoint])(**view_args)  # type: ignore[no-any-return]
           ^^^^^^^^^^^^^^^^^^^^^^^^^^^^^^^^^^^^^^^^^^^^^^^^^^^^^^^^^^^^^^^^^
  File "/home/pipohkr01/xcobs2/dmg_clc/app.py", line 786, in index
    return render_template('cobs2.html', **context)
           ^^^^^^^^^^^^^^^^^^^^^^^^^^^^^^^^^^^^^^^^
  File "/home/pipohkr01/xcobs2/venv/lib/python3.11/site-packages/flask/templating.py", line 150, in render_template
    return _render(app, template, context)
           ^^^^^^^^^^^^^^^^^^^^^^^^^^^^^^^
  File "/home/pipohkr01/xcobs2/venv/lib/python3.11/site-packages/flask/templating.py", line 131, in _render
    rv = template.render(context)
         ^^^^^^^^^^^^^^^^^^^^^^^^
  File "/home/pipohkr01/xcobs2/venv/lib/python3.11/site-packages/jinja2/environment.py", line 1295, in render
    self.environment.handle_exception()
  File "/home/pipohkr01/xcobs2/venv/lib/python3.11/site-packages/jinja2/environment.py", line 942, in handle_exception
    raise rewrite_traceback_stack(source=source)
  File "/home/pipohkr01/xcobs2/dmg_clc/templates/cobs2.html", line 1, in top-level template code
    {% extends "base.html" %}
  File "/home/pipohkr01/xcobs2/dmg_clc/templates/base.html", line 56, in top-level template code
    {% block content %}{% endblock %}
    ^^^^^^^^^^^^^^^^^^^^^^^^^
  File "/home/pipohkr01/xcobs2/dmg_clc/templates/cobs2.html", line 6, in block 'content'
    {% include "partials/cobs2_content.html" %}
    ^^^^^^^^^^^^^^^^^^^^^^^^^
  File "/home/pipohkr01/xcobs2/venv/lib/python3.11/site-packages/jinja2/environment.py", line 942, in handle_exception
    raise rewrite_traceback_stack(source=source)
  File "/home/pipohkr01/xcobs2/dmg_clc/templates/partials/cobs2_content.html", line 284, in template
    <option  value="さみしがり"{% if char_Bl==’さみしがり’ %}selected{% endif %}>さみしがり</option>
    ^^^^^^^^^^^^^^^^^^^^^^^
jinja2.exceptions.TemplateSyntaxError: unexpected char '’' at 13335
[2025-08-02 07:28:13 +0000] [180129] [INFO] Handling signal: term
[2025-08-02 07:28:13 +0000] [180130] [INFO] Worker exiting (pid: 180130)
[2025-08-02 07:28:13 +0000] [180131] [INFO] Worker exiting (pid: 180131)
[2025-08-02 07:28:13 +0000] [180132] [INFO] Worker exiting (pid: 180132)
[2025-08-02 07:28:13 +0000] [180133] [INFO] Worker exiting (pid: 180133)
[2025-08-02 07:28:14 +0000] [180129] [INFO] Shutting down: Master
[2025-08-02 07:28:22 +0000] [180248] [INFO] Starting gunicorn 23.0.0
[2025-08-02 07:28:22 +0000] [180248] [INFO] Listening at: http://127.0.0.1:8000 (180248)
[2025-08-02 07:28:22 +0000] [180248] [INFO] Using worker: sync
[2025-08-02 07:28:22 +0000] [180249] [INFO] Booting worker with pid: 180249
[2025-08-02 07:28:22 +0000] [180250] [INFO] Booting worker with pid: 180250
[2025-08-02 07:28:22 +0000] [180251] [INFO] Booting worker with pid: 180251
[2025-08-02 07:28:22 +0000] [180252] [INFO] Booting worker with pid: 180252
[2025-08-02 07:28:28,743] ERROR in app: Exception on / [GET]
Traceback (most recent call last):
  File "/home/pipohkr01/xcobs2/venv/lib/python3.11/site-packages/flask/app.py", line 1511, in wsgi_app
    response = self.full_dispatch_request()
               ^^^^^^^^^^^^^^^^^^^^^^^^^^^^
  File "/home/pipohkr01/xcobs2/venv/lib/python3.11/site-packages/flask/app.py", line 919, in full_dispatch_request
    rv = self.handle_user_exception(e)
         ^^^^^^^^^^^^^^^^^^^^^^^^^^^^^
  File "/home/pipohkr01/xcobs2/venv/lib/python3.11/site-packages/flask/app.py", line 917, in full_dispatch_request
    rv = self.dispatch_request()
         ^^^^^^^^^^^^^^^^^^^^^^^
  File "/home/pipohkr01/xcobs2/venv/lib/python3.11/site-packages/flask/app.py", line 902, in dispatch_request
    return self.ensure_sync(self.view_functions[rule.endpoint])(**view_args)  # type: ignore[no-any-return]
           ^^^^^^^^^^^^^^^^^^^^^^^^^^^^^^^^^^^^^^^^^^^^^^^^^^^^^^^^^^^^^^^^^
  File "/home/pipohkr01/xcobs2/dmg_clc/app.py", line 786, in index
    return render_template('cobs2.html', **context)
           ^^^^^^^^^^^^^^^^^^^^^^^^^^^^^^^^^^^^^^^^
  File "/home/pipohkr01/xcobs2/venv/lib/python3.11/site-packages/flask/templating.py", line 150, in render_template
    return _render(app, template, context)
           ^^^^^^^^^^^^^^^^^^^^^^^^^^^^^^^
  File "/home/pipohkr01/xcobs2/venv/lib/python3.11/site-packages/flask/templating.py", line 131, in _render
    rv = template.render(context)
         ^^^^^^^^^^^^^^^^^^^^^^^^
  File "/home/pipohkr01/xcobs2/venv/lib/python3.11/site-packages/jinja2/environment.py", line 1295, in render
    self.environment.handle_exception()
  File "/home/pipohkr01/xcobs2/venv/lib/python3.11/site-packages/jinja2/environment.py", line 942, in handle_exception
    raise rewrite_traceback_stack(source=source)
  File "/home/pipohkr01/xcobs2/dmg_clc/templates/cobs2.html", line 1, in top-level template code
    {% extends "base.html" %}
  File "/home/pipohkr01/xcobs2/dmg_clc/templates/base.html", line 56, in top-level template code
    {% block content %}{% endblock %}
    ^^^^^^^^^^^^^^^^^^^^^^^^^
  File "/home/pipohkr01/xcobs2/dmg_clc/templates/cobs2.html", line 6, in block 'content'
    {% include "partials/cobs2_content.html" %}
    ^^^^^^^^^^^^^^^^^^^^^^^^^
  File "/home/pipohkr01/xcobs2/venv/lib/python3.11/site-packages/jinja2/environment.py", line 942, in handle_exception
    raise rewrite_traceback_stack(source=source)
  File "/home/pipohkr01/xcobs2/dmg_clc/templates/partials/cobs2_content.html", line 284, in template
    <option  value="さみしがり"{% if char_Bl==’さみしがり’ %}selected{% endif %}>さみしがり</option>
    ^^^^^^^^^^^^^^^^^^^^^^^
jinja2.exceptions.TemplateSyntaxError: unexpected char '’' at 13337
[2025-08-02 07:33:44 +0000] [180248] [INFO] Handling signal: term
[2025-08-02 07:33:44 +0000] [180249] [INFO] Worker exiting (pid: 180249)
[2025-08-02 07:33:44 +0000] [180250] [INFO] Worker exiting (pid: 180250)
[2025-08-02 07:33:44 +0000] [180251] [INFO] Worker exiting (pid: 180251)
[2025-08-02 07:33:44 +0000] [180252] [INFO] Worker exiting (pid: 180252)
[2025-08-02 07:33:45 +0000] [180248] [INFO] Shutting down: Master
[2025-08-02 07:34:39 +0000] [180987] [INFO] Starting gunicorn 23.0.0
[2025-08-02 07:34:39 +0000] [180987] [INFO] Listening at: http://127.0.0.1:8000 (180987)
[2025-08-02 07:34:39 +0000] [180987] [INFO] Using worker: sync
[2025-08-02 07:34:39 +0000] [180988] [INFO] Booting worker with pid: 180988
[2025-08-02 07:34:39 +0000] [180989] [INFO] Booting worker with pid: 180989
[2025-08-02 07:34:39 +0000] [180990] [INFO] Booting worker with pid: 180990
[2025-08-02 07:34:39 +0000] [180991] [INFO] Booting worker with pid: 180991
[2025-08-02 07:34:46,722] ERROR in app: Exception on / [GET]
Traceback (most recent call last):
  File "/home/pipohkr01/xcobs2/venv/lib/python3.11/site-packages/flask/app.py", line 1511, in wsgi_app
    response = self.full_dispatch_request()
               ^^^^^^^^^^^^^^^^^^^^^^^^^^^^
  File "/home/pipohkr01/xcobs2/venv/lib/python3.11/site-packages/flask/app.py", line 919, in full_dispatch_request
    rv = self.handle_user_exception(e)
         ^^^^^^^^^^^^^^^^^^^^^^^^^^^^^
  File "/home/pipohkr01/xcobs2/venv/lib/python3.11/site-packages/flask/app.py", line 917, in full_dispatch_request
    rv = self.dispatch_request()
         ^^^^^^^^^^^^^^^^^^^^^^^
  File "/home/pipohkr01/xcobs2/venv/lib/python3.11/site-packages/flask/app.py", line 902, in dispatch_request
    return self.ensure_sync(self.view_functions[rule.endpoint])(**view_args)  # type: ignore[no-any-return]
           ^^^^^^^^^^^^^^^^^^^^^^^^^^^^^^^^^^^^^^^^^^^^^^^^^^^^^^^^^^^^^^^^^
  File "/home/pipohkr01/xcobs2/dmg_clc/app.py", line 786, in index
    return render_template('cobs2.html', **context)
           ^^^^^^^^^^^^^^^^^^^^^^^^^^^^^^^^^^^^^^^^
  File "/home/pipohkr01/xcobs2/venv/lib/python3.11/site-packages/flask/templating.py", line 150, in render_template
    return _render(app, template, context)
           ^^^^^^^^^^^^^^^^^^^^^^^^^^^^^^^
  File "/home/pipohkr01/xcobs2/venv/lib/python3.11/site-packages/flask/templating.py", line 131, in _render
    rv = template.render(context)
         ^^^^^^^^^^^^^^^^^^^^^^^^
  File "/home/pipohkr01/xcobs2/venv/lib/python3.11/site-packages/jinja2/environment.py", line 1295, in render
    self.environment.handle_exception()
  File "/home/pipohkr01/xcobs2/venv/lib/python3.11/site-packages/jinja2/environment.py", line 942, in handle_exception
    raise rewrite_traceback_stack(source=source)
  File "/home/pipohkr01/xcobs2/dmg_clc/templates/cobs2.html", line 1, in top-level template code
    {% extends "base.html" %}
  File "/home/pipohkr01/xcobs2/dmg_clc/templates/base.html", line 56, in top-level template code
    {% block content %}{% endblock %}
    ^^^^^^^^^^^^^^^^^^^^^^^^^
  File "/home/pipohkr01/xcobs2/dmg_clc/templates/cobs2.html", line 6, in block 'content'
    {% include "partials/cobs2_content.html" %}
    ^^^^^^^^^^^^^^^^^^^^^^^^^
  File "/home/pipohkr01/xcobs2/venv/lib/python3.11/site-packages/jinja2/environment.py", line 942, in handle_exception
    raise rewrite_traceback_stack(source=source)
  File "/home/pipohkr01/xcobs2/dmg_clc/templates/partials/cobs2_content.html", line 284, in template
    <option  value="さみしがり"{% if char_Bl==’さみしがり’ %}selected{% endif %}>さみしがり</option>
    ^^^^^^^^^^^^^^^^^^^^^^^
jinja2.exceptions.TemplateSyntaxError: unexpected char '’' at 13338
[2025-08-02 07:35:06 +0000] [180987] [INFO] Handling signal: term
[2025-08-02 07:35:06 +0000] [180988] [INFO] Worker exiting (pid: 180988)
[2025-08-02 07:35:06 +0000] [180989] [INFO] Worker exiting (pid: 180989)
[2025-08-02 07:35:06 +0000] [180990] [INFO] Worker exiting (pid: 180990)
[2025-08-02 07:35:06 +0000] [180991] [INFO] Worker exiting (pid: 180991)
[2025-08-02 07:35:06 +0000] [180987] [INFO] Shutting down: Master
[2025-08-02 07:35:38 +0000] [181004] [INFO] Starting gunicorn 23.0.0
[2025-08-02 07:35:38 +0000] [181004] [INFO] Listening at: http://127.0.0.1:8000 (181004)
[2025-08-02 07:35:38 +0000] [181004] [INFO] Using worker: sync
[2025-08-02 07:35:38 +0000] [181005] [INFO] Booting worker with pid: 181005
[2025-08-02 07:35:38 +0000] [181006] [INFO] Booting worker with pid: 181006
[2025-08-02 07:35:38 +0000] [181007] [INFO] Booting worker with pid: 181007
[2025-08-02 07:35:38 +0000] [181008] [INFO] Booting worker with pid: 181008
[2025-08-02 07:35:40,752] ERROR in app: Exception on / [GET]
Traceback (most recent call last):
  File "/home/pipohkr01/xcobs2/venv/lib/python3.11/site-packages/flask/app.py", line 1511, in wsgi_app
    response = self.full_dispatch_request()
               ^^^^^^^^^^^^^^^^^^^^^^^^^^^^
  File "/home/pipohkr01/xcobs2/venv/lib/python3.11/site-packages/flask/app.py", line 919, in full_dispatch_request
    rv = self.handle_user_exception(e)
         ^^^^^^^^^^^^^^^^^^^^^^^^^^^^^
  File "/home/pipohkr01/xcobs2/venv/lib/python3.11/site-packages/flask/app.py", line 917, in full_dispatch_request
    rv = self.dispatch_request()
         ^^^^^^^^^^^^^^^^^^^^^^^
  File "/home/pipohkr01/xcobs2/venv/lib/python3.11/site-packages/flask/app.py", line 902, in dispatch_request
    return self.ensure_sync(self.view_functions[rule.endpoint])(**view_args)  # type: ignore[no-any-return]
           ^^^^^^^^^^^^^^^^^^^^^^^^^^^^^^^^^^^^^^^^^^^^^^^^^^^^^^^^^^^^^^^^^
  File "/home/pipohkr01/xcobs2/dmg_clc/app.py", line 786, in index
    return render_template('cobs2.html', **context)
           ^^^^^^^^^^^^^^^^^^^^^^^^^^^^^^^^^^^^^^^^
  File "/home/pipohkr01/xcobs2/venv/lib/python3.11/site-packages/flask/templating.py", line 150, in render_template
    return _render(app, template, context)
           ^^^^^^^^^^^^^^^^^^^^^^^^^^^^^^^
  File "/home/pipohkr01/xcobs2/venv/lib/python3.11/site-packages/flask/templating.py", line 131, in _render
    rv = template.render(context)
         ^^^^^^^^^^^^^^^^^^^^^^^^
  File "/home/pipohkr01/xcobs2/venv/lib/python3.11/site-packages/jinja2/environment.py", line 1295, in render
    self.environment.handle_exception()
  File "/home/pipohkr01/xcobs2/venv/lib/python3.11/site-packages/jinja2/environment.py", line 942, in handle_exception
    raise rewrite_traceback_stack(source=source)
  File "/home/pipohkr01/xcobs2/dmg_clc/templates/cobs2.html", line 1, in top-level template code
    {% extends "base.html" %}
  File "/home/pipohkr01/xcobs2/dmg_clc/templates/base.html", line 56, in top-level template code
    {% block content %}{% endblock %}
    ^^^^^^^^^^^^^^^^^^^^^^^^^
  File "/home/pipohkr01/xcobs2/dmg_clc/templates/cobs2.html", line 6, in block 'content'
    {% include "partials/cobs2_content.html" %}
    ^^^^^^^^^^^^^^^^^^^^^^^^^
  File "/home/pipohkr01/xcobs2/venv/lib/python3.11/site-packages/jinja2/environment.py", line 942, in handle_exception
    raise rewrite_traceback_stack(source=source)
  File "/home/pipohkr01/xcobs2/dmg_clc/templates/partials/cobs2_content.html", line 284, in template
    <option  value="さみしがり"{% if char_Bl==’さみしがり’ %}selected{% endif %}>さみしがり</option>
    ^^^^^^^^^^^^^^^^^^^^^^^
jinja2.exceptions.TemplateSyntaxError: unexpected char '’' at 13338
[2025-08-02 07:36:15,362] ERROR in app: Exception on / [GET]
Traceback (most recent call last):
  File "/home/pipohkr01/xcobs2/venv/lib/python3.11/site-packages/flask/app.py", line 1511, in wsgi_app
    response = self.full_dispatch_request()
               ^^^^^^^^^^^^^^^^^^^^^^^^^^^^
  File "/home/pipohkr01/xcobs2/venv/lib/python3.11/site-packages/flask/app.py", line 919, in full_dispatch_request
    rv = self.handle_user_exception(e)
         ^^^^^^^^^^^^^^^^^^^^^^^^^^^^^
  File "/home/pipohkr01/xcobs2/venv/lib/python3.11/site-packages/flask/app.py", line 917, in full_dispatch_request
    rv = self.dispatch_request()
         ^^^^^^^^^^^^^^^^^^^^^^^
  File "/home/pipohkr01/xcobs2/venv/lib/python3.11/site-packages/flask/app.py", line 902, in dispatch_request
    return self.ensure_sync(self.view_functions[rule.endpoint])(**view_args)  # type: ignore[no-any-return]
           ^^^^^^^^^^^^^^^^^^^^^^^^^^^^^^^^^^^^^^^^^^^^^^^^^^^^^^^^^^^^^^^^^
  File "/home/pipohkr01/xcobs2/dmg_clc/app.py", line 786, in index
    return render_template('cobs2.html', **context)
           ^^^^^^^^^^^^^^^^^^^^^^^^^^^^^^^^^^^^^^^^
  File "/home/pipohkr01/xcobs2/venv/lib/python3.11/site-packages/flask/templating.py", line 150, in render_template
    return _render(app, template, context)
           ^^^^^^^^^^^^^^^^^^^^^^^^^^^^^^^
  File "/home/pipohkr01/xcobs2/venv/lib/python3.11/site-packages/flask/templating.py", line 131, in _render
    rv = template.render(context)
         ^^^^^^^^^^^^^^^^^^^^^^^^
  File "/home/pipohkr01/xcobs2/venv/lib/python3.11/site-packages/jinja2/environment.py", line 1295, in render
    self.environment.handle_exception()
  File "/home/pipohkr01/xcobs2/venv/lib/python3.11/site-packages/jinja2/environment.py", line 942, in handle_exception
    raise rewrite_traceback_stack(source=source)
  File "/home/pipohkr01/xcobs2/dmg_clc/templates/cobs2.html", line 1, in top-level template code
    {% extends "base.html" %}
  File "/home/pipohkr01/xcobs2/dmg_clc/templates/base.html", line 56, in top-level template code
    {% block content %}{% endblock %}
    ^^^^^^^^^^^^^^^^^^^^^^^^^
  File "/home/pipohkr01/xcobs2/dmg_clc/templates/cobs2.html", line 6, in block 'content'
    {% include "partials/cobs2_content.html" %}
    ^^^^^^^^^^^^^^^^^^^^^^^^^
  File "/home/pipohkr01/xcobs2/venv/lib/python3.11/site-packages/jinja2/environment.py", line 942, in handle_exception
    raise rewrite_traceback_stack(source=source)
  File "/home/pipohkr01/xcobs2/dmg_clc/templates/partials/cobs2_content.html", line 284, in template
    <option  value="さみしがり"{% if char_Bl==’さみしがり’ %}selected{% endif %}>さみしがり</option>
    ^^^^^^^^^^^^^^^^^^^^^^^
jinja2.exceptions.TemplateSyntaxError: unexpected char '’' at 13338
[2025-08-02 07:41:12 +0000] [181004] [INFO] Handling signal: term
[2025-08-02 07:41:12 +0000] [181006] [INFO] Worker exiting (pid: 181006)
[2025-08-02 07:41:12 +0000] [181005] [INFO] Worker exiting (pid: 181005)
[2025-08-02 07:41:12 +0000] [181008] [INFO] Worker exiting (pid: 181008)
[2025-08-02 07:41:12 +0000] [181007] [INFO] Worker exiting (pid: 181007)
[2025-08-02 07:41:13 +0000] [181004] [INFO] Shutting down: Master
[2025-08-02 07:41:18 +0000] [181723] [INFO] Starting gunicorn 23.0.0
[2025-08-02 07:41:18 +0000] [181723] [INFO] Listening at: http://127.0.0.1:8000 (181723)
[2025-08-02 07:41:18 +0000] [181723] [INFO] Using worker: sync
[2025-08-02 07:41:18 +0000] [181724] [INFO] Booting worker with pid: 181724
[2025-08-02 07:41:18 +0000] [181725] [INFO] Booting worker with pid: 181725
[2025-08-02 07:41:18 +0000] [181726] [INFO] Booting worker with pid: 181726
[2025-08-02 07:41:18 +0000] [181727] [INFO] Booting worker with pid: 181727
[2025-08-02 07:41:21,030] ERROR in app: Exception on / [GET]
Traceback (most recent call last):
  File "/home/pipohkr01/xcobs2/venv/lib/python3.11/site-packages/flask/app.py", line 1511, in wsgi_app
    response = self.full_dispatch_request()
               ^^^^^^^^^^^^^^^^^^^^^^^^^^^^
  File "/home/pipohkr01/xcobs2/venv/lib/python3.11/site-packages/flask/app.py", line 919, in full_dispatch_request
    rv = self.handle_user_exception(e)
         ^^^^^^^^^^^^^^^^^^^^^^^^^^^^^
  File "/home/pipohkr01/xcobs2/venv/lib/python3.11/site-packages/flask/app.py", line 917, in full_dispatch_request
    rv = self.dispatch_request()
         ^^^^^^^^^^^^^^^^^^^^^^^
  File "/home/pipohkr01/xcobs2/venv/lib/python3.11/site-packages/flask/app.py", line 902, in dispatch_request
    return self.ensure_sync(self.view_functions[rule.endpoint])(**view_args)  # type: ignore[no-any-return]
           ^^^^^^^^^^^^^^^^^^^^^^^^^^^^^^^^^^^^^^^^^^^^^^^^^^^^^^^^^^^^^^^^^
  File "/home/pipohkr01/xcobs2/dmg_clc/app.py", line 786, in index
    return render_template('cobs2.html', **context)
           ^^^^^^^^^^^^^^^^^^^^^^^^^^^^^^^^^^^^^^^^
  File "/home/pipohkr01/xcobs2/venv/lib/python3.11/site-packages/flask/templating.py", line 150, in render_template
    return _render(app, template, context)
           ^^^^^^^^^^^^^^^^^^^^^^^^^^^^^^^
  File "/home/pipohkr01/xcobs2/venv/lib/python3.11/site-packages/flask/templating.py", line 131, in _render
    rv = template.render(context)
         ^^^^^^^^^^^^^^^^^^^^^^^^
  File "/home/pipohkr01/xcobs2/venv/lib/python3.11/site-packages/jinja2/environment.py", line 1295, in render
    self.environment.handle_exception()
  File "/home/pipohkr01/xcobs2/venv/lib/python3.11/site-packages/jinja2/environment.py", line 942, in handle_exception
    raise rewrite_traceback_stack(source=source)
  File "/home/pipohkr01/xcobs2/dmg_clc/templates/cobs2.html", line 1, in top-level template code
    {% extends "base.html" %}
  File "/home/pipohkr01/xcobs2/dmg_clc/templates/base.html", line 56, in top-level template code
    {% block content %}{% endblock %}
    ^^^^^^^^^^^^^^^^^^^^^^^^^
  File "/home/pipohkr01/xcobs2/dmg_clc/templates/cobs2.html", line 6, in block 'content'
    {% include "partials/cobs2_content.html" %}
    ^^^^^^^^^^^^^^^^^^^^^^^^^
  File "/home/pipohkr01/xcobs2/venv/lib/python3.11/site-packages/jinja2/environment.py", line 942, in handle_exception
    raise rewrite_traceback_stack(source=source)
  File "/home/pipohkr01/xcobs2/dmg_clc/templates/partials/cobs2_content.html", line 271, in template
    <option  value="さみしがり"{% if char_Bl==’さみしがり’ %}selected{% endif %}>さみしがり</option>
    ^^^^^^^^^^^^^^^^^^^^^^^
jinja2.exceptions.TemplateSyntaxError: unexpected char '’' at 12830
[2025-08-02 07:45:11 +0000] [181723] [INFO] Handling signal: term
[2025-08-02 07:45:11 +0000] [181724] [INFO] Worker exiting (pid: 181724)
[2025-08-02 07:45:11 +0000] [181725] [INFO] Worker exiting (pid: 181725)
[2025-08-02 07:45:11 +0000] [181726] [INFO] Worker exiting (pid: 181726)
[2025-08-02 07:45:11 +0000] [181727] [INFO] Worker exiting (pid: 181727)
[2025-08-02 07:45:12 +0000] [181723] [INFO] Shutting down: Master
[2025-08-02 07:45:16 +0000] [181769] [INFO] Starting gunicorn 23.0.0
[2025-08-02 07:45:16 +0000] [181769] [INFO] Listening at: http://127.0.0.1:8000 (181769)
[2025-08-02 07:45:16 +0000] [181769] [INFO] Using worker: sync
[2025-08-02 07:45:16 +0000] [181770] [INFO] Booting worker with pid: 181770
[2025-08-02 07:45:16 +0000] [181771] [INFO] Booting worker with pid: 181771
[2025-08-02 07:45:16 +0000] [181772] [INFO] Booting worker with pid: 181772
[2025-08-02 07:45:16 +0000] [181773] [INFO] Booting worker with pid: 181773
[2025-08-02 07:45:19,371] ERROR in app: Exception on / [GET]
Traceback (most recent call last):
  File "/home/pipohkr01/xcobs2/venv/lib/python3.11/site-packages/flask/app.py", line 1511, in wsgi_app
    response = self.full_dispatch_request()
               ^^^^^^^^^^^^^^^^^^^^^^^^^^^^
  File "/home/pipohkr01/xcobs2/venv/lib/python3.11/site-packages/flask/app.py", line 919, in full_dispatch_request
    rv = self.handle_user_exception(e)
         ^^^^^^^^^^^^^^^^^^^^^^^^^^^^^
  File "/home/pipohkr01/xcobs2/venv/lib/python3.11/site-packages/flask/app.py", line 917, in full_dispatch_request
    rv = self.dispatch_request()
         ^^^^^^^^^^^^^^^^^^^^^^^
  File "/home/pipohkr01/xcobs2/venv/lib/python3.11/site-packages/flask/app.py", line 902, in dispatch_request
    return self.ensure_sync(self.view_functions[rule.endpoint])(**view_args)  # type: ignore[no-any-return]
           ^^^^^^^^^^^^^^^^^^^^^^^^^^^^^^^^^^^^^^^^^^^^^^^^^^^^^^^^^^^^^^^^^
  File "/home/pipohkr01/xcobs2/dmg_clc/app.py", line 786, in index
    return render_template('cobs2.html', **context)
           ^^^^^^^^^^^^^^^^^^^^^^^^^^^^^^^^^^^^^^^^
  File "/home/pipohkr01/xcobs2/venv/lib/python3.11/site-packages/flask/templating.py", line 150, in render_template
    return _render(app, template, context)
           ^^^^^^^^^^^^^^^^^^^^^^^^^^^^^^^
  File "/home/pipohkr01/xcobs2/venv/lib/python3.11/site-packages/flask/templating.py", line 131, in _render
    rv = template.render(context)
         ^^^^^^^^^^^^^^^^^^^^^^^^
  File "/home/pipohkr01/xcobs2/venv/lib/python3.11/site-packages/jinja2/environment.py", line 1295, in render
    self.environment.handle_exception()
  File "/home/pipohkr01/xcobs2/venv/lib/python3.11/site-packages/jinja2/environment.py", line 942, in handle_exception
    raise rewrite_traceback_stack(source=source)
  File "/home/pipohkr01/xcobs2/dmg_clc/templates/cobs2.html", line 1, in top-level template code
    {% extends "base.html" %}
  File "/home/pipohkr01/xcobs2/dmg_clc/templates/base.html", line 56, in top-level template code
    {% block content %}{% endblock %}
    ^^^^^^^^^^^^^^^^^^^^^^^^^
  File "/home/pipohkr01/xcobs2/dmg_clc/templates/cobs2.html", line 6, in block 'content'
    {% include "partials/cobs2_content.html" %}
    ^^^^^^^^^^^^^^^^^^^^^^^^^
  File "/home/pipohkr01/xcobs2/venv/lib/python3.11/site-packages/jinja2/environment.py", line 942, in handle_exception
    raise rewrite_traceback_stack(source=source)
  File "/home/pipohkr01/xcobs2/dmg_clc/templates/partials/cobs2_content.html", line 272, in template
    <option  value="さみしがり"{% if char_Bl==’さみしがり’ %}selected{% endif %}>さみしがり</option>
    ^^^^^^^^^^^^^^^^^^^^^^^
jinja2.exceptions.TemplateSyntaxError: unexpected char '’' at 12826
[2025-08-02 07:48:47 +0000] [181769] [INFO] Handling signal: term
[2025-08-02 07:48:47 +0000] [181770] [INFO] Worker exiting (pid: 181770)
[2025-08-02 07:48:47 +0000] [181773] [INFO] Worker exiting (pid: 181773)
[2025-08-02 07:48:47 +0000] [181771] [INFO] Worker exiting (pid: 181771)
[2025-08-02 07:48:47 +0000] [181772] [INFO] Worker exiting (pid: 181772)
[2025-08-02 07:48:48 +0000] [181769] [INFO] Shutting down: Master
[2025-08-02 07:49:12 +0000] [182476] [INFO] Starting gunicorn 23.0.0
[2025-08-02 07:49:12 +0000] [182476] [INFO] Listening at: http://127.0.0.1:8000 (182476)
[2025-08-02 07:49:12 +0000] [182476] [INFO] Using worker: sync
[2025-08-02 07:49:12 +0000] [182477] [INFO] Booting worker with pid: 182477
[2025-08-02 07:49:12 +0000] [182478] [INFO] Booting worker with pid: 182478
[2025-08-02 07:49:12 +0000] [182479] [INFO] Booting worker with pid: 182479
[2025-08-02 07:49:12 +0000] [182480] [INFO] Booting worker with pid: 182480
[2025-08-02 07:49:15,041] ERROR in app: Exception on / [GET]
Traceback (most recent call last):
  File "/home/pipohkr01/xcobs2/venv/lib/python3.11/site-packages/flask/app.py", line 1511, in wsgi_app
    response = self.full_dispatch_request()
               ^^^^^^^^^^^^^^^^^^^^^^^^^^^^
  File "/home/pipohkr01/xcobs2/venv/lib/python3.11/site-packages/flask/app.py", line 919, in full_dispatch_request
    rv = self.handle_user_exception(e)
         ^^^^^^^^^^^^^^^^^^^^^^^^^^^^^
  File "/home/pipohkr01/xcobs2/venv/lib/python3.11/site-packages/flask/app.py", line 917, in full_dispatch_request
    rv = self.dispatch_request()
         ^^^^^^^^^^^^^^^^^^^^^^^
  File "/home/pipohkr01/xcobs2/venv/lib/python3.11/site-packages/flask/app.py", line 902, in dispatch_request
    return self.ensure_sync(self.view_functions[rule.endpoint])(**view_args)  # type: ignore[no-any-return]
           ^^^^^^^^^^^^^^^^^^^^^^^^^^^^^^^^^^^^^^^^^^^^^^^^^^^^^^^^^^^^^^^^^
  File "/home/pipohkr01/xcobs2/dmg_clc/app.py", line 786, in index
    return render_template('cobs2.html', **context)
           ^^^^^^^^^^^^^^^^^^^^^^^^^^^^^^^^^^^^^^^^
  File "/home/pipohkr01/xcobs2/venv/lib/python3.11/site-packages/flask/templating.py", line 150, in render_template
    return _render(app, template, context)
           ^^^^^^^^^^^^^^^^^^^^^^^^^^^^^^^
  File "/home/pipohkr01/xcobs2/venv/lib/python3.11/site-packages/flask/templating.py", line 131, in _render
    rv = template.render(context)
         ^^^^^^^^^^^^^^^^^^^^^^^^
  File "/home/pipohkr01/xcobs2/venv/lib/python3.11/site-packages/jinja2/environment.py", line 1295, in render
    self.environment.handle_exception()
  File "/home/pipohkr01/xcobs2/venv/lib/python3.11/site-packages/jinja2/environment.py", line 942, in handle_exception
    raise rewrite_traceback_stack(source=source)
  File "/home/pipohkr01/xcobs2/dmg_clc/templates/cobs2.html", line 1, in top-level template code
    {% extends "base.html" %}
  File "/home/pipohkr01/xcobs2/dmg_clc/templates/base.html", line 56, in top-level template code
    {% block content %}{% endblock %}
    ^^^^^^^^^^^^^^^^^^^^^^^^^
  File "/home/pipohkr01/xcobs2/dmg_clc/templates/cobs2.html", line 6, in block 'content'
    {% include "partials/cobs2_content.html" %}
    ^^^^^^^^^^^^^^^^^^^^^^^^^
  File "/home/pipohkr01/xcobs2/venv/lib/python3.11/site-packages/jinja2/environment.py", line 942, in handle_exception
    raise rewrite_traceback_stack(source=source)
  File "/home/pipohkr01/xcobs2/dmg_clc/templates/partials/cobs2_content.html", line 272, in template
    <option  value="さみしがり"{% if char_Bl==’さみしがり’ %}selected{% endif %}>さみしがり</option>
    ^^^^^^^^^^^^^^^^^^^^^^^
jinja2.exceptions.TemplateSyntaxError: unexpected char '’' at 12846
[2025-08-02 08:14:06,892] ERROR in app: Exception on / [GET]
Traceback (most recent call last):
  File "/home/pipohkr01/xcobs2/venv/lib/python3.11/site-packages/flask/app.py", line 1511, in wsgi_app
    response = self.full_dispatch_request()
               ^^^^^^^^^^^^^^^^^^^^^^^^^^^^
  File "/home/pipohkr01/xcobs2/venv/lib/python3.11/site-packages/flask/app.py", line 919, in full_dispatch_request
    rv = self.handle_user_exception(e)
         ^^^^^^^^^^^^^^^^^^^^^^^^^^^^^
  File "/home/pipohkr01/xcobs2/venv/lib/python3.11/site-packages/flask/app.py", line 917, in full_dispatch_request
    rv = self.dispatch_request()
         ^^^^^^^^^^^^^^^^^^^^^^^
  File "/home/pipohkr01/xcobs2/venv/lib/python3.11/site-packages/flask/app.py", line 902, in dispatch_request
    return self.ensure_sync(self.view_functions[rule.endpoint])(**view_args)  # type: ignore[no-any-return]
           ^^^^^^^^^^^^^^^^^^^^^^^^^^^^^^^^^^^^^^^^^^^^^^^^^^^^^^^^^^^^^^^^^
  File "/home/pipohkr01/xcobs2/dmg_clc/app.py", line 786, in index
    return render_template('cobs2.html', **context)
           ^^^^^^^^^^^^^^^^^^^^^^^^^^^^^^^^^^^^^^^^
  File "/home/pipohkr01/xcobs2/venv/lib/python3.11/site-packages/flask/templating.py", line 150, in render_template
    return _render(app, template, context)
           ^^^^^^^^^^^^^^^^^^^^^^^^^^^^^^^
  File "/home/pipohkr01/xcobs2/venv/lib/python3.11/site-packages/flask/templating.py", line 131, in _render
    rv = template.render(context)
         ^^^^^^^^^^^^^^^^^^^^^^^^
  File "/home/pipohkr01/xcobs2/venv/lib/python3.11/site-packages/jinja2/environment.py", line 1295, in render
    self.environment.handle_exception()
  File "/home/pipohkr01/xcobs2/venv/lib/python3.11/site-packages/jinja2/environment.py", line 942, in handle_exception
    raise rewrite_traceback_stack(source=source)
  File "/home/pipohkr01/xcobs2/dmg_clc/templates/cobs2.html", line 1, in top-level template code
    {% extends "base.html" %}
  File "/home/pipohkr01/xcobs2/dmg_clc/templates/base.html", line 56, in top-level template code
    {% block content %}{% endblock %}
    ^^^^^^^^^^^^^^^^^^^^^^^^^
  File "/home/pipohkr01/xcobs2/dmg_clc/templates/cobs2.html", line 6, in block 'content'
    {% include "partials/cobs2_content.html" %}
    ^^^^^^^^^^^^^^^^^^^^^^^^^
  File "/home/pipohkr01/xcobs2/venv/lib/python3.11/site-packages/jinja2/environment.py", line 942, in handle_exception
    raise rewrite_traceback_stack(source=source)
  File "/home/pipohkr01/xcobs2/dmg_clc/templates/partials/cobs2_content.html", line 272, in template
    <option  value="さみしがり"{% if char_Bl==’さみしがり’ %}selected{% endif %}>さみしがり</option>
    ^^^^^^^^^^^^^^^^^^^^^^^
jinja2.exceptions.TemplateSyntaxError: unexpected char '’' at 12846
[2025-08-02 08:14:13,861] ERROR in app: Exception on / [GET]
Traceback (most recent call last):
  File "/home/pipohkr01/xcobs2/venv/lib/python3.11/site-packages/flask/app.py", line 1511, in wsgi_app
    response = self.full_dispatch_request()
               ^^^^^^^^^^^^^^^^^^^^^^^^^^^^
  File "/home/pipohkr01/xcobs2/venv/lib/python3.11/site-packages/flask/app.py", line 919, in full_dispatch_request
    rv = self.handle_user_exception(e)
         ^^^^^^^^^^^^^^^^^^^^^^^^^^^^^
  File "/home/pipohkr01/xcobs2/venv/lib/python3.11/site-packages/flask/app.py", line 917, in full_dispatch_request
    rv = self.dispatch_request()
         ^^^^^^^^^^^^^^^^^^^^^^^
  File "/home/pipohkr01/xcobs2/venv/lib/python3.11/site-packages/flask/app.py", line 902, in dispatch_request
    return self.ensure_sync(self.view_functions[rule.endpoint])(**view_args)  # type: ignore[no-any-return]
           ^^^^^^^^^^^^^^^^^^^^^^^^^^^^^^^^^^^^^^^^^^^^^^^^^^^^^^^^^^^^^^^^^
  File "/home/pipohkr01/xcobs2/dmg_clc/app.py", line 786, in index
    return render_template('cobs2.html', **context)
           ^^^^^^^^^^^^^^^^^^^^^^^^^^^^^^^^^^^^^^^^
  File "/home/pipohkr01/xcobs2/venv/lib/python3.11/site-packages/flask/templating.py", line 150, in render_template
    return _render(app, template, context)
           ^^^^^^^^^^^^^^^^^^^^^^^^^^^^^^^
  File "/home/pipohkr01/xcobs2/venv/lib/python3.11/site-packages/flask/templating.py", line 131, in _render
    rv = template.render(context)
         ^^^^^^^^^^^^^^^^^^^^^^^^
  File "/home/pipohkr01/xcobs2/venv/lib/python3.11/site-packages/jinja2/environment.py", line 1295, in render
    self.environment.handle_exception()
  File "/home/pipohkr01/xcobs2/venv/lib/python3.11/site-packages/jinja2/environment.py", line 942, in handle_exception
    raise rewrite_traceback_stack(source=source)
  File "/home/pipohkr01/xcobs2/dmg_clc/templates/cobs2.html", line 1, in top-level template code
    {% extends "base.html" %}
  File "/home/pipohkr01/xcobs2/dmg_clc/templates/base.html", line 56, in top-level template code
    {% block content %}{% endblock %}
    ^^^^^^^^^^^^^^^^^^^^^^^^^
  File "/home/pipohkr01/xcobs2/dmg_clc/templates/cobs2.html", line 6, in block 'content'
    {% include "partials/cobs2_content.html" %}
    ^^^^^^^^^^^^^^^^^^^^^^^^^
  File "/home/pipohkr01/xcobs2/venv/lib/python3.11/site-packages/jinja2/environment.py", line 942, in handle_exception
    raise rewrite_traceback_stack(source=source)
  File "/home/pipohkr01/xcobs2/dmg_clc/templates/partials/cobs2_content.html", line 272, in template
    <option  value="さみしがり"{% if char_Bl==’さみしがり’ %}selected{% endif %}>さみしがり</option>
    ^^^^^^^^^^^^^^^^^^^^^^^
jinja2.exceptions.TemplateSyntaxError: unexpected char '’' at 12846
[2025-08-02 08:14:26,904] ERROR in app: Exception on / [GET]
Traceback (most recent call last):
  File "/home/pipohkr01/xcobs2/venv/lib/python3.11/site-packages/flask/app.py", line 1511, in wsgi_app
    response = self.full_dispatch_request()
               ^^^^^^^^^^^^^^^^^^^^^^^^^^^^
  File "/home/pipohkr01/xcobs2/venv/lib/python3.11/site-packages/flask/app.py", line 919, in full_dispatch_request
    rv = self.handle_user_exception(e)
         ^^^^^^^^^^^^^^^^^^^^^^^^^^^^^
  File "/home/pipohkr01/xcobs2/venv/lib/python3.11/site-packages/flask/app.py", line 917, in full_dispatch_request
    rv = self.dispatch_request()
         ^^^^^^^^^^^^^^^^^^^^^^^
  File "/home/pipohkr01/xcobs2/venv/lib/python3.11/site-packages/flask/app.py", line 902, in dispatch_request
    return self.ensure_sync(self.view_functions[rule.endpoint])(**view_args)  # type: ignore[no-any-return]
           ^^^^^^^^^^^^^^^^^^^^^^^^^^^^^^^^^^^^^^^^^^^^^^^^^^^^^^^^^^^^^^^^^
  File "/home/pipohkr01/xcobs2/dmg_clc/app.py", line 786, in index
    return render_template('cobs2.html', **context)
           ^^^^^^^^^^^^^^^^^^^^^^^^^^^^^^^^^^^^^^^^
  File "/home/pipohkr01/xcobs2/venv/lib/python3.11/site-packages/flask/templating.py", line 150, in render_template
    return _render(app, template, context)
           ^^^^^^^^^^^^^^^^^^^^^^^^^^^^^^^
  File "/home/pipohkr01/xcobs2/venv/lib/python3.11/site-packages/flask/templating.py", line 131, in _render
    rv = template.render(context)
         ^^^^^^^^^^^^^^^^^^^^^^^^
  File "/home/pipohkr01/xcobs2/venv/lib/python3.11/site-packages/jinja2/environment.py", line 1295, in render
    self.environment.handle_exception()
  File "/home/pipohkr01/xcobs2/venv/lib/python3.11/site-packages/jinja2/environment.py", line 942, in handle_exception
    raise rewrite_traceback_stack(source=source)
  File "/home/pipohkr01/xcobs2/dmg_clc/templates/cobs2.html", line 1, in top-level template code
    {% extends "base.html" %}
  File "/home/pipohkr01/xcobs2/dmg_clc/templates/base.html", line 56, in top-level template code
    {% block content %}{% endblock %}
    ^^^^^^^^^^^^^^^^^^^^^^^^^
  File "/home/pipohkr01/xcobs2/dmg_clc/templates/cobs2.html", line 6, in block 'content'
    {% include "partials/cobs2_content.html" %}
    ^^^^^^^^^^^^^^^^^^^^^^^^^
  File "/home/pipohkr01/xcobs2/venv/lib/python3.11/site-packages/jinja2/environment.py", line 942, in handle_exception
    raise rewrite_traceback_stack(source=source)
  File "/home/pipohkr01/xcobs2/dmg_clc/templates/partials/cobs2_content.html", line 272, in template
    <option  value="さみしがり"{% if char_Bl==’さみしがり’ %}selected{% endif %}>さみしがり</option>
    ^^^^^^^^^^^^^^^^^^^^^^^
jinja2.exceptions.TemplateSyntaxError: unexpected char '’' at 12846
[2025-08-02 08:15:27 +0000] [184676] [INFO] Starting gunicorn 23.0.0
[2025-08-02 08:15:27 +0000] [184676] [ERROR] Connection in use: ('127.0.0.1', 8000)
[2025-08-02 08:15:27 +0000] [184676] [ERROR] connection to ('127.0.0.1', 8000) failed: [Errno 98] Address already in use
[2025-08-02 08:15:28 +0000] [184676] [ERROR] Connection in use: ('127.0.0.1', 8000)
[2025-08-02 08:15:28 +0000] [184676] [ERROR] connection to ('127.0.0.1', 8000) failed: [Errno 98] Address already in use
[2025-08-02 08:15:29 +0000] [184676] [ERROR] Connection in use: ('127.0.0.1', 8000)
[2025-08-02 08:15:29 +0000] [184676] [ERROR] connection to ('127.0.0.1', 8000) failed: [Errno 98] Address already in use
[2025-08-02 08:15:30,198] ERROR in app: Exception on / [GET]
Traceback (most recent call last):
  File "/home/pipohkr01/xcobs2/venv/lib/python3.11/site-packages/flask/app.py", line 1511, in wsgi_app
    response = self.full_dispatch_request()
               ^^^^^^^^^^^^^^^^^^^^^^^^^^^^
  File "/home/pipohkr01/xcobs2/venv/lib/python3.11/site-packages/flask/app.py", line 919, in full_dispatch_request
    rv = self.handle_user_exception(e)
         ^^^^^^^^^^^^^^^^^^^^^^^^^^^^^
  File "/home/pipohkr01/xcobs2/venv/lib/python3.11/site-packages/flask/app.py", line 917, in full_dispatch_request
    rv = self.dispatch_request()
         ^^^^^^^^^^^^^^^^^^^^^^^
  File "/home/pipohkr01/xcobs2/venv/lib/python3.11/site-packages/flask/app.py", line 902, in dispatch_request
    return self.ensure_sync(self.view_functions[rule.endpoint])(**view_args)  # type: ignore[no-any-return]
           ^^^^^^^^^^^^^^^^^^^^^^^^^^^^^^^^^^^^^^^^^^^^^^^^^^^^^^^^^^^^^^^^^
  File "/home/pipohkr01/xcobs2/dmg_clc/app.py", line 786, in index
    return render_template('cobs2.html', **context)
           ^^^^^^^^^^^^^^^^^^^^^^^^^^^^^^^^^^^^^^^^
  File "/home/pipohkr01/xcobs2/venv/lib/python3.11/site-packages/flask/templating.py", line 150, in render_template
    return _render(app, template, context)
           ^^^^^^^^^^^^^^^^^^^^^^^^^^^^^^^
  File "/home/pipohkr01/xcobs2/venv/lib/python3.11/site-packages/flask/templating.py", line 131, in _render
    rv = template.render(context)
         ^^^^^^^^^^^^^^^^^^^^^^^^
  File "/home/pipohkr01/xcobs2/venv/lib/python3.11/site-packages/jinja2/environment.py", line 1295, in render
    self.environment.handle_exception()
  File "/home/pipohkr01/xcobs2/venv/lib/python3.11/site-packages/jinja2/environment.py", line 942, in handle_exception
    raise rewrite_traceback_stack(source=source)
  File "/home/pipohkr01/xcobs2/dmg_clc/templates/cobs2.html", line 1, in top-level template code
    {% extends "base.html" %}
  File "/home/pipohkr01/xcobs2/dmg_clc/templates/base.html", line 56, in top-level template code
    {% block content %}{% endblock %}
    ^^^^^^^^^^^^^^^^^^^^^^^^^
  File "/home/pipohkr01/xcobs2/dmg_clc/templates/cobs2.html", line 6, in block 'content'
    {% include "partials/cobs2_content.html" %}
    ^^^^^^^^^^^^^^^^^^^^^^^^^
  File "/home/pipohkr01/xcobs2/venv/lib/python3.11/site-packages/jinja2/environment.py", line 942, in handle_exception
    raise rewrite_traceback_stack(source=source)
  File "/home/pipohkr01/xcobs2/dmg_clc/templates/partials/cobs2_content.html", line 272, in template
    <option  value="さみしがり"{% if char_Bl==’さみしがり’ %}selected{% endif %}>さみしがり</option>
    ^^^^^^^^^^^^^^^^^^^^^^^
jinja2.exceptions.TemplateSyntaxError: unexpected char '’' at 12846
[2025-08-02 08:15:30 +0000] [184676] [ERROR] Connection in use: ('127.0.0.1', 8000)
[2025-08-02 08:15:30 +0000] [184676] [ERROR] connection to ('127.0.0.1', 8000) failed: [Errno 98] Address already in use
[2025-08-02 08:15:31 +0000] [184676] [ERROR] Connection in use: ('127.0.0.1', 8000)
[2025-08-02 08:15:31 +0000] [184676] [ERROR] connection to ('127.0.0.1', 8000) failed: [Errno 98] Address already in use
[2025-08-02 08:15:32 +0000] [184676] [ERROR] Can't connect to ('127.0.0.1', 8000)
[2025-08-02 08:19:31 +0000] [182476] [INFO] Handling signal: term
[2025-08-02 08:19:31 +0000] [182478] [INFO] Worker exiting (pid: 182478)
[2025-08-02 08:19:31 +0000] [182477] [INFO] Worker exiting (pid: 182477)
[2025-08-02 08:19:31 +0000] [182479] [INFO] Worker exiting (pid: 182479)
[2025-08-02 08:19:31 +0000] [182480] [INFO] Worker exiting (pid: 182480)
[2025-08-02 08:19:32 +0000] [182476] [INFO] Shutting down: Master
[2025-08-02 08:20:14 +0000] [184702] [INFO] Starting gunicorn 23.0.0
[2025-08-02 08:20:14 +0000] [184702] [INFO] Listening at: http://127.0.0.1:8000 (184702)
[2025-08-02 08:20:14 +0000] [184702] [INFO] Using worker: sync
[2025-08-02 08:20:14 +0000] [184703] [INFO] Booting worker with pid: 184703
[2025-08-02 08:20:14 +0000] [184704] [INFO] Booting worker with pid: 184704
[2025-08-02 08:20:14 +0000] [184705] [INFO] Booting worker with pid: 184705
[2025-08-02 08:20:15 +0000] [184706] [INFO] Booting worker with pid: 184706
[2025-08-02 08:20:19,894] ERROR in app: Exception on / [GET]
Traceback (most recent call last):
  File "/home/pipohkr01/xcobs2/venv/lib/python3.11/site-packages/flask/app.py", line 1511, in wsgi_app
    response = self.full_dispatch_request()
               ^^^^^^^^^^^^^^^^^^^^^^^^^^^^
  File "/home/pipohkr01/xcobs2/venv/lib/python3.11/site-packages/flask/app.py", line 919, in full_dispatch_request
    rv = self.handle_user_exception(e)
         ^^^^^^^^^^^^^^^^^^^^^^^^^^^^^
  File "/home/pipohkr01/xcobs2/venv/lib/python3.11/site-packages/flask/app.py", line 917, in full_dispatch_request
    rv = self.dispatch_request()
         ^^^^^^^^^^^^^^^^^^^^^^^
  File "/home/pipohkr01/xcobs2/venv/lib/python3.11/site-packages/flask/app.py", line 902, in dispatch_request
    return self.ensure_sync(self.view_functions[rule.endpoint])(**view_args)  # type: ignore[no-any-return]
           ^^^^^^^^^^^^^^^^^^^^^^^^^^^^^^^^^^^^^^^^^^^^^^^^^^^^^^^^^^^^^^^^^
  File "/home/pipohkr01/xcobs2/dmg_clc/app.py", line 786, in index
    return render_template('cobs2.html', **context)
           ^^^^^^^^^^^^^^^^^^^^^^^^^^^^^^^^^^^^^^^^
  File "/home/pipohkr01/xcobs2/venv/lib/python3.11/site-packages/flask/templating.py", line 150, in render_template
    return _render(app, template, context)
           ^^^^^^^^^^^^^^^^^^^^^^^^^^^^^^^
  File "/home/pipohkr01/xcobs2/venv/lib/python3.11/site-packages/flask/templating.py", line 131, in _render
    rv = template.render(context)
         ^^^^^^^^^^^^^^^^^^^^^^^^
  File "/home/pipohkr01/xcobs2/venv/lib/python3.11/site-packages/jinja2/environment.py", line 1295, in render
    self.environment.handle_exception()
  File "/home/pipohkr01/xcobs2/venv/lib/python3.11/site-packages/jinja2/environment.py", line 942, in handle_exception
    raise rewrite_traceback_stack(source=source)
  File "/home/pipohkr01/xcobs2/dmg_clc/templates/cobs2.html", line 1, in top-level template code
    {% extends "base.html" %}
  File "/home/pipohkr01/xcobs2/dmg_clc/templates/base.html", line 56, in top-level template code
    {% block content %}{% endblock %}
    ^^^^^^^^^^^^^^^^^^^^^^^^^
  File "/home/pipohkr01/xcobs2/dmg_clc/templates/cobs2.html", line 6, in block 'content'
    {% include "partials/cobs2_content.html" %}
    ^^^^^^^^^^^^^^^^^^^^^^^^^
  File "/home/pipohkr01/xcobs2/venv/lib/python3.11/site-packages/jinja2/environment.py", line 942, in handle_exception
    raise rewrite_traceback_stack(source=source)
  File "/home/pipohkr01/xcobs2/dmg_clc/templates/partials/cobs2_content.html", line 272, in template
    <option  value="さみしがり"{% if char_Bl==’さみしがり’ %}selected{% endif %}>さみしがり</option>
    ^^^^^^^^^^^^^^^^^^^^^^^
jinja2.exceptions.TemplateSyntaxError: unexpected char '’' at 12848
[2025-08-02 08:21:08,129] ERROR in app: Exception on / [GET]
Traceback (most recent call last):
  File "/home/pipohkr01/xcobs2/venv/lib/python3.11/site-packages/flask/app.py", line 1511, in wsgi_app
    response = self.full_dispatch_request()
               ^^^^^^^^^^^^^^^^^^^^^^^^^^^^
  File "/home/pipohkr01/xcobs2/venv/lib/python3.11/site-packages/flask/app.py", line 919, in full_dispatch_request
    rv = self.handle_user_exception(e)
         ^^^^^^^^^^^^^^^^^^^^^^^^^^^^^
  File "/home/pipohkr01/xcobs2/venv/lib/python3.11/site-packages/flask/app.py", line 917, in full_dispatch_request
    rv = self.dispatch_request()
         ^^^^^^^^^^^^^^^^^^^^^^^
  File "/home/pipohkr01/xcobs2/venv/lib/python3.11/site-packages/flask/app.py", line 902, in dispatch_request
    return self.ensure_sync(self.view_functions[rule.endpoint])(**view_args)  # type: ignore[no-any-return]
           ^^^^^^^^^^^^^^^^^^^^^^^^^^^^^^^^^^^^^^^^^^^^^^^^^^^^^^^^^^^^^^^^^
  File "/home/pipohkr01/xcobs2/dmg_clc/app.py", line 786, in index
    return render_template('cobs2.html', **context)
           ^^^^^^^^^^^^^^^^^^^^^^^^^^^^^^^^^^^^^^^^
  File "/home/pipohkr01/xcobs2/venv/lib/python3.11/site-packages/flask/templating.py", line 150, in render_template
    return _render(app, template, context)
           ^^^^^^^^^^^^^^^^^^^^^^^^^^^^^^^
  File "/home/pipohkr01/xcobs2/venv/lib/python3.11/site-packages/flask/templating.py", line 131, in _render
    rv = template.render(context)
         ^^^^^^^^^^^^^^^^^^^^^^^^
  File "/home/pipohkr01/xcobs2/venv/lib/python3.11/site-packages/jinja2/environment.py", line 1295, in render
    self.environment.handle_exception()
  File "/home/pipohkr01/xcobs2/venv/lib/python3.11/site-packages/jinja2/environment.py", line 942, in handle_exception
    raise rewrite_traceback_stack(source=source)
  File "/home/pipohkr01/xcobs2/dmg_clc/templates/cobs2.html", line 1, in top-level template code
    {% extends "base.html" %}
  File "/home/pipohkr01/xcobs2/dmg_clc/templates/base.html", line 56, in top-level template code
    {% block content %}{% endblock %}
    ^^^^^^^^^^^^^^^^^^^^^^^^^
  File "/home/pipohkr01/xcobs2/dmg_clc/templates/cobs2.html", line 6, in block 'content'
    {% include "partials/cobs2_content.html" %}
    ^^^^^^^^^^^^^^^^^^^^^^^^^
  File "/home/pipohkr01/xcobs2/venv/lib/python3.11/site-packages/jinja2/environment.py", line 942, in handle_exception
    raise rewrite_traceback_stack(source=source)
  File "/home/pipohkr01/xcobs2/dmg_clc/templates/partials/cobs2_content.html", line 272, in template
    <option  value="さみしがり"{% if char_Bl==’さみしがり’ %}selected{% endif %}>さみしがり</option>
    ^^^^^^^^^^^^^^^^^^^^^^^
jinja2.exceptions.TemplateSyntaxError: unexpected char '’' at 12848
[2025-08-02 08:21:11,232] ERROR in app: Exception on / [GET]
Traceback (most recent call last):
  File "/home/pipohkr01/xcobs2/venv/lib/python3.11/site-packages/flask/app.py", line 1511, in wsgi_app
    response = self.full_dispatch_request()
               ^^^^^^^^^^^^^^^^^^^^^^^^^^^^
  File "/home/pipohkr01/xcobs2/venv/lib/python3.11/site-packages/flask/app.py", line 919, in full_dispatch_request
    rv = self.handle_user_exception(e)
         ^^^^^^^^^^^^^^^^^^^^^^^^^^^^^
  File "/home/pipohkr01/xcobs2/venv/lib/python3.11/site-packages/flask/app.py", line 917, in full_dispatch_request
    rv = self.dispatch_request()
         ^^^^^^^^^^^^^^^^^^^^^^^
  File "/home/pipohkr01/xcobs2/venv/lib/python3.11/site-packages/flask/app.py", line 902, in dispatch_request
    return self.ensure_sync(self.view_functions[rule.endpoint])(**view_args)  # type: ignore[no-any-return]
           ^^^^^^^^^^^^^^^^^^^^^^^^^^^^^^^^^^^^^^^^^^^^^^^^^^^^^^^^^^^^^^^^^
  File "/home/pipohkr01/xcobs2/dmg_clc/app.py", line 786, in index
    return render_template('cobs2.html', **context)
           ^^^^^^^^^^^^^^^^^^^^^^^^^^^^^^^^^^^^^^^^
  File "/home/pipohkr01/xcobs2/venv/lib/python3.11/site-packages/flask/templating.py", line 150, in render_template
    return _render(app, template, context)
           ^^^^^^^^^^^^^^^^^^^^^^^^^^^^^^^
  File "/home/pipohkr01/xcobs2/venv/lib/python3.11/site-packages/flask/templating.py", line 131, in _render
    rv = template.render(context)
         ^^^^^^^^^^^^^^^^^^^^^^^^
  File "/home/pipohkr01/xcobs2/venv/lib/python3.11/site-packages/jinja2/environment.py", line 1295, in render
    self.environment.handle_exception()
  File "/home/pipohkr01/xcobs2/venv/lib/python3.11/site-packages/jinja2/environment.py", line 942, in handle_exception
    raise rewrite_traceback_stack(source=source)
  File "/home/pipohkr01/xcobs2/dmg_clc/templates/cobs2.html", line 1, in top-level template code
    {% extends "base.html" %}
  File "/home/pipohkr01/xcobs2/dmg_clc/templates/base.html", line 56, in top-level template code
    {% block content %}{% endblock %}
    ^^^^^^^^^^^^^^^^^^^^^^^^^
  File "/home/pipohkr01/xcobs2/dmg_clc/templates/cobs2.html", line 6, in block 'content'
    {% include "partials/cobs2_content.html" %}
    ^^^^^^^^^^^^^^^^^^^^^^^^^
  File "/home/pipohkr01/xcobs2/venv/lib/python3.11/site-packages/jinja2/environment.py", line 942, in handle_exception
    raise rewrite_traceback_stack(source=source)
  File "/home/pipohkr01/xcobs2/dmg_clc/templates/partials/cobs2_content.html", line 272, in template
    <option  value="さみしがり"{% if char_Bl==’さみしがり’ %}selected{% endif %}>さみしがり</option>
    ^^^^^^^^^^^^^^^^^^^^^^^
jinja2.exceptions.TemplateSyntaxError: unexpected char '’' at 12848
[2025-08-02 08:22:49 +0000] [184702] [INFO] Handling signal: term
[2025-08-02 08:22:49 +0000] [184703] [INFO] Worker exiting (pid: 184703)
[2025-08-02 08:22:49 +0000] [184706] [INFO] Worker exiting (pid: 184706)
[2025-08-02 08:22:49 +0000] [184704] [INFO] Worker exiting (pid: 184704)
[2025-08-02 08:22:49 +0000] [184705] [INFO] Worker exiting (pid: 184705)
[2025-08-02 08:22:50 +0000] [184702] [INFO] Shutting down: Master
[2025-08-02 08:35:03 +0000] [186094] [INFO] Starting gunicorn 23.0.0
[2025-08-02 08:35:03 +0000] [186094] [INFO] Listening at: http://127.0.0.1:8000 (186094)
[2025-08-02 08:35:03 +0000] [186094] [INFO] Using worker: sync
[2025-08-02 08:35:03 +0000] [186095] [INFO] Booting worker with pid: 186095
[2025-08-02 08:35:04 +0000] [186096] [INFO] Booting worker with pid: 186096
[2025-08-02 08:35:04 +0000] [186097] [INFO] Booting worker with pid: 186097
[2025-08-02 08:35:04 +0000] [186098] [INFO] Booting worker with pid: 186098
[2025-08-02 08:51:00 +0000] [186094] [INFO] Handling signal: term
[2025-08-02 08:51:00 +0000] [186097] [INFO] Worker exiting (pid: 186097)
[2025-08-02 08:51:00 +0000] [186095] [INFO] Worker exiting (pid: 186095)
100 31 252 50 さみしがり
155 125 31 252 50 さみしがり
みず みず None あく じめん
False False
ノーマル ノーマル
1.1 1.0 0.9 1.0
262 167.20000000000002 202.0 159.3 132.0
22
130
フィールド補正:1.0
130
攻撃補正
防御補正
天候補正:1.5
タイプ一致
タイプ一致1.5
タイプ相性補正: 2.0
いのちのたまありけり
基本ダメージ
22 130 202.0 132.0
ん？
517
ダメ計終了
262 167.20000000000002 202.0 159.3 132.0
155
[2025-08-02 08:51:00 +0000] [186096] [INFO] Worker exiting (pid: 186096)
[2025-08-02 08:51:00 +0000] [186098] [INFO] Worker exiting (pid: 186098)
[2025-08-02 08:51:01 +0000] [186094] [INFO] Shutting down: Master
[2025-08-02 08:52:42 +0000] [187450] [INFO] Starting gunicorn 23.0.0
[2025-08-02 08:52:42 +0000] [187450] [INFO] Listening at: http://127.0.0.1:8000 (187450)
[2025-08-02 08:52:42 +0000] [187450] [INFO] Using worker: sync
[2025-08-02 08:52:42 +0000] [187451] [INFO] Booting worker with pid: 187451
[2025-08-02 08:52:42 +0000] [187452] [INFO] Booting worker with pid: 187452
[2025-08-02 08:52:42 +0000] [187453] [INFO] Booting worker with pid: 187453
[2025-08-02 08:52:42 +0000] [187454] [INFO] Booting worker with pid: 187454
[2025-08-02 09:41:42 +0000] [187450] [INFO] Handling signal: term
[2025-08-02 09:41:42 +0000] [187452] [INFO] Worker exiting (pid: 187452)
[2025-08-02 09:41:42 +0000] [187454] [INFO] Worker exiting (pid: 187454)
100 31 252 50 さみしがり
155 125 31 252 50 さみしがり
みず みず None あく じめん
True False
みず ノーマル
1.1 1.0 0.9 1.0
262 167.20000000000002 202.0 159.3 132.0
22
130
フィールド補正:1.0
130
攻撃補正
防御補正
天候補正:1.5
攻撃側テラス
両方一致タイプ一致
タイプ一致2.0
タイプ相性補正: 2.0
基本ダメージ
22 130 202.0 132.0
ん？
532
ダメ計終了
防御側ダイマックス適用: レベル=10, 倍率=2.0
524 167.20000000000002 202.0 159.3 132.0
310
262 167.20000000000002 202.0 159.3 132.0
155
防御側ダイマ
100 31 252 50 さみしがり
155 125 31 252 50 さみしがり
みず みず None あく じめん
False False
ノーマル ノーマル
1.1 1.0 0.9 1.0
262 167.20000000000002 202.0 159.3 132.0
22
130
フィールド補正:1.0
130
攻撃補正
防御補正
天候補正:1
タイプ一致
タイプ一致1.5
タイプ相性補正: 2.0
基本ダメージ
22 130 167 159
あれ
186
ダメ計終了
262 167.20000000000002 202.0 159.3 132.0
155
100 31 252 50 さみしがり
155 125 31 252 50 さみしがり
みず みず None あく じめん
True False
みず ノーマル
1.1 1.0 0.9 1.0
262 167.20000000000002 202.0 159.3 132.0
22
130
フィールド補正:1.0
130
攻撃補正
防御補正
天候補正:1
攻撃側テラス
両方一致タイプ一致
タイプ一致2.0
タイプ相性補正: 2.0
基本ダメージ
22 130 167 159
あれ
248
ダメ計終了
262 167.20000000000002 202.0 159.3 132.0
155
100 31 252 50 さみしがり
155 125 31 252 50 さみしがり
ノーマル みず None あく じめん
False False
ノーマル ノーマル
1.1 1.0 0.9 1.0
262 167.20000000000002 202.0 159.3 132.0
22
130
フィールド補正:1.0
130
攻撃補正
防御補正
天候補正:1
タイプ一致1.0
タイプ相性補正: 1.0
基本ダメージ
22 130 202.0 132.0
ん？
89
ダメ計終了
262 167.20000000000002 202.0 159.3 132.0
155
100 31 252 50 さみしがり
155 125 31 252 50 さみしがり
ノーマル みず None あく じめん
False False
ノーマル ノーマル
1.1 1.0 0.9 1.0
262 167.20000000000002 202.0 159.3 132.0
22
130
フィールド補正:1.0
130
攻撃補正
防御補正
天候補正:1
タイプ一致1.0
タイプ相性補正: 1.0
基本ダメージ
22 130 167 159
あれ
62
ダメ計終了
262 167.20000000000002 202.0 159.3 132.0
155
100 31 252 50 さみしがり
155 125 31 252 50 さみしがり
みず みず None あく じめん
False False
ノーマル ノーマル
1.1 1.0 0.9 1.0
262 167.20000000000002 202.0 159.3 132.0
22
130
フィールド補正:1.0
130
攻撃補正
防御補正
天候補正:1
タイプ一致
タイプ一致1.5
タイプ相性補正: 2.0
基本ダメージ
22 130 167 159
あれ
186
ダメ計終了
262 167.20000000000002 202.0 159.3 132.0
155
[2025-08-02 09:41:42 +0000] [187451] [INFO] Worker exiting (pid: 187451)
100 31 252 50 さみしがり
155 125 31 252 50 さみしがり
ノーマル みず None あく じめん
True False
みず ノーマル
1.1 1.0 0.9 1.0
262 167.20000000000002 202.0 159.3 132.0
22
130
フィールド補正:1.0
130
攻撃補正
防御補正
天候補正:1
攻撃側テラス
タイプ一致1.0
タイプ相性補正: 1.0
基本ダメージ
22 130 167 159
あれ
62
ダメ計終了
262 167.20000000000002 202.0 159.3 132.0
155
100 31 252 50 さみしがり
155 125 31 252 50 さみしがり
みず みず None あく じめん
True False
みず ノーマル
1.1 1.0 0.9 1.0
262 167.20000000000002 202.0 159.3 132.0
22
130
フィールド補正:1.0
130
攻撃補正
防御補正
天候補正:1
攻撃側テラス
両方一致タイプ一致
タイプ一致2.0
タイプ相性補正: 2.0
基本ダメージ
22 130 202.0 132.0
ん？
356
ダメ計終了
防御側ダイマックス適用: レベル=10, 倍率=2.0
524 167.20000000000002 202.0 159.3 132.0
310
262 167.20000000000002 202.0 159.3 132.0
155
防御側ダイマ
100 31 252 50 むじゃき
155 125 31 252 50 さみしがり
みず みず None あく じめん
False False
ノーマル ノーマル
1.0 1.0 0.9 1.0
262 152.0 202.0 159.3 132.0
22
130
フィールド補正:1.0
130
攻撃補正
防御補正
天候補正:1
タイプ一致
タイプ一致1.5
タイプ相性補正: 2.0
基本ダメージ
22 130 202.0 132.0
ん？
266
ダメ計終了
262 152.0 202.0 159.3 132.0
155
[2025-08-02 09:41:42 +0000] [187453] [INFO] Worker exiting (pid: 187453)
100 31 252 50 さみしがり
155 125 31 252 50 さみしがり
ノーマル みず None あく じめん
False False
ノーマル ノーマル
1.1 1.0 0.9 1.0
262 167.20000000000002 202.0 159.3 132.0
22
1
フィールド補正:1.0
1
攻撃補正
防御補正
天候補正:1
タイプ一致1.0
タイプ相性補正: 1.0
基本ダメージ
22 1 167 159
あれ
2
ダメ計終了
262 167.20000000000002 202.0 159.3 132.0
155
100 31 252 50 さみしがり
155 125 31 252 50 さみしがり
ノーマル みず None あく じめん
False False
ノーマル ノーマル
1.1 1.0 0.9 1.0
262 167.20000000000002 202.0 159.3 132.0
22
1
フィールド補正:1.0
1
攻撃補正
防御補正
天候補正:1
タイプ一致1.0
タイプ相性補正: 1.0
基本ダメージ
22 1 167 159
あれ
2
ダメ計終了
262 167.20000000000002 202.0 159.3 132.0
155
100 31 252 50 さみしがり
155 125 31 252 50 さみしがり
みず みず None あく じめん
True False
みず ノーマル
1.1 1.0 0.9 1.0
262 167.20000000000002 202.0 159.3 132.0
22
130
フィールド補正:1.0
130
攻撃補正
防御補正
天候補正:1
攻撃側テラス
両方一致タイプ一致
タイプ一致2.0
タイプ相性補正: 2.0
いのちのたまありけり
基本ダメージ
22 130 202.0 132.0
ん？
463
ダメ計終了
262 167.20000000000002 202.0 159.3 132.0
155
100 31 252 50 さみしがり
155 125 31 252 50 さみしがり
ノーマル みず None あく じめん
True False
みず ノーマル
1.1 1.0 0.9 1.0
262 167.20000000000002 202.0 159.3 132.0
22
130
フィールド補正:1.0
130
攻撃補正
防御補正
天候補正:1
攻撃側テラス
タイプ一致1.0
タイプ相性補正: 1.0
基本ダメージ
22 130 202.0 132.0
ん？
89
ダメ計終了
防御側ダイマックス適用: レベル=10, 倍率=2.0
524 167.20000000000002 202.0 159.3 132.0
310
262 167.20000000000002 202.0 159.3 132.0
155
防御側ダイマ
100 31 252 50 さみしがり
155 125 31 252 50 さみしがり
みず みず None あく じめん
False False
ノーマル ノーマル
1.1 1.0 0.9 1.0
262 167.20000000000002 202.0 159.3 132.0
22
130
フィールド補正:1.0
130
攻撃補正
防御補正
天候補正:1.5
タイプ一致
タイプ一致1.5
タイプ相性補正: 2.0
いのちのたまありけり
基本ダメージ
22 130 167 159
あれ
361
ダメ計終了
262 167.20000000000002 202.0 159.3 132.0
155
100 31 252 50 ひかえめ
155 125 31 252 50 さみしがり
みず みず None あく じめん
False False
ノーマル ノーマル
0.9 1.1 0.9 1.0
262 136.8 222.20000000000002 159.3 132.0
22
130
フィールド補正:1.0
130
攻撃補正
防御補正
天候補正:1
タイプ一致
タイプ一致1.5
タイプ相性補正: 2.0
基本ダメージ
22 130 222.20000000000002 132.0
ん？
294
ダメ計終了
262 136.8 222.20000000000002 159.3 132.0
155
[2025-08-02 09:41:43 +0000] [187450] [INFO] Shutting down: Master
[2025-08-02 09:41:50 +0000] [190793] [INFO] Starting gunicorn 23.0.0
[2025-08-02 09:41:50 +0000] [190793] [INFO] Listening at: http://127.0.0.1:8000 (190793)
[2025-08-02 09:41:50 +0000] [190793] [INFO] Using worker: sync
[2025-08-02 09:41:50 +0000] [190794] [INFO] Booting worker with pid: 190794
[2025-08-02 09:41:50 +0000] [190794] [ERROR] Exception in worker process
Traceback (most recent call last):
  File "/home/pipohkr01/xcobs2/venv/lib/python3.11/site-packages/gunicorn/arbiter.py", line 608, in spawn_worker
    worker.init_process()
  File "/home/pipohkr01/xcobs2/venv/lib/python3.11/site-packages/gunicorn/workers/base.py", line 135, in init_process
    self.load_wsgi()
  File "/home/pipohkr01/xcobs2/venv/lib/python3.11/site-packages/gunicorn/workers/base.py", line 147, in load_wsgi
    self.wsgi = self.app.wsgi()
                ^^^^^^^^^^^^^^^
  File "/home/pipohkr01/xcobs2/venv/lib/python3.11/site-packages/gunicorn/app/base.py", line 66, in wsgi
    self.callable = self.load()
                    ^^^^^^^^^^^
  File "/home/pipohkr01/xcobs2/venv/lib/python3.11/site-packages/gunicorn/app/wsgiapp.py", line 57, in load
    return self.load_wsgiapp()
           ^^^^^^^^^^^^^^^^^^^
  File "/home/pipohkr01/xcobs2/venv/lib/python3.11/site-packages/gunicorn/app/wsgiapp.py", line 47, in load_wsgiapp
    return util.import_app(self.app_uri)
           ^^^^^^^^^^^^^^^^^^^^^^^^^^^^^
  File "/home/pipohkr01/xcobs2/venv/lib/python3.11/site-packages/gunicorn/util.py", line 370, in import_app
    mod = importlib.import_module(module)
          ^^^^^^^^^^^^^^^^^^^^^^^^^^^^^^^
  File "/usr/lib/python3.11/importlib/__init__.py", line 126, in import_module
    return _bootstrap._gcd_import(name[level:], package, level)
           ^^^^^^^^^^^^^^^^^^^^^^^^^^^^^^^^^^^^^^^^^^^^^^^^^^^^
  File "<frozen importlib._bootstrap>", line 1206, in _gcd_import
  File "<frozen importlib._bootstrap>", line 1178, in _find_and_load
  File "<frozen importlib._bootstrap>", line 1149, in _find_and_load_unlocked
  File "<frozen importlib._bootstrap>", line 690, in _load_unlocked
  File "<frozen importlib._bootstrap_external>", line 936, in exec_module
  File "<frozen importlib._bootstrap_external>", line 1074, in get_code
  File "<frozen importlib._bootstrap_external>", line 1004, in source_to_code
  File "<frozen importlib._bootstrap>", line 241, in _call_with_frames_removed
  File "/home/pipohkr01/xcobs2/dmg_clc/app.py", line 312
    	    lv = int(request.form.get('lv', session.get('lv', 0)) or 0)
    ^
TabError: inconsistent use of tabs and spaces in indentation
[2025-08-02 09:41:50 +0000] [190794] [INFO] Worker exiting (pid: 190794)
[2025-08-02 09:41:50 +0000] [190795] [INFO] Booting worker with pid: 190795
[2025-08-02 09:41:50 +0000] [190793] [ERROR] Worker (pid:190794) exited with code 3
[2025-08-02 09:41:50 +0000] [190795] [ERROR] Exception in worker process
Traceback (most recent call last):
  File "/home/pipohkr01/xcobs2/venv/lib/python3.11/site-packages/gunicorn/arbiter.py", line 608, in spawn_worker
    worker.init_process()
  File "/home/pipohkr01/xcobs2/venv/lib/python3.11/site-packages/gunicorn/workers/base.py", line 135, in init_process
    self.load_wsgi()
  File "/home/pipohkr01/xcobs2/venv/lib/python3.11/site-packages/gunicorn/workers/base.py", line 147, in load_wsgi
    self.wsgi = self.app.wsgi()
                ^^^^^^^^^^^^^^^
  File "/home/pipohkr01/xcobs2/venv/lib/python3.11/site-packages/gunicorn/app/base.py", line 66, in wsgi
    self.callable = self.load()
                    ^^^^^^^^^^^
  File "/home/pipohkr01/xcobs2/venv/lib/python3.11/site-packages/gunicorn/app/wsgiapp.py", line 57, in load
    return self.load_wsgiapp()
           ^^^^^^^^^^^^^^^^^^^
  File "/home/pipohkr01/xcobs2/venv/lib/python3.11/site-packages/gunicorn/app/wsgiapp.py", line 47, in load_wsgiapp
    return util.import_app(self.app_uri)
           ^^^^^^^^^^^^^^^^^^^^^^^^^^^^^
  File "/home/pipohkr01/xcobs2/venv/lib/python3.11/site-packages/gunicorn/util.py", line 370, in import_app
    mod = importlib.import_module(module)
          ^^^^^^^^^^^^^^^^^^^^^^^^^^^^^^^
  File "/usr/lib/python3.11/importlib/__init__.py", line 126, in import_module
    return _bootstrap._gcd_import(name[level:], package, level)
           ^^^^^^^^^^^^^^^^^^^^^^^^^^^^^^^^^^^^^^^^^^^^^^^^^^^^
  File "<frozen importlib._bootstrap>", line 1206, in _gcd_import
  File "<frozen importlib._bootstrap>", line 1178, in _find_and_load
  File "<frozen importlib._bootstrap>", line 1149, in _find_and_load_unlocked
  File "<frozen importlib._bootstrap>", line 690, in _load_unlocked
  File "<frozen importlib._bootstrap_external>", line 936, in exec_module
  File "<frozen importlib._bootstrap_external>", line 1074, in get_code
  File "<frozen importlib._bootstrap_external>", line 1004, in source_to_code
  File "<frozen importlib._bootstrap>", line 241, in _call_with_frames_removed
  File "/home/pipohkr01/xcobs2/dmg_clc/app.py", line 312
    	    lv = int(request.form.get('lv', session.get('lv', 0)) or 0)
    ^
TabError: inconsistent use of tabs and spaces in indentation
[2025-08-02 09:41:50 +0000] [190795] [INFO] Worker exiting (pid: 190795)
[2025-08-02 09:41:50 +0000] [190793] [ERROR] Worker (pid:190795) exited with code 3
Traceback (most recent call last):
  File "/home/pipohkr01/xcobs2/venv/lib/python3.11/site-packages/gunicorn/arbiter.py", line 201, in run
    self.manage_workers()
  File "/home/pipohkr01/xcobs2/venv/lib/python3.11/site-packages/gunicorn/arbiter.py", line 570, in manage_workers
    self.spawn_workers()
  File "/home/pipohkr01/xcobs2/venv/lib/python3.11/site-packages/gunicorn/arbiter.py", line 642, in spawn_workers
    time.sleep(0.1 * random.random())
  File "/home/pipohkr01/xcobs2/venv/lib/python3.11/site-packages/gunicorn/arbiter.py", line 241, in handle_chld
    self.reap_workers()
  File "/home/pipohkr01/xcobs2/venv/lib/python3.11/site-packages/gunicorn/arbiter.py", line 529, in reap_workers
    raise HaltServer(reason, self.WORKER_BOOT_ERROR)
gunicorn.errors.HaltServer: <HaltServer 'Worker failed to boot.' 3>

During handling of the above exception, another exception occurred:

Traceback (most recent call last):
  File "/home/pipohkr01/xcobs2/venv/bin/gunicorn", line 8, in <module>
    sys.exit(run())
             ^^^^^
  File "/home/pipohkr01/xcobs2/venv/lib/python3.11/site-packages/gunicorn/app/wsgiapp.py", line 66, in run
    WSGIApplication("%(prog)s [OPTIONS] [APP_MODULE]", prog=prog).run()
  File "/home/pipohkr01/xcobs2/venv/lib/python3.11/site-packages/gunicorn/app/base.py", line 235, in run
    super().run()
  File "/home/pipohkr01/xcobs2/venv/lib/python3.11/site-packages/gunicorn/app/base.py", line 71, in run
    Arbiter(self).run()
  File "/home/pipohkr01/xcobs2/venv/lib/python3.11/site-packages/gunicorn/arbiter.py", line 228, in run
    self.halt(reason=inst.reason, exit_status=inst.exit_status)
  File "/home/pipohkr01/xcobs2/venv/lib/python3.11/site-packages/gunicorn/arbiter.py", line 341, in halt
    self.stop()
  File "/home/pipohkr01/xcobs2/venv/lib/python3.11/site-packages/gunicorn/arbiter.py", line 395, in stop
    time.sleep(0.1)
  File "/home/pipohkr01/xcobs2/venv/lib/python3.11/site-packages/gunicorn/arbiter.py", line 241, in handle_chld
    self.reap_workers()
  File "/home/pipohkr01/xcobs2/venv/lib/python3.11/site-packages/gunicorn/arbiter.py", line 529, in reap_workers
    raise HaltServer(reason, self.WORKER_BOOT_ERROR)
gunicorn.errors.HaltServer: <HaltServer 'Worker failed to boot.' 3>
[2025-08-02 09:42:31 +0000] [190796] [INFO] Starting gunicorn 23.0.0
[2025-08-02 09:42:31 +0000] [190796] [INFO] Listening at: http://127.0.0.1:8000 (190796)
[2025-08-02 09:42:31 +0000] [190796] [INFO] Using worker: sync
[2025-08-02 09:42:31 +0000] [190797] [INFO] Booting worker with pid: 190797
[2025-08-02 09:42:31 +0000] [190798] [INFO] Booting worker with pid: 190798
[2025-08-02 09:42:31 +0000] [190797] [ERROR] Exception in worker process
Traceback (most recent call last):
  File "/home/pipohkr01/xcobs2/venv/lib/python3.11/site-packages/gunicorn/arbiter.py", line 608, in spawn_worker
    worker.init_process()
  File "/home/pipohkr01/xcobs2/venv/lib/python3.11/site-packages/gunicorn/workers/base.py", line 135, in init_process
    self.load_wsgi()
  File "/home/pipohkr01/xcobs2/venv/lib/python3.11/site-packages/gunicorn/workers/base.py", line 147, in load_wsgi
    self.wsgi = self.app.wsgi()
                ^^^^^^^^^^^^^^^
  File "/home/pipohkr01/xcobs2/venv/lib/python3.11/site-packages/gunicorn/app/base.py", line 66, in wsgi
    self.callable = self.load()
                    ^^^^^^^^^^^
  File "/home/pipohkr01/xcobs2/venv/lib/python3.11/site-packages/gunicorn/app/wsgiapp.py", line 57, in load
    return self.load_wsgiapp()
           ^^^^^^^^^^^^^^^^^^^
  File "/home/pipohkr01/xcobs2/venv/lib/python3.11/site-packages/gunicorn/app/wsgiapp.py", line 47, in load_wsgiapp
    return util.import_app(self.app_uri)
           ^^^^^^^^^^^^^^^^^^^^^^^^^^^^^
  File "/home/pipohkr01/xcobs2/venv/lib/python3.11/site-packages/gunicorn/util.py", line 370, in import_app
    mod = importlib.import_module(module)
          ^^^^^^^^^^^^^^^^^^^^^^^^^^^^^^^
  File "/usr/lib/python3.11/importlib/__init__.py", line 126, in import_module
    return _bootstrap._gcd_import(name[level:], package, level)
           ^^^^^^^^^^^^^^^^^^^^^^^^^^^^^^^^^^^^^^^^^^^^^^^^^^^^
  File "<frozen importlib._bootstrap>", line 1206, in _gcd_import
  File "<frozen importlib._bootstrap>", line 1178, in _find_and_load
  File "<frozen importlib._bootstrap>", line 1149, in _find_and_load_unlocked
  File "<frozen importlib._bootstrap>", line 690, in _load_unlocked
  File "<frozen importlib._bootstrap_external>", line 936, in exec_module
  File "<frozen importlib._bootstrap_external>", line 1074, in get_code
  File "<frozen importlib._bootstrap_external>", line 1004, in source_to_code
  File "<frozen importlib._bootstrap>", line 241, in _call_with_frames_removed
  File "/home/pipohkr01/xcobs2/dmg_clc/app.py", line 312
    	    lv = int(request.form.get('lv', session.get('lv', 0)) or 0)
    ^
TabError: inconsistent use of tabs and spaces in indentation
[2025-08-02 09:42:31 +0000] [190797] [INFO] Worker exiting (pid: 190797)
[2025-08-02 09:42:31 +0000] [190798] [ERROR] Exception in worker process
Traceback (most recent call last):
  File "/home/pipohkr01/xcobs2/venv/lib/python3.11/site-packages/gunicorn/arbiter.py", line 608, in spawn_worker
    worker.init_process()
  File "/home/pipohkr01/xcobs2/venv/lib/python3.11/site-packages/gunicorn/workers/base.py", line 135, in init_process
    self.load_wsgi()
  File "/home/pipohkr01/xcobs2/venv/lib/python3.11/site-packages/gunicorn/workers/base.py", line 147, in load_wsgi
    self.wsgi = self.app.wsgi()
                ^^^^^^^^^^^^^^^
  File "/home/pipohkr01/xcobs2/venv/lib/python3.11/site-packages/gunicorn/app/base.py", line 66, in wsgi
    self.callable = self.load()
                    ^^^^^^^^^^^
  File "/home/pipohkr01/xcobs2/venv/lib/python3.11/site-packages/gunicorn/app/wsgiapp.py", line 57, in load
    return self.load_wsgiapp()
           ^^^^^^^^^^^^^^^^^^^
  File "/home/pipohkr01/xcobs2/venv/lib/python3.11/site-packages/gunicorn/app/wsgiapp.py", line 47, in load_wsgiapp
    return util.import_app(self.app_uri)
           ^^^^^^^^^^^^^^^^^^^^^^^^^^^^^
  File "/home/pipohkr01/xcobs2/venv/lib/python3.11/site-packages/gunicorn/util.py", line 370, in import_app
    mod = importlib.import_module(module)
          ^^^^^^^^^^^^^^^^^^^^^^^^^^^^^^^
  File "/usr/lib/python3.11/importlib/__init__.py", line 126, in import_module
    return _bootstrap._gcd_import(name[level:], package, level)
           ^^^^^^^^^^^^^^^^^^^^^^^^^^^^^^^^^^^^^^^^^^^^^^^^^^^^
  File "<frozen importlib._bootstrap>", line 1206, in _gcd_import
  File "<frozen importlib._bootstrap>", line 1178, in _find_and_load
  File "<frozen importlib._bootstrap>", line 1149, in _find_and_load_unlocked
  File "<frozen importlib._bootstrap>", line 690, in _load_unlocked
  File "<frozen importlib._bootstrap_external>", line 936, in exec_module
  File "<frozen importlib._bootstrap_external>", line 1074, in get_code
  File "<frozen importlib._bootstrap_external>", line 1004, in source_to_code
  File "<frozen importlib._bootstrap>", line 241, in _call_with_frames_removed
  File "/home/pipohkr01/xcobs2/dmg_clc/app.py", line 312
    	    lv = int(request.form.get('lv', session.get('lv', 0)) or 0)
    ^
TabError: inconsistent use of tabs and spaces in indentation
[2025-08-02 09:42:31 +0000] [190798] [INFO] Worker exiting (pid: 190798)
[2025-08-02 09:42:31 +0000] [190799] [INFO] Booting worker with pid: 190799
[2025-08-02 09:42:31 +0000] [190799] [ERROR] Exception in worker process
Traceback (most recent call last):
  File "/home/pipohkr01/xcobs2/venv/lib/python3.11/site-packages/gunicorn/arbiter.py", line 608, in spawn_worker
    worker.init_process()
  File "/home/pipohkr01/xcobs2/venv/lib/python3.11/site-packages/gunicorn/workers/base.py", line 135, in init_process
    self.load_wsgi()
  File "/home/pipohkr01/xcobs2/venv/lib/python3.11/site-packages/gunicorn/workers/base.py", line 147, in load_wsgi
    self.wsgi = self.app.wsgi()
                ^^^^^^^^^^^^^^^
  File "/home/pipohkr01/xcobs2/venv/lib/python3.11/site-packages/gunicorn/app/base.py", line 66, in wsgi
    self.callable = self.load()
                    ^^^^^^^^^^^
  File "/home/pipohkr01/xcobs2/venv/lib/python3.11/site-packages/gunicorn/app/wsgiapp.py", line 57, in load
    return self.load_wsgiapp()
           ^^^^^^^^^^^^^^^^^^^
  File "/home/pipohkr01/xcobs2/venv/lib/python3.11/site-packages/gunicorn/app/wsgiapp.py", line 47, in load_wsgiapp
    return util.import_app(self.app_uri)
           ^^^^^^^^^^^^^^^^^^^^^^^^^^^^^
  File "/home/pipohkr01/xcobs2/venv/lib/python3.11/site-packages/gunicorn/util.py", line 370, in import_app
    mod = importlib.import_module(module)
          ^^^^^^^^^^^^^^^^^^^^^^^^^^^^^^^
  File "/usr/lib/python3.11/importlib/__init__.py", line 126, in import_module
    return _bootstrap._gcd_import(name[level:], package, level)
           ^^^^^^^^^^^^^^^^^^^^^^^^^^^^^^^^^^^^^^^^^^^^^^^^^^^^
  File "<frozen importlib._bootstrap>", line 1206, in _gcd_import
  File "<frozen importlib._bootstrap>", line 1178, in _find_and_load
  File "<frozen importlib._bootstrap>", line 1149, in _find_and_load_unlocked
  File "<frozen importlib._bootstrap>", line 690, in _load_unlocked
  File "<frozen importlib._bootstrap_external>", line 936, in exec_module
  File "<frozen importlib._bootstrap_external>", line 1074, in get_code
  File "<frozen importlib._bootstrap_external>", line 1004, in source_to_code
  File "<frozen importlib._bootstrap>", line 241, in _call_with_frames_removed
  File "/home/pipohkr01/xcobs2/dmg_clc/app.py", line 312
    	    lv = int(request.form.get('lv', session.get('lv', 0)) or 0)
    ^
TabError: inconsistent use of tabs and spaces in indentation
[2025-08-02 09:42:31 +0000] [190799] [INFO] Worker exiting (pid: 190799)
[2025-08-02 09:42:31 +0000] [190796] [ERROR] Worker (pid:190798) exited with code 3
[2025-08-02 09:42:31 +0000] [190796] [ERROR] Worker (pid:190797) was sent SIGTERM!
[2025-08-02 09:42:31 +0000] [190796] [ERROR] Worker (pid:190799) was sent SIGTERM!
[2025-08-02 09:42:31 +0000] [190796] [ERROR] Shutting down: Master
[2025-08-02 09:42:31 +0000] [190796] [ERROR] Reason: Worker failed to boot.
[2025-08-02 09:44:13 +0000] [190806] [INFO] Starting gunicorn 23.0.0
[2025-08-02 09:44:13 +0000] [190806] [INFO] Listening at: http://127.0.0.1:8000 (190806)
[2025-08-02 09:44:13 +0000] [190806] [INFO] Using worker: sync
[2025-08-02 09:44:13 +0000] [190807] [INFO] Booting worker with pid: 190807
[2025-08-02 09:44:13 +0000] [190807] [ERROR] Exception in worker process
Traceback (most recent call last):
  File "/home/pipohkr01/xcobs2/venv/lib/python3.11/site-packages/gunicorn/arbiter.py", line 608, in spawn_worker
    worker.init_process()
  File "/home/pipohkr01/xcobs2/venv/lib/python3.11/site-packages/gunicorn/workers/base.py", line 135, in init_process
    self.load_wsgi()
  File "/home/pipohkr01/xcobs2/venv/lib/python3.11/site-packages/gunicorn/workers/base.py", line 147, in load_wsgi
    self.wsgi = self.app.wsgi()
                ^^^^^^^^^^^^^^^
  File "/home/pipohkr01/xcobs2/venv/lib/python3.11/site-packages/gunicorn/app/base.py", line 66, in wsgi
    self.callable = self.load()
                    ^^^^^^^^^^^
  File "/home/pipohkr01/xcobs2/venv/lib/python3.11/site-packages/gunicorn/app/wsgiapp.py", line 57, in load
    return self.load_wsgiapp()
           ^^^^^^^^^^^^^^^^^^^
  File "/home/pipohkr01/xcobs2/venv/lib/python3.11/site-packages/gunicorn/app/wsgiapp.py", line 47, in load_wsgiapp
    return util.import_app(self.app_uri)
           ^^^^^^^^^^^^^^^^^^^^^^^^^^^^^
  File "/home/pipohkr01/xcobs2/venv/lib/python3.11/site-packages/gunicorn/util.py", line 370, in import_app
    mod = importlib.import_module(module)
          ^^^^^^^^^^^^^^^^^^^^^^^^^^^^^^^
  File "/usr/lib/python3.11/importlib/__init__.py", line 126, in import_module
    return _bootstrap._gcd_import(name[level:], package, level)
           ^^^^^^^^^^^^^^^^^^^^^^^^^^^^^^^^^^^^^^^^^^^^^^^^^^^^
  File "<frozen importlib._bootstrap>", line 1206, in _gcd_import
  File "<frozen importlib._bootstrap>", line 1178, in _find_and_load
  File "<frozen importlib._bootstrap>", line 1149, in _find_and_load_unlocked
  File "<frozen importlib._bootstrap>", line 690, in _load_unlocked
  File "<frozen importlib._bootstrap_external>", line 936, in exec_module
  File "<frozen importlib._bootstrap_external>", line 1074, in get_code
  File "<frozen importlib._bootstrap_external>", line 1004, in source_to_code
  File "<frozen importlib._bootstrap>", line 241, in _call_with_frames_removed
  File "/home/pipohkr01/xcobs2/dmg_clc/app.py", line 312
    	    lv = int(request.form.get('lv', session.get('lv', 0)) or 0)
    ^
TabError: inconsistent use of tabs and spaces in indentation
[2025-08-02 09:44:13 +0000] [190807] [INFO] Worker exiting (pid: 190807)
[2025-08-02 09:44:14 +0000] [190806] [ERROR] Worker (pid:190807) exited with code 3
[2025-08-02 09:44:14 +0000] [190806] [ERROR] Shutting down: Master
[2025-08-02 09:44:14 +0000] [190806] [ERROR] Reason: Worker failed to boot.
[2025-08-02 09:46:57 +0000] [190829] [INFO] Starting gunicorn 23.0.0
[2025-08-02 09:46:57 +0000] [190829] [INFO] Listening at: http://127.0.0.1:8000 (190829)
[2025-08-02 09:46:57 +0000] [190829] [INFO] Using worker: sync
[2025-08-02 09:46:57 +0000] [190830] [INFO] Booting worker with pid: 190830
[2025-08-02 09:46:57 +0000] [190830] [ERROR] Exception in worker process
Traceback (most recent call last):
  File "/home/pipohkr01/xcobs2/venv/lib/python3.11/site-packages/gunicorn/arbiter.py", line 608, in spawn_worker
    worker.init_process()
  File "/home/pipohkr01/xcobs2/venv/lib/python3.11/site-packages/gunicorn/workers/base.py", line 135, in init_process
    self.load_wsgi()
  File "/home/pipohkr01/xcobs2/venv/lib/python3.11/site-packages/gunicorn/workers/base.py", line 147, in load_wsgi
    self.wsgi = self.app.wsgi()
                ^^^^^^^^^^^^^^^
  File "/home/pipohkr01/xcobs2/venv/lib/python3.11/site-packages/gunicorn/app/base.py", line 66, in wsgi
    self.callable = self.load()
                    ^^^^^^^^^^^
  File "/home/pipohkr01/xcobs2/venv/lib/python3.11/site-packages/gunicorn/app/wsgiapp.py", line 57, in load
    return self.load_wsgiapp()
           ^^^^^^^^^^^^^^^^^^^
  File "/home/pipohkr01/xcobs2/venv/lib/python3.11/site-packages/gunicorn/app/wsgiapp.py", line 47, in load_wsgiapp
    return util.import_app(self.app_uri)
           ^^^^^^^^^^^^^^^^^^^^^^^^^^^^^
  File "/home/pipohkr01/xcobs2/venv/lib/python3.11/site-packages/gunicorn/util.py", line 370, in import_app
    mod = importlib.import_module(module)
          ^^^^^^^^^^^^^^^^^^^^^^^^^^^^^^^
  File "/usr/lib/python3.11/importlib/__init__.py", line 126, in import_module
    return _bootstrap._gcd_import(name[level:], package, level)
           ^^^^^^^^^^^^^^^^^^^^^^^^^^^^^^^^^^^^^^^^^^^^^^^^^^^^
  File "<frozen importlib._bootstrap>", line 1206, in _gcd_import
  File "<frozen importlib._bootstrap>", line 1178, in _find_and_load
  File "<frozen importlib._bootstrap>", line 1149, in _find_and_load_unlocked
  File "<frozen importlib._bootstrap>", line 690, in _load_unlocked
  File "<frozen importlib._bootstrap_external>", line 936, in exec_module
  File "<frozen importlib._bootstrap_external>", line 1074, in get_code
  File "<frozen importlib._bootstrap_external>", line 1004, in source_to_code
  File "<frozen importlib._bootstrap>", line 241, in _call_with_frames_removed
  File "/home/pipohkr01/xcobs2/dmg_clc/app.py", line 312
    	    lv = int(request.form.get('lv', session.get('lv', 0)) or 0)
    ^
TabError: inconsistent use of tabs and spaces in indentation
[2025-08-02 09:46:57 +0000] [190830] [INFO] Worker exiting (pid: 190830)
[2025-08-02 09:46:57 +0000] [190829] [ERROR] Worker (pid:190830) exited with code 3
[2025-08-02 09:46:57 +0000] [190829] [ERROR] Shutting down: Master
[2025-08-02 09:46:57 +0000] [190829] [ERROR] Reason: Worker failed to boot.
[2025-08-02 09:51:58 +0000] [191559] [INFO] Starting gunicorn 23.0.0
[2025-08-02 09:51:58 +0000] [191559] [INFO] Listening at: http://127.0.0.1:8000 (191559)
[2025-08-02 09:51:58 +0000] [191559] [INFO] Using worker: sync
[2025-08-02 09:51:58 +0000] [191560] [INFO] Booting worker with pid: 191560
[2025-08-02 09:51:58 +0000] [191560] [ERROR] Exception in worker process
Traceback (most recent call last):
  File "/home/pipohkr01/xcobs2/venv/lib/python3.11/site-packages/gunicorn/arbiter.py", line 608, in spawn_worker
    worker.init_process()
  File "/home/pipohkr01/xcobs2/venv/lib/python3.11/site-packages/gunicorn/workers/base.py", line 135, in init_process
    self.load_wsgi()
  File "/home/pipohkr01/xcobs2/venv/lib/python3.11/site-packages/gunicorn/workers/base.py", line 147, in load_wsgi
    self.wsgi = self.app.wsgi()
                ^^^^^^^^^^^^^^^
  File "/home/pipohkr01/xcobs2/venv/lib/python3.11/site-packages/gunicorn/app/base.py", line 66, in wsgi
    self.callable = self.load()
                    ^^^^^^^^^^^
  File "/home/pipohkr01/xcobs2/venv/lib/python3.11/site-packages/gunicorn/app/wsgiapp.py", line 57, in load
    return self.load_wsgiapp()
           ^^^^^^^^^^^^^^^^^^^
  File "/home/pipohkr01/xcobs2/venv/lib/python3.11/site-packages/gunicorn/app/wsgiapp.py", line 47, in load_wsgiapp
    return util.import_app(self.app_uri)
           ^^^^^^^^^^^^^^^^^^^^^^^^^^^^^
  File "/home/pipohkr01/xcobs2/venv/lib/python3.11/site-packages/gunicorn/util.py", line 370, in import_app
    mod = importlib.import_module(module)
          ^^^^^^^^^^^^^^^^^^^^^^^^^^^^^^^
  File "/usr/lib/python3.11/importlib/__init__.py", line 126, in import_module
    return _bootstrap._gcd_import(name[level:], package, level)
           ^^^^^^^^^^^^^^^^^^^^^^^^^^^^^^^^^^^^^^^^^^^^^^^^^^^^
  File "<frozen importlib._bootstrap>", line 1206, in _gcd_import
  File "<frozen importlib._bootstrap>", line 1178, in _find_and_load
  File "<frozen importlib._bootstrap>", line 1149, in _find_and_load_unlocked
  File "<frozen importlib._bootstrap>", line 690, in _load_unlocked
  File "<frozen importlib._bootstrap_external>", line 936, in exec_module
  File "<frozen importlib._bootstrap_external>", line 1074, in get_code
  File "<frozen importlib._bootstrap_external>", line 1004, in source_to_code
  File "<frozen importlib._bootstrap>", line 241, in _call_with_frames_removed
  File "/home/pipohkr01/xcobs2/dmg_clc/app.py", line 312
    	    lv = int(request.form.get('lv', session.get('lv', 0)) or 0)
    ^
TabError: inconsistent use of tabs and spaces in indentation
[2025-08-02 09:51:58 +0000] [191560] [INFO] Worker exiting (pid: 191560)
[2025-08-02 09:51:59 +0000] [191562] [INFO] Booting worker with pid: 191562
[2025-08-02 09:51:59 +0000] [191562] [ERROR] Exception in worker process
Traceback (most recent call last):
  File "/home/pipohkr01/xcobs2/venv/lib/python3.11/site-packages/gunicorn/arbiter.py", line 608, in spawn_worker
    worker.init_process()
  File "/home/pipohkr01/xcobs2/venv/lib/python3.11/site-packages/gunicorn/workers/base.py", line 135, in init_process
    self.load_wsgi()
  File "/home/pipohkr01/xcobs2/venv/lib/python3.11/site-packages/gunicorn/workers/base.py", line 147, in load_wsgi
    self.wsgi = self.app.wsgi()
                ^^^^^^^^^^^^^^^
  File "/home/pipohkr01/xcobs2/venv/lib/python3.11/site-packages/gunicorn/app/base.py", line 66, in wsgi
    self.callable = self.load()
                    ^^^^^^^^^^^
  File "/home/pipohkr01/xcobs2/venv/lib/python3.11/site-packages/gunicorn/app/wsgiapp.py", line 57, in load
    return self.load_wsgiapp()
           ^^^^^^^^^^^^^^^^^^^
  File "/home/pipohkr01/xcobs2/venv/lib/python3.11/site-packages/gunicorn/app/wsgiapp.py", line 47, in load_wsgiapp
    return util.import_app(self.app_uri)
           ^^^^^^^^^^^^^^^^^^^^^^^^^^^^^
  File "/home/pipohkr01/xcobs2/venv/lib/python3.11/site-packages/gunicorn/util.py", line 370, in import_app
    mod = importlib.import_module(module)
          ^^^^^^^^^^^^^^^^^^^^^^^^^^^^^^^
  File "/usr/lib/python3.11/importlib/__init__.py", line 126, in import_module
    return _bootstrap._gcd_import(name[level:], package, level)
           ^^^^^^^^^^^^^^^^^^^^^^^^^^^^^^^^^^^^^^^^^^^^^^^^^^^^
  File "<frozen importlib._bootstrap>", line 1206, in _gcd_import
  File "<frozen importlib._bootstrap>", line 1178, in _find_and_load
  File "<frozen importlib._bootstrap>", line 1149, in _find_and_load_unlocked
  File "<frozen importlib._bootstrap>", line 690, in _load_unlocked
  File "<frozen importlib._bootstrap_external>", line 936, in exec_module
  File "<frozen importlib._bootstrap_external>", line 1074, in get_code
  File "<frozen importlib._bootstrap_external>", line 1004, in source_to_code
  File "<frozen importlib._bootstrap>", line 241, in _call_with_frames_removed
  File "/home/pipohkr01/xcobs2/dmg_clc/app.py", line 312
    	    lv = int(request.form.get('lv', session.get('lv', 0)) or 0)
    ^
TabError: inconsistent use of tabs and spaces in indentation
[2025-08-02 09:51:59 +0000] [191562] [INFO] Worker exiting (pid: 191562)
[2025-08-02 09:51:59 +0000] [191559] [ERROR] Worker (pid:191560) exited with code 3
[2025-08-02 09:51:59 +0000] [191559] [ERROR] Worker (pid:191562) was sent SIGTERM!
[2025-08-02 09:51:59 +0000] [191561] [INFO] Booting worker with pid: 191561
[2025-08-02 09:51:59 +0000] [191563] [INFO] Booting worker with pid: 191563
[2025-08-02 09:51:59 +0000] [191561] [ERROR] Exception in worker process
Traceback (most recent call last):
  File "/home/pipohkr01/xcobs2/venv/lib/python3.11/site-packages/gunicorn/arbiter.py", line 608, in spawn_worker
    worker.init_process()
  File "/home/pipohkr01/xcobs2/venv/lib/python3.11/site-packages/gunicorn/workers/base.py", line 135, in init_process
    self.load_wsgi()
  File "/home/pipohkr01/xcobs2/venv/lib/python3.11/site-packages/gunicorn/workers/base.py", line 147, in load_wsgi
    self.wsgi = self.app.wsgi()
                ^^^^^^^^^^^^^^^
  File "/home/pipohkr01/xcobs2/venv/lib/python3.11/site-packages/gunicorn/app/base.py", line 66, in wsgi
    self.callable = self.load()
                    ^^^^^^^^^^^
  File "/home/pipohkr01/xcobs2/venv/lib/python3.11/site-packages/gunicorn/app/wsgiapp.py", line 57, in load
    return self.load_wsgiapp()
           ^^^^^^^^^^^^^^^^^^^
  File "/home/pipohkr01/xcobs2/venv/lib/python3.11/site-packages/gunicorn/app/wsgiapp.py", line 47, in load_wsgiapp
    return util.import_app(self.app_uri)
           ^^^^^^^^^^^^^^^^^^^^^^^^^^^^^
  File "/home/pipohkr01/xcobs2/venv/lib/python3.11/site-packages/gunicorn/util.py", line 370, in import_app
    mod = importlib.import_module(module)
          ^^^^^^^^^^^^^^^^^^^^^^^^^^^^^^^
  File "/usr/lib/python3.11/importlib/__init__.py", line 126, in import_module
    return _bootstrap._gcd_import(name[level:], package, level)
           ^^^^^^^^^^^^^^^^^^^^^^^^^^^^^^^^^^^^^^^^^^^^^^^^^^^^
  File "<frozen importlib._bootstrap>", line 1206, in _gcd_import
  File "<frozen importlib._bootstrap>", line 1178, in _find_and_load
  File "<frozen importlib._bootstrap>", line 1149, in _find_and_load_unlocked
  File "<frozen importlib._bootstrap>", line 690, in _load_unlocked
  File "<frozen importlib._bootstrap_external>", line 936, in exec_module
  File "<frozen importlib._bootstrap_external>", line 1074, in get_code
  File "<frozen importlib._bootstrap_external>", line 1004, in source_to_code
  File "<frozen importlib._bootstrap>", line 241, in _call_with_frames_removed
  File "/home/pipohkr01/xcobs2/dmg_clc/app.py", line 312
    	    lv = int(request.form.get('lv', session.get('lv', 0)) or 0)
    ^
TabError: inconsistent use of tabs and spaces in indentation
[2025-08-02 09:51:59 +0000] [191561] [INFO] Worker exiting (pid: 191561)
[2025-08-02 09:51:59 +0000] [191563] [ERROR] Exception in worker process
Traceback (most recent call last):
  File "/home/pipohkr01/xcobs2/venv/lib/python3.11/site-packages/gunicorn/arbiter.py", line 608, in spawn_worker
    worker.init_process()
  File "/home/pipohkr01/xcobs2/venv/lib/python3.11/site-packages/gunicorn/workers/base.py", line 135, in init_process
    self.load_wsgi()
  File "/home/pipohkr01/xcobs2/venv/lib/python3.11/site-packages/gunicorn/workers/base.py", line 147, in load_wsgi
    self.wsgi = self.app.wsgi()
                ^^^^^^^^^^^^^^^
  File "/home/pipohkr01/xcobs2/venv/lib/python3.11/site-packages/gunicorn/app/base.py", line 66, in wsgi
    self.callable = self.load()
                    ^^^^^^^^^^^
  File "/home/pipohkr01/xcobs2/venv/lib/python3.11/site-packages/gunicorn/app/wsgiapp.py", line 57, in load
    return self.load_wsgiapp()
           ^^^^^^^^^^^^^^^^^^^
  File "/home/pipohkr01/xcobs2/venv/lib/python3.11/site-packages/gunicorn/app/wsgiapp.py", line 47, in load_wsgiapp
    return util.import_app(self.app_uri)
           ^^^^^^^^^^^^^^^^^^^^^^^^^^^^^
  File "/home/pipohkr01/xcobs2/venv/lib/python3.11/site-packages/gunicorn/util.py", line 370, in import_app
    mod = importlib.import_module(module)
          ^^^^^^^^^^^^^^^^^^^^^^^^^^^^^^^
  File "/usr/lib/python3.11/importlib/__init__.py", line 126, in import_module
    return _bootstrap._gcd_import(name[level:], package, level)
           ^^^^^^^^^^^^^^^^^^^^^^^^^^^^^^^^^^^^^^^^^^^^^^^^^^^^
  File "<frozen importlib._bootstrap>", line 1206, in _gcd_import
  File "<frozen importlib._bootstrap>", line 1178, in _find_and_load
  File "<frozen importlib._bootstrap>", line 1149, in _find_and_load_unlocked
  File "<frozen importlib._bootstrap>", line 690, in _load_unlocked
  File "<frozen importlib._bootstrap_external>", line 936, in exec_module
  File "<frozen importlib._bootstrap_external>", line 1074, in get_code
  File "<frozen importlib._bootstrap_external>", line 1004, in source_to_code
  File "<frozen importlib._bootstrap>", line 241, in _call_with_frames_removed
  File "/home/pipohkr01/xcobs2/dmg_clc/app.py", line 312
    	    lv = int(request.form.get('lv', session.get('lv', 0)) or 0)
    ^
TabError: inconsistent use of tabs and spaces in indentation
[2025-08-02 09:51:59 +0000] [191563] [INFO] Worker exiting (pid: 191563)
[2025-08-02 09:51:59 +0000] [191559] [ERROR] Worker (pid:191561) exited with code 3
Traceback (most recent call last):
  File "/home/pipohkr01/xcobs2/venv/lib/python3.11/site-packages/gunicorn/arbiter.py", line 201, in run
    self.manage_workers()
  File "/home/pipohkr01/xcobs2/venv/lib/python3.11/site-packages/gunicorn/arbiter.py", line 570, in manage_workers
    self.spawn_workers()
  File "/home/pipohkr01/xcobs2/venv/lib/python3.11/site-packages/gunicorn/arbiter.py", line 642, in spawn_workers
    time.sleep(0.1 * random.random())
  File "/home/pipohkr01/xcobs2/venv/lib/python3.11/site-packages/gunicorn/arbiter.py", line 241, in handle_chld
    self.reap_workers()
  File "/home/pipohkr01/xcobs2/venv/lib/python3.11/site-packages/gunicorn/arbiter.py", line 529, in reap_workers
    raise HaltServer(reason, self.WORKER_BOOT_ERROR)
gunicorn.errors.HaltServer: <HaltServer 'Worker failed to boot.' 3>

During handling of the above exception, another exception occurred:

Traceback (most recent call last):
  File "/home/pipohkr01/xcobs2/venv/bin/gunicorn", line 8, in <module>
    sys.exit(run())
             ^^^^^
  File "/home/pipohkr01/xcobs2/venv/lib/python3.11/site-packages/gunicorn/app/wsgiapp.py", line 66, in run
    WSGIApplication("%(prog)s [OPTIONS] [APP_MODULE]", prog=prog).run()
  File "/home/pipohkr01/xcobs2/venv/lib/python3.11/site-packages/gunicorn/app/base.py", line 235, in run
    super().run()
  File "/home/pipohkr01/xcobs2/venv/lib/python3.11/site-packages/gunicorn/app/base.py", line 71, in run
    Arbiter(self).run()
  File "/home/pipohkr01/xcobs2/venv/lib/python3.11/site-packages/gunicorn/arbiter.py", line 228, in run
    self.halt(reason=inst.reason, exit_status=inst.exit_status)
  File "/home/pipohkr01/xcobs2/venv/lib/python3.11/site-packages/gunicorn/arbiter.py", line 341, in halt
    self.stop()
  File "/home/pipohkr01/xcobs2/venv/lib/python3.11/site-packages/gunicorn/arbiter.py", line 395, in stop
    time.sleep(0.1)
  File "/home/pipohkr01/xcobs2/venv/lib/python3.11/site-packages/gunicorn/arbiter.py", line 241, in handle_chld
    self.reap_workers()
  File "/home/pipohkr01/xcobs2/venv/lib/python3.11/site-packages/gunicorn/arbiter.py", line 529, in reap_workers
    raise HaltServer(reason, self.WORKER_BOOT_ERROR)
gunicorn.errors.HaltServer: <HaltServer 'Worker failed to boot.' 3>
[2025-08-02 10:00:15 +0000] [191650] [INFO] Starting gunicorn 23.0.0
[2025-08-02 10:00:15 +0000] [191650] [INFO] Listening at: http://127.0.0.1:8000 (191650)
[2025-08-02 10:00:15 +0000] [191650] [INFO] Using worker: sync
[2025-08-02 10:00:15 +0000] [191680] [INFO] Booting worker with pid: 191680
[2025-08-02 10:00:15 +0000] [191749] [INFO] Booting worker with pid: 191749
[2025-08-02 10:00:15 +0000] [191753] [INFO] Booting worker with pid: 191753
[2025-08-02 10:00:15 +0000] [191762] [INFO] Booting worker with pid: 191762
[2025-08-02 10:40:42 +0000] [191650] [INFO] Handling signal: term
[2025-08-02 10:40:42 +0000] [191680] [INFO] Worker exiting (pid: 191680)
[2025-08-02 10:40:42 +0000] [191749] [INFO] Worker exiting (pid: 191749)
100 31 252 70 さみしがり
155 125 31 252 70 さみしがり
みず みず None あく じめん
False False
ノーマル ノーマル
1.1 1.0 0.9 1.0
362 231.00000000000003 280.0 220.5 182.0
30
130
フィールド補正:1.0
130
攻撃補正
防御補正
天候補正:1
タイプ一致
タイプ一致1.5
タイプ相性補正: 2.0
基本ダメージ
30 130 280.0 182.0
ん？
366
ダメ計終了
362 231.00000000000003 280.0 220.5 182.0
155
100 31 252 100 さみしがり
155 125 31 252 100 さみしがり
みず みず None あく じめん
True False
みず ノーマル
1.1 1.0 0.9 1.0
514 328.90000000000003 399.0 314.1 259.0
42
130
フィールド補正:1.0
130
攻撃補正
防御補正
天候補正:1.5
攻撃側テラス
両方一致タイプ一致
タイプ一致2.0
タイプ相性補正: 2.0
基本ダメージ
42 130 399.0 259.0
ん？
1020
ダメ計終了
防御側ダイマックス適用: レベル=10, 倍率=2.0
1028 328.90000000000003 399.0 314.1 259.0
310
514 328.90000000000003 399.0 314.1 259.0
155
防御側ダイマ
[2025-08-02 10:40:42 +0000] [191753] [INFO] Worker exiting (pid: 191753)
100 31 252 0 さみしがり
155 125 31 252 0 さみしがり
ノーマル みず None あく じめん
False False
ノーマル ノーマル
1.1 1.0 0.9 1.0
10 5.5 5.0 4.5 5.0
2
1
フィールド補正:1.0
1
攻撃補正
防御補正
天候補正:1
タイプ一致1.0
タイプ相性補正: 1.0
基本ダメージ
2 1 5 4
あれ
2
ダメ計終了
10 5.5 5.0 4.5 5.0
155
[2025-08-02 10:40:42 +0000] [191762] [INFO] Worker exiting (pid: 191762)
100 31 252 50 さみしがり
155 125 31 252 50 さみしがり
みず みず None あく じめん
False False
ノーマル ノーマル
1.1 1.0 0.9 1.0
262 167.20000000000002 202.0 159.3 132.0
22
130
フィールド補正:1.0
130
攻撃補正
防御補正
天候補正:1
タイプ一致
タイプ一致1.5
タイプ相性補正: 2.0
基本ダメージ
22 130 202.0 132.0
ん？
266
ダメ計終了
262 167.20000000000002 202.0 159.3 132.0
155
[2025-08-02 10:40:43 +0000] [191650] [INFO] Shutting down: Master
[2025-08-02 10:41:18 +0000] [194984] [INFO] Starting gunicorn 23.0.0
[2025-08-02 10:41:18 +0000] [194984] [INFO] Listening at: http://127.0.0.1:8000 (194984)
[2025-08-02 10:41:18 +0000] [194984] [INFO] Using worker: sync
[2025-08-02 10:41:18 +0000] [194985] [INFO] Booting worker with pid: 194985
[2025-08-02 10:41:18 +0000] [194986] [INFO] Booting worker with pid: 194986
[2025-08-02 10:41:18 +0000] [194987] [INFO] Booting worker with pid: 194987
[2025-08-02 10:41:18 +0000] [194988] [INFO] Booting worker with pid: 194988
[2025-08-02 10:57:37 +0000] [194984] [INFO] Handling signal: term
[2025-08-02 10:57:37 +0000] [194986] [INFO] Worker exiting (pid: 194986)
[2025-08-02 10:57:37 +0000] [194988] [INFO] Worker exiting (pid: 194988)
[2025-08-02 10:57:37 +0000] [194985] [INFO] Worker exiting (pid: 194985)
[2025-08-02 10:57:37 +0000] [194987] [INFO] Worker exiting (pid: 194987)
100 31 252 100 ようき
155 125 31 252 100 さみしがり
みず みず None あく じめん
True False
みず ノーマル
1.0 0.9 0.9 1.0
514 299.0 359.1 314.1 259.0
42
150
フィールド補正:1.0
150
攻撃補正
防御補正
天候補正:1.5
攻撃側テラス
両方一致タイプ一致
タイプ一致2.0
タイプ相性補正: 2.0
いのちのたまありけり
基本ダメージ
42 150 359.1 259.0
ん？
1373
ダメ計終了
514 299.0 359.1 314.1 259.0
155
100 31 252 50 ようき
155 125 31 252 50 さみしがり
みず みず None あく じめん
False False
ノーマル ノーマル
1.0 0.9 0.9 1.0
262 152.0 181.8 159.3 132.0
22
130
フィールド補正:1.0
130
攻撃補正
防御補正
天候補正:1
タイプ一致
タイプ一致1.5
タイプ相性補正: 2.0
基本ダメージ
22 130 181.8 132.0
ん？
240
ダメ計終了
262 152.0 181.8 159.3 132.0
155
[2025-08-02 10:57:38 +0000] [194984] [INFO] Shutting down: Master
[2025-08-02 10:57:49 +0000] [195692] [INFO] Starting gunicorn 23.0.0
[2025-08-02 10:57:49 +0000] [195692] [INFO] Listening at: http://127.0.0.1:8000 (195692)
[2025-08-02 10:57:49 +0000] [195692] [INFO] Using worker: sync
[2025-08-02 10:57:49 +0000] [195693] [INFO] Booting worker with pid: 195693
[2025-08-02 10:57:49 +0000] [195693] [ERROR] Exception in worker process
Traceback (most recent call last):
  File "/home/pipohkr01/xcobs2/venv/lib/python3.11/site-packages/gunicorn/arbiter.py", line 608, in spawn_worker
    worker.init_process()
  File "/home/pipohkr01/xcobs2/venv/lib/python3.11/site-packages/gunicorn/workers/base.py", line 135, in init_process
    self.load_wsgi()
  File "/home/pipohkr01/xcobs2/venv/lib/python3.11/site-packages/gunicorn/workers/base.py", line 147, in load_wsgi
    self.wsgi = self.app.wsgi()
                ^^^^^^^^^^^^^^^
  File "/home/pipohkr01/xcobs2/venv/lib/python3.11/site-packages/gunicorn/app/base.py", line 66, in wsgi
    self.callable = self.load()
                    ^^^^^^^^^^^
  File "/home/pipohkr01/xcobs2/venv/lib/python3.11/site-packages/gunicorn/app/wsgiapp.py", line 57, in load
    return self.load_wsgiapp()
           ^^^^^^^^^^^^^^^^^^^
  File "/home/pipohkr01/xcobs2/venv/lib/python3.11/site-packages/gunicorn/app/wsgiapp.py", line 47, in load_wsgiapp
    return util.import_app(self.app_uri)
           ^^^^^^^^^^^^^^^^^^^^^^^^^^^^^
  File "/home/pipohkr01/xcobs2/venv/lib/python3.11/site-packages/gunicorn/util.py", line 370, in import_app
    mod = importlib.import_module(module)
          ^^^^^^^^^^^^^^^^^^^^^^^^^^^^^^^
  File "/usr/lib/python3.11/importlib/__init__.py", line 126, in import_module
    return _bootstrap._gcd_import(name[level:], package, level)
           ^^^^^^^^^^^^^^^^^^^^^^^^^^^^^^^^^^^^^^^^^^^^^^^^^^^^
  File "<frozen importlib._bootstrap>", line 1206, in _gcd_import
  File "<frozen importlib._bootstrap>", line 1178, in _find_and_load
  File "<frozen importlib._bootstrap>", line 1149, in _find_and_load_unlocked
  File "<frozen importlib._bootstrap>", line 690, in _load_unlocked
  File "<frozen importlib._bootstrap_external>", line 936, in exec_module
  File "<frozen importlib._bootstrap_external>", line 1074, in get_code
  File "<frozen importlib._bootstrap_external>", line 1004, in source_to_code
  File "<frozen importlib._bootstrap>", line 241, in _call_with_frames_removed
  File "/home/pipohkr01/xcobs2/dmg_clc/app.py", line 731
    lv_bl = session.get('lv_bl', 0)
            ^^^^^^
SyntaxError: invalid syntax. Perhaps you forgot a comma?
[2025-08-02 10:57:49 +0000] [195693] [INFO] Worker exiting (pid: 195693)
[2025-08-02 10:57:49 +0000] [195694] [INFO] Booting worker with pid: 195694
[2025-08-02 10:57:49 +0000] [195694] [ERROR] Exception in worker process
Traceback (most recent call last):
  File "/home/pipohkr01/xcobs2/venv/lib/python3.11/site-packages/gunicorn/arbiter.py", line 608, in spawn_worker
    worker.init_process()
  File "/home/pipohkr01/xcobs2/venv/lib/python3.11/site-packages/gunicorn/workers/base.py", line 135, in init_process
    self.load_wsgi()
  File "/home/pipohkr01/xcobs2/venv/lib/python3.11/site-packages/gunicorn/workers/base.py", line 147, in load_wsgi
    self.wsgi = self.app.wsgi()
                ^^^^^^^^^^^^^^^
  File "/home/pipohkr01/xcobs2/venv/lib/python3.11/site-packages/gunicorn/app/base.py", line 66, in wsgi
    self.callable = self.load()
                    ^^^^^^^^^^^
  File "/home/pipohkr01/xcobs2/venv/lib/python3.11/site-packages/gunicorn/app/wsgiapp.py", line 57, in load
    return self.load_wsgiapp()
           ^^^^^^^^^^^^^^^^^^^
  File "/home/pipohkr01/xcobs2/venv/lib/python3.11/site-packages/gunicorn/app/wsgiapp.py", line 47, in load_wsgiapp
    return util.import_app(self.app_uri)
           ^^^^^^^^^^^^^^^^^^^^^^^^^^^^^
  File "/home/pipohkr01/xcobs2/venv/lib/python3.11/site-packages/gunicorn/util.py", line 370, in import_app
    mod = importlib.import_module(module)
          ^^^^^^^^^^^^^^^^^^^^^^^^^^^^^^^
  File "/usr/lib/python3.11/importlib/__init__.py", line 126, in import_module
    return _bootstrap._gcd_import(name[level:], package, level)
           ^^^^^^^^^^^^^^^^^^^^^^^^^^^^^^^^^^^^^^^^^^^^^^^^^^^^
  File "<frozen importlib._bootstrap>", line 1206, in _gcd_import
  File "<frozen importlib._bootstrap>", line 1178, in _find_and_load
  File "<frozen importlib._bootstrap>", line 1149, in _find_and_load_unlocked
  File "<frozen importlib._bootstrap>", line 690, in _load_unlocked
  File "<frozen importlib._bootstrap_external>", line 936, in exec_module
  File "<frozen importlib._bootstrap_external>", line 1074, in get_code
  File "<frozen importlib._bootstrap_external>", line 1004, in source_to_code
  File "<frozen importlib._bootstrap>", line 241, in _call_with_frames_removed
  File "/home/pipohkr01/xcobs2/dmg_clc/app.py", line 731
    lv_bl = session.get('lv_bl', 0)
            ^^^^^^
SyntaxError: invalid syntax. Perhaps you forgot a comma?
[2025-08-02 10:57:49 +0000] [195694] [INFO] Worker exiting (pid: 195694)
[2025-08-02 10:57:49 +0000] [195695] [INFO] Booting worker with pid: 195695
[2025-08-02 10:57:49 +0000] [195692] [ERROR] Worker (pid:195693) exited with code 3
[2025-08-02 10:57:49 +0000] [195692] [ERROR] Worker (pid:195694) was sent SIGTERM!
[2025-08-02 10:57:49 +0000] [195695] [ERROR] Exception in worker process
Traceback (most recent call last):
  File "/home/pipohkr01/xcobs2/venv/lib/python3.11/site-packages/gunicorn/arbiter.py", line 608, in spawn_worker
    worker.init_process()
  File "/home/pipohkr01/xcobs2/venv/lib/python3.11/site-packages/gunicorn/workers/base.py", line 135, in init_process
    self.load_wsgi()
  File "/home/pipohkr01/xcobs2/venv/lib/python3.11/site-packages/gunicorn/workers/base.py", line 147, in load_wsgi
    self.wsgi = self.app.wsgi()
                ^^^^^^^^^^^^^^^
  File "/home/pipohkr01/xcobs2/venv/lib/python3.11/site-packages/gunicorn/app/base.py", line 66, in wsgi
    self.callable = self.load()
                    ^^^^^^^^^^^
  File "/home/pipohkr01/xcobs2/venv/lib/python3.11/site-packages/gunicorn/app/wsgiapp.py", line 57, in load
    return self.load_wsgiapp()
           ^^^^^^^^^^^^^^^^^^^
  File "/home/pipohkr01/xcobs2/venv/lib/python3.11/site-packages/gunicorn/app/wsgiapp.py", line 47, in load_wsgiapp
    return util.import_app(self.app_uri)
           ^^^^^^^^^^^^^^^^^^^^^^^^^^^^^
  File "/home/pipohkr01/xcobs2/venv/lib/python3.11/site-packages/gunicorn/util.py", line 370, in import_app
    mod = importlib.import_module(module)
          ^^^^^^^^^^^^^^^^^^^^^^^^^^^^^^^
  File "/usr/lib/python3.11/importlib/__init__.py", line 126, in import_module
    return _bootstrap._gcd_import(name[level:], package, level)
           ^^^^^^^^^^^^^^^^^^^^^^^^^^^^^^^^^^^^^^^^^^^^^^^^^^^^
  File "<frozen importlib._bootstrap>", line 1206, in _gcd_import
  File "<frozen importlib._bootstrap>", line 1178, in _find_and_load
  File "<frozen importlib._bootstrap>", line 1149, in _find_and_load_unlocked
  File "<frozen importlib._bootstrap>", line 690, in _load_unlocked
  File "<frozen importlib._bootstrap_external>", line 936, in exec_module
  File "<frozen importlib._bootstrap_external>", line 1074, in get_code
  File "<frozen importlib._bootstrap_external>", line 1004, in source_to_code
  File "<frozen importlib._bootstrap>", line 241, in _call_with_frames_removed
  File "/home/pipohkr01/xcobs2/dmg_clc/app.py", line 731
    lv_bl = session.get('lv_bl', 0)
            ^^^^^^
SyntaxError: invalid syntax. Perhaps you forgot a comma?
[2025-08-02 10:57:49 +0000] [195695] [INFO] Worker exiting (pid: 195695)
[2025-08-02 10:57:49 +0000] [195692] [ERROR] Worker (pid:195695) exited with code 3
Traceback (most recent call last):
  File "/home/pipohkr01/xcobs2/venv/lib/python3.11/site-packages/gunicorn/arbiter.py", line 201, in run
    self.manage_workers()
  File "/home/pipohkr01/xcobs2/venv/lib/python3.11/site-packages/gunicorn/arbiter.py", line 570, in manage_workers
    self.spawn_workers()
  File "/home/pipohkr01/xcobs2/venv/lib/python3.11/site-packages/gunicorn/arbiter.py", line 642, in spawn_workers
    time.sleep(0.1 * random.random())
  File "/home/pipohkr01/xcobs2/venv/lib/python3.11/site-packages/gunicorn/arbiter.py", line 241, in handle_chld
    self.reap_workers()
  File "/home/pipohkr01/xcobs2/venv/lib/python3.11/site-packages/gunicorn/arbiter.py", line 529, in reap_workers
    raise HaltServer(reason, self.WORKER_BOOT_ERROR)
gunicorn.errors.HaltServer: <HaltServer 'Worker failed to boot.' 3>

During handling of the above exception, another exception occurred:

Traceback (most recent call last):
  File "/home/pipohkr01/xcobs2/venv/bin/gunicorn", line 8, in <module>
    sys.exit(run())
             ^^^^^
  File "/home/pipohkr01/xcobs2/venv/lib/python3.11/site-packages/gunicorn/app/wsgiapp.py", line 66, in run
    WSGIApplication("%(prog)s [OPTIONS] [APP_MODULE]", prog=prog).run()
  File "/home/pipohkr01/xcobs2/venv/lib/python3.11/site-packages/gunicorn/app/base.py", line 235, in run
    super().run()
  File "/home/pipohkr01/xcobs2/venv/lib/python3.11/site-packages/gunicorn/app/base.py", line 71, in run
    Arbiter(self).run()
  File "/home/pipohkr01/xcobs2/venv/lib/python3.11/site-packages/gunicorn/arbiter.py", line 228, in run
    self.halt(reason=inst.reason, exit_status=inst.exit_status)
  File "/home/pipohkr01/xcobs2/venv/lib/python3.11/site-packages/gunicorn/arbiter.py", line 341, in halt
    self.stop()
  File "/home/pipohkr01/xcobs2/venv/lib/python3.11/site-packages/gunicorn/arbiter.py", line 395, in stop
    time.sleep(0.1)
  File "/home/pipohkr01/xcobs2/venv/lib/python3.11/site-packages/gunicorn/arbiter.py", line 241, in handle_chld
    self.reap_workers()
  File "/home/pipohkr01/xcobs2/venv/lib/python3.11/site-packages/gunicorn/arbiter.py", line 529, in reap_workers
    raise HaltServer(reason, self.WORKER_BOOT_ERROR)
gunicorn.errors.HaltServer: <HaltServer 'Worker failed to boot.' 3>
[2025-08-02 11:00:56 +0000] [196381] [INFO] Starting gunicorn 23.0.0
[2025-08-02 11:00:56 +0000] [196381] [INFO] Listening at: http://127.0.0.1:8000 (196381)
[2025-08-02 11:00:56 +0000] [196381] [INFO] Using worker: sync
[2025-08-02 11:00:56 +0000] [196382] [INFO] Booting worker with pid: 196382
[2025-08-02 11:00:56 +0000] [196383] [INFO] Booting worker with pid: 196383
[2025-08-02 11:00:56 +0000] [196384] [INFO] Booting worker with pid: 196384
[2025-08-02 11:00:56 +0000] [196385] [INFO] Booting worker with pid: 196385
[2025-08-02 11:04:42 +0000] [196381] [INFO] Handling signal: term
[2025-08-02 11:04:42 +0000] [196382] [INFO] Worker exiting (pid: 196382)
[2025-08-02 11:04:42 +0000] [196383] [INFO] Worker exiting (pid: 196383)
[2025-08-02 11:04:42 +0000] [196385] [INFO] Worker exiting (pid: 196385)
[2025-08-02 11:04:42 +0000] [196384] [INFO] Worker exiting (pid: 196384)
[2025-08-02 11:04:43 +0000] [196381] [INFO] Shutting down: Master
[2025-08-02 11:05:27 +0000] [196467] [INFO] Starting gunicorn 23.0.0
[2025-08-02 11:05:27 +0000] [196467] [INFO] Listening at: http://127.0.0.1:8000 (196467)
[2025-08-02 11:05:27 +0000] [196467] [INFO] Using worker: sync
[2025-08-02 11:05:27 +0000] [196468] [INFO] Booting worker with pid: 196468
[2025-08-02 11:05:27 +0000] [196469] [INFO] Booting worker with pid: 196469
[2025-08-02 11:05:27 +0000] [196470] [INFO] Booting worker with pid: 196470
[2025-08-02 11:05:27 +0000] [196471] [INFO] Booting worker with pid: 196471
[2025-08-02 11:06:03,696] ERROR in app: Exception on / [POST]
Traceback (most recent call last):
  File "/home/pipohkr01/xcobs2/venv/lib/python3.11/site-packages/flask/app.py", line 1511, in wsgi_app
    response = self.full_dispatch_request()
               ^^^^^^^^^^^^^^^^^^^^^^^^^^^^
  File "/home/pipohkr01/xcobs2/venv/lib/python3.11/site-packages/flask/app.py", line 919, in full_dispatch_request
    rv = self.handle_user_exception(e)
         ^^^^^^^^^^^^^^^^^^^^^^^^^^^^^
  File "/home/pipohkr01/xcobs2/venv/lib/python3.11/site-packages/flask/app.py", line 917, in full_dispatch_request
    rv = self.dispatch_request()
         ^^^^^^^^^^^^^^^^^^^^^^^
  File "/home/pipohkr01/xcobs2/venv/lib/python3.11/site-packages/flask/app.py", line 902, in dispatch_request
    return self.ensure_sync(self.view_functions[rule.endpoint])(**view_args)  # type: ignore[no-any-return]
           ^^^^^^^^^^^^^^^^^^^^^^^^^^^^^^^^^^^^^^^^^^^^^^^^^^^^^^^^^^^^^^^^^
  File "/home/pipohkr01/xcobs2/dmg_clc/app.py", line 367, in index
    intermediate = math.floor(lv * 2 / 5 + 2)
                              ^^
NameError: name 'lv' is not defined
[2025-08-02 11:06:30,505] ERROR in app: Exception on / [POST]
Traceback (most recent call last):
  File "/home/pipohkr01/xcobs2/venv/lib/python3.11/site-packages/flask/app.py", line 1511, in wsgi_app
    response = self.full_dispatch_request()
               ^^^^^^^^^^^^^^^^^^^^^^^^^^^^
  File "/home/pipohkr01/xcobs2/venv/lib/python3.11/site-packages/flask/app.py", line 919, in full_dispatch_request
    rv = self.handle_user_exception(e)
         ^^^^^^^^^^^^^^^^^^^^^^^^^^^^^
  File "/home/pipohkr01/xcobs2/venv/lib/python3.11/site-packages/flask/app.py", line 917, in full_dispatch_request
    rv = self.dispatch_request()
         ^^^^^^^^^^^^^^^^^^^^^^^
  File "/home/pipohkr01/xcobs2/venv/lib/python3.11/site-packages/flask/app.py", line 902, in dispatch_request
    return self.ensure_sync(self.view_functions[rule.endpoint])(**view_args)  # type: ignore[no-any-return]
           ^^^^^^^^^^^^^^^^^^^^^^^^^^^^^^^^^^^^^^^^^^^^^^^^^^^^^^^^^^^^^^^^^
  File "/home/pipohkr01/xcobs2/dmg_clc/app.py", line 367, in index
    intermediate = math.floor(lv * 2 / 5 + 2)
                              ^^
NameError: name 'lv' is not defined
[2025-08-02 11:07:06,229] ERROR in app: Exception on / [POST]
Traceback (most recent call last):
  File "/home/pipohkr01/xcobs2/venv/lib/python3.11/site-packages/flask/app.py", line 1511, in wsgi_app
    response = self.full_dispatch_request()
               ^^^^^^^^^^^^^^^^^^^^^^^^^^^^
  File "/home/pipohkr01/xcobs2/venv/lib/python3.11/site-packages/flask/app.py", line 919, in full_dispatch_request
    rv = self.handle_user_exception(e)
         ^^^^^^^^^^^^^^^^^^^^^^^^^^^^^
  File "/home/pipohkr01/xcobs2/venv/lib/python3.11/site-packages/flask/app.py", line 917, in full_dispatch_request
    rv = self.dispatch_request()
         ^^^^^^^^^^^^^^^^^^^^^^^
  File "/home/pipohkr01/xcobs2/venv/lib/python3.11/site-packages/flask/app.py", line 902, in dispatch_request
    return self.ensure_sync(self.view_functions[rule.endpoint])(**view_args)  # type: ignore[no-any-return]
           ^^^^^^^^^^^^^^^^^^^^^^^^^^^^^^^^^^^^^^^^^^^^^^^^^^^^^^^^^^^^^^^^^
  File "/home/pipohkr01/xcobs2/dmg_clc/app.py", line 367, in index
    intermediate = math.floor(lv * 2 / 5 + 2)
                              ^^
NameError: name 'lv' is not defined
[2025-08-02 11:07:56 +0000] [196467] [INFO] Handling signal: term
[2025-08-02 11:07:56 +0000] [196470] [INFO] Worker exiting (pid: 196470)
[2025-08-02 11:07:56 +0000] [196468] [INFO] Worker exiting (pid: 196468)
[2025-08-02 11:07:56 +0000] [196469] [INFO] Worker exiting (pid: 196469)
100 31 252 70 50 さみしがり
155 125 31 252 70 50 さみしがり
みず みず None あく じめん
False False
ノーマル ノーマル
1.1 1.0 0.9 1.0
262 167.20000000000002 202.0 159.3 132.0
100 31 252 70 50 さみしがり
155 125 31 252 70 50 さみしがり
みず みず None あく じめん
False False
ノーマル ノーマル
1.1 1.0 0.9 1.0
262 167.20000000000002 202.0 159.3 132.0
[2025-08-02 11:07:56 +0000] [196471] [INFO] Worker exiting (pid: 196471)
100 31 252 0 0 さみしがり
155 125 31 252 0 0 さみしがり
ノーマル みず None あく じめん
False False
ノーマル ノーマル
1.1 1.0 0.9 1.0
10 5.5 5.0 4.5 5.0
[2025-08-02 11:07:57 +0000] [196467] [INFO] Shutting down: Master
[2025-08-02 11:11:12 +0000] [197172] [INFO] Starting gunicorn 23.0.0
[2025-08-02 11:11:12 +0000] [197172] [INFO] Listening at: http://127.0.0.1:8000 (197172)
[2025-08-02 11:11:12 +0000] [197172] [INFO] Using worker: sync
[2025-08-02 11:11:12 +0000] [197173] [INFO] Booting worker with pid: 197173
[2025-08-02 11:11:12 +0000] [197174] [INFO] Booting worker with pid: 197174
[2025-08-02 11:11:12 +0000] [197175] [INFO] Booting worker with pid: 197175
[2025-08-02 11:11:12 +0000] [197176] [INFO] Booting worker with pid: 197176
[2025-08-02 11:26:02 +0000] [197172] [INFO] Handling signal: term
[2025-08-02 11:26:02 +0000] [197176] [INFO] Worker exiting (pid: 197176)
[2025-08-02 11:26:02 +0000] [197174] [INFO] Worker exiting (pid: 197174)
100 31 252 0 0 さみしがり
155 125 31 252 0 0 さみしがり
ノーマル みず None あく じめん
False False
ノーマル ノーマル
1.1 1.0 0.9 1.0
10 5.5 5.0 4.5 5.0
2
1
フィールド補正:1.0
1
攻撃補正
防御補正
天候補正:1
タイプ一致1.0
タイプ相性補正: 1.0
基本ダメージ
2 1 5 4
あれ
2
ダメ計終了
10 5.5 5.0 4.5 5.0
155
[2025-08-02 11:26:02 +0000] [197175] [INFO] Worker exiting (pid: 197175)
100 31 252 70 50 さみしがり
155 125 31 252 70 50 さみしがり
みず みず None あく じめん
False False
ノーマル ノーマル
1.1 1.0 0.9 1.0
262 167.20000000000002 202.0 159.3 132.0
30
130
フィールド補正:1.0
130
攻撃補正
防御補正
天候補正:1
タイプ一致
タイプ一致1.5
タイプ相性補正: 2.0
基本ダメージ
30 130 167 159
あれ
248
ダメ計終了
262 167.20000000000002 202.0 159.3 132.0
155
[2025-08-02 11:26:02 +0000] [197173] [INFO] Worker exiting (pid: 197173)
[2025-08-02 11:26:03 +0000] [197172] [INFO] Shutting down: Master
[2025-08-02 14:05:52 +0000] [208967] [INFO] Starting gunicorn 23.0.0
[2025-08-02 14:05:52 +0000] [208967] [INFO] Listening at: http://127.0.0.1:8000 (208967)
[2025-08-02 14:05:52 +0000] [208967] [INFO] Using worker: sync
[2025-08-02 14:05:52 +0000] [208968] [INFO] Booting worker with pid: 208968
[2025-08-02 14:05:52 +0000] [208969] [INFO] Booting worker with pid: 208969
[2025-08-02 14:05:52 +0000] [208970] [INFO] Booting worker with pid: 208970
[2025-08-02 14:05:52 +0000] [208971] [INFO] Booting worker with pid: 208971
[2025-08-02 14:09:14 +0000] [208996] [INFO] Starting gunicorn 23.0.0
[2025-08-02 14:09:14 +0000] [208996] [ERROR] Connection in use: ('127.0.0.1', 8000)
[2025-08-02 14:09:14 +0000] [208996] [ERROR] connection to ('127.0.0.1', 8000) failed: [Errno 98] Address already in use
[2025-08-02 14:09:15 +0000] [208996] [ERROR] Connection in use: ('127.0.0.1', 8000)
[2025-08-02 14:09:15 +0000] [208996] [ERROR] connection to ('127.0.0.1', 8000) failed: [Errno 98] Address already in use
[2025-08-02 14:09:16 +0000] [208996] [ERROR] Connection in use: ('127.0.0.1', 8000)
[2025-08-02 14:09:16 +0000] [208996] [ERROR] connection to ('127.0.0.1', 8000) failed: [Errno 98] Address already in use
[2025-08-02 14:09:17 +0000] [208996] [ERROR] Connection in use: ('127.0.0.1', 8000)
[2025-08-02 14:09:17 +0000] [208996] [ERROR] connection to ('127.0.0.1', 8000) failed: [Errno 98] Address already in use
[2025-08-02 14:09:18 +0000] [208996] [ERROR] Connection in use: ('127.0.0.1', 8000)
[2025-08-02 14:09:18 +0000] [208996] [ERROR] connection to ('127.0.0.1', 8000) failed: [Errno 98] Address already in use
[2025-08-02 14:09:19 +0000] [208996] [ERROR] Can't connect to ('127.0.0.1', 8000)
[2025-08-02 14:14:39 +0000] [209667] [INFO] Starting gunicorn 23.0.0
[2025-08-02 14:14:39 +0000] [209667] [ERROR] Connection in use: ('127.0.0.1', 8000)
[2025-08-02 14:14:39 +0000] [209667] [ERROR] connection to ('127.0.0.1', 8000) failed: [Errno 98] Address already in use
[2025-08-02 14:14:40 +0000] [209667] [ERROR] Connection in use: ('127.0.0.1', 8000)
[2025-08-02 14:14:40 +0000] [209667] [ERROR] connection to ('127.0.0.1', 8000) failed: [Errno 98] Address already in use
[2025-08-02 14:14:41 +0000] [209667] [ERROR] Connection in use: ('127.0.0.1', 8000)
[2025-08-02 14:14:41 +0000] [209667] [ERROR] connection to ('127.0.0.1', 8000) failed: [Errno 98] Address already in use
[2025-08-02 14:14:42 +0000] [209667] [ERROR] Connection in use: ('127.0.0.1', 8000)
[2025-08-02 14:14:42 +0000] [209667] [ERROR] connection to ('127.0.0.1', 8000) failed: [Errno 98] Address already in use
[2025-08-02 14:14:43 +0000] [209667] [ERROR] Connection in use: ('127.0.0.1', 8000)
[2025-08-02 14:14:43 +0000] [209667] [ERROR] connection to ('127.0.0.1', 8000) failed: [Errno 98] Address already in use
[2025-08-02 14:14:44 +0000] [209667] [ERROR] Can't connect to ('127.0.0.1', 8000)
[2025-08-02 14:19:12 +0000] [208967] [INFO] Handling signal: term
[2025-08-02 14:19:12 +0000] [208968] [INFO] Worker exiting (pid: 208968)
[2025-08-02 14:19:12 +0000] [208969] [INFO] Worker exiting (pid: 208969)
120 31 252 0 0 さみしがり
30 30 31 252 0 0 さみしがり
はがね ノーマル ひこう ゴースト どく
False False
ノーマル ノーマル
1.1 1.0 0.9 1.0
10 5.5 5.0 4.5 5.0
2
0
フィールド補正:1.0
0
攻撃補正
防御補正
天候補正:1
タイプ一致1.0
ここにはいる？
('ノーマル', 0.0, 1.0)
タイプ相性補正: 1.0
基本ダメージ
2 0 5 4
あれ
2
ダメ計終了
10 5.5 5.0 4.5 5.0
30
[2025-08-02 14:19:12 +0000] [208970] [INFO] Worker exiting (pid: 208970)
[2025-08-02 14:19:12 +0000] [208971] [INFO] Worker exiting (pid: 208971)
[2025-08-02 14:19:13 +0000] [208967] [INFO] Shutting down: Master
[2025-08-02 15:15:15 +0000] [214346] [INFO] Starting gunicorn 23.0.0
[2025-08-02 15:15:15 +0000] [214346] [INFO] Listening at: http://127.0.0.1:8000 (214346)
[2025-08-02 15:15:15 +0000] [214346] [INFO] Using worker: sync
[2025-08-02 15:15:15 +0000] [214347] [INFO] Booting worker with pid: 214347
[2025-08-02 15:15:15 +0000] [214348] [INFO] Booting worker with pid: 214348
[2025-08-02 15:15:15 +0000] [214349] [INFO] Booting worker with pid: 214349
[2025-08-02 15:15:15 +0000] [214350] [INFO] Booting worker with pid: 214350
[2025-08-02 15:24:34,215] ERROR in app: Exception on / [POST]
Traceback (most recent call last):
  File "/home/pipohkr01/xcobs2/venv/lib/python3.11/site-packages/flask/app.py", line 1511, in wsgi_app
    response = self.full_dispatch_request()
               ^^^^^^^^^^^^^^^^^^^^^^^^^^^^
  File "/home/pipohkr01/xcobs2/venv/lib/python3.11/site-packages/flask/app.py", line 919, in full_dispatch_request
    rv = self.handle_user_exception(e)
         ^^^^^^^^^^^^^^^^^^^^^^^^^^^^^
  File "/home/pipohkr01/xcobs2/venv/lib/python3.11/site-packages/flask/app.py", line 917, in full_dispatch_request
    rv = self.dispatch_request()
         ^^^^^^^^^^^^^^^^^^^^^^^
  File "/home/pipohkr01/xcobs2/venv/lib/python3.11/site-packages/flask/app.py", line 902, in dispatch_request
    return self.ensure_sync(self.view_functions[rule.endpoint])(**view_args)  # type: ignore[no-any-return]
           ^^^^^^^^^^^^^^^^^^^^^^^^^^^^^^^^^^^^^^^^^^^^^^^^^^^^^^^^^^^^^^^^^
  File "/home/pipohkr01/xcobs2/dmg_clc/app.py", line 571, in index
    cusor.execute("SELECT attacker FROM type_chart")
    ^^^^^
NameError: name 'cusor' is not defined
[2025-08-02 15:24:36,693] ERROR in app: Exception on / [POST]
Traceback (most recent call last):
  File "/home/pipohkr01/xcobs2/venv/lib/python3.11/site-packages/flask/app.py", line 1511, in wsgi_app
    response = self.full_dispatch_request()
               ^^^^^^^^^^^^^^^^^^^^^^^^^^^^
  File "/home/pipohkr01/xcobs2/venv/lib/python3.11/site-packages/flask/app.py", line 919, in full_dispatch_request
    rv = self.handle_user_exception(e)
         ^^^^^^^^^^^^^^^^^^^^^^^^^^^^^
  File "/home/pipohkr01/xcobs2/venv/lib/python3.11/site-packages/flask/app.py", line 917, in full_dispatch_request
    rv = self.dispatch_request()
         ^^^^^^^^^^^^^^^^^^^^^^^
  File "/home/pipohkr01/xcobs2/venv/lib/python3.11/site-packages/flask/app.py", line 902, in dispatch_request
    return self.ensure_sync(self.view_functions[rule.endpoint])(**view_args)  # type: ignore[no-any-return]
           ^^^^^^^^^^^^^^^^^^^^^^^^^^^^^^^^^^^^^^^^^^^^^^^^^^^^^^^^^^^^^^^^^
  File "/home/pipohkr01/xcobs2/dmg_clc/app.py", line 571, in index
    cusor.execute("SELECT attacker FROM type_chart")
    ^^^^^
NameError: name 'cusor' is not defined
[2025-08-02 15:24:44,705] ERROR in app: Exception on / [POST]
Traceback (most recent call last):
  File "/home/pipohkr01/xcobs2/venv/lib/python3.11/site-packages/flask/app.py", line 1511, in wsgi_app
    response = self.full_dispatch_request()
               ^^^^^^^^^^^^^^^^^^^^^^^^^^^^
  File "/home/pipohkr01/xcobs2/venv/lib/python3.11/site-packages/flask/app.py", line 919, in full_dispatch_request
    rv = self.handle_user_exception(e)
         ^^^^^^^^^^^^^^^^^^^^^^^^^^^^^
  File "/home/pipohkr01/xcobs2/venv/lib/python3.11/site-packages/flask/app.py", line 917, in full_dispatch_request
    rv = self.dispatch_request()
         ^^^^^^^^^^^^^^^^^^^^^^^
  File "/home/pipohkr01/xcobs2/venv/lib/python3.11/site-packages/flask/app.py", line 902, in dispatch_request
    return self.ensure_sync(self.view_functions[rule.endpoint])(**view_args)  # type: ignore[no-any-return]
           ^^^^^^^^^^^^^^^^^^^^^^^^^^^^^^^^^^^^^^^^^^^^^^^^^^^^^^^^^^^^^^^^^
  File "/home/pipohkr01/xcobs2/dmg_clc/app.py", line 571, in index
    cusor.execute("SELECT attacker FROM type_chart")
    ^^^^^
NameError: name 'cusor' is not defined
[2025-08-02 15:24:51,598] ERROR in app: Exception on / [POST]
Traceback (most recent call last):
  File "/home/pipohkr01/xcobs2/venv/lib/python3.11/site-packages/flask/app.py", line 1511, in wsgi_app
    response = self.full_dispatch_request()
               ^^^^^^^^^^^^^^^^^^^^^^^^^^^^
  File "/home/pipohkr01/xcobs2/venv/lib/python3.11/site-packages/flask/app.py", line 919, in full_dispatch_request
    rv = self.handle_user_exception(e)
         ^^^^^^^^^^^^^^^^^^^^^^^^^^^^^
  File "/home/pipohkr01/xcobs2/venv/lib/python3.11/site-packages/flask/app.py", line 917, in full_dispatch_request
    rv = self.dispatch_request()
         ^^^^^^^^^^^^^^^^^^^^^^^
  File "/home/pipohkr01/xcobs2/venv/lib/python3.11/site-packages/flask/app.py", line 902, in dispatch_request
    return self.ensure_sync(self.view_functions[rule.endpoint])(**view_args)  # type: ignore[no-any-return]
           ^^^^^^^^^^^^^^^^^^^^^^^^^^^^^^^^^^^^^^^^^^^^^^^^^^^^^^^^^^^^^^^^^
  File "/home/pipohkr01/xcobs2/dmg_clc/app.py", line 571, in index
    cusor.execute("SELECT attacker FROM type_chart")
    ^^^^^
NameError: name 'cusor' is not defined
[2025-08-02 15:25:30,512] ERROR in app: Exception on / [POST]
Traceback (most recent call last):
  File "/home/pipohkr01/xcobs2/venv/lib/python3.11/site-packages/flask/app.py", line 1511, in wsgi_app
    response = self.full_dispatch_request()
               ^^^^^^^^^^^^^^^^^^^^^^^^^^^^
  File "/home/pipohkr01/xcobs2/venv/lib/python3.11/site-packages/flask/app.py", line 919, in full_dispatch_request
    rv = self.handle_user_exception(e)
         ^^^^^^^^^^^^^^^^^^^^^^^^^^^^^
  File "/home/pipohkr01/xcobs2/venv/lib/python3.11/site-packages/flask/app.py", line 917, in full_dispatch_request
    rv = self.dispatch_request()
         ^^^^^^^^^^^^^^^^^^^^^^^
  File "/home/pipohkr01/xcobs2/venv/lib/python3.11/site-packages/flask/app.py", line 902, in dispatch_request
    return self.ensure_sync(self.view_functions[rule.endpoint])(**view_args)  # type: ignore[no-any-return]
           ^^^^^^^^^^^^^^^^^^^^^^^^^^^^^^^^^^^^^^^^^^^^^^^^^^^^^^^^^^^^^^^^^
  File "/home/pipohkr01/xcobs2/dmg_clc/app.py", line 571, in index
    cusor.execute("SELECT attacker FROM type_chart")
    ^^^^^
NameError: name 'cusor' is not defined
[2025-08-02 15:25:37,774] ERROR in app: Exception on / [POST]
Traceback (most recent call last):
  File "/home/pipohkr01/xcobs2/venv/lib/python3.11/site-packages/flask/app.py", line 1511, in wsgi_app
    response = self.full_dispatch_request()
               ^^^^^^^^^^^^^^^^^^^^^^^^^^^^
  File "/home/pipohkr01/xcobs2/venv/lib/python3.11/site-packages/flask/app.py", line 919, in full_dispatch_request
    rv = self.handle_user_exception(e)
         ^^^^^^^^^^^^^^^^^^^^^^^^^^^^^
  File "/home/pipohkr01/xcobs2/venv/lib/python3.11/site-packages/flask/app.py", line 917, in full_dispatch_request
    rv = self.dispatch_request()
         ^^^^^^^^^^^^^^^^^^^^^^^
  File "/home/pipohkr01/xcobs2/venv/lib/python3.11/site-packages/flask/app.py", line 902, in dispatch_request
    return self.ensure_sync(self.view_functions[rule.endpoint])(**view_args)  # type: ignore[no-any-return]
           ^^^^^^^^^^^^^^^^^^^^^^^^^^^^^^^^^^^^^^^^^^^^^^^^^^^^^^^^^^^^^^^^^
  File "/home/pipohkr01/xcobs2/dmg_clc/app.py", line 571, in index
    cusor.execute("SELECT attacker FROM type_chart")
    ^^^^^
NameError: name 'cusor' is not defined
[2025-08-02 15:25:39,908] ERROR in app: Exception on / [POST]
Traceback (most recent call last):
  File "/home/pipohkr01/xcobs2/venv/lib/python3.11/site-packages/flask/app.py", line 1511, in wsgi_app
    response = self.full_dispatch_request()
               ^^^^^^^^^^^^^^^^^^^^^^^^^^^^
  File "/home/pipohkr01/xcobs2/venv/lib/python3.11/site-packages/flask/app.py", line 919, in full_dispatch_request
    rv = self.handle_user_exception(e)
         ^^^^^^^^^^^^^^^^^^^^^^^^^^^^^
  File "/home/pipohkr01/xcobs2/venv/lib/python3.11/site-packages/flask/app.py", line 917, in full_dispatch_request
    rv = self.dispatch_request()
         ^^^^^^^^^^^^^^^^^^^^^^^
  File "/home/pipohkr01/xcobs2/venv/lib/python3.11/site-packages/flask/app.py", line 902, in dispatch_request
    return self.ensure_sync(self.view_functions[rule.endpoint])(**view_args)  # type: ignore[no-any-return]
           ^^^^^^^^^^^^^^^^^^^^^^^^^^^^^^^^^^^^^^^^^^^^^^^^^^^^^^^^^^^^^^^^^
  File "/home/pipohkr01/xcobs2/dmg_clc/app.py", line 571, in index
    cusor.execute("SELECT attacker FROM type_chart")
    ^^^^^
NameError: name 'cusor' is not defined
[2025-08-02 15:25:48,359] ERROR in app: Exception on / [POST]
Traceback (most recent call last):
  File "/home/pipohkr01/xcobs2/venv/lib/python3.11/site-packages/flask/app.py", line 1511, in wsgi_app
    response = self.full_dispatch_request()
               ^^^^^^^^^^^^^^^^^^^^^^^^^^^^
  File "/home/pipohkr01/xcobs2/venv/lib/python3.11/site-packages/flask/app.py", line 919, in full_dispatch_request
    rv = self.handle_user_exception(e)
         ^^^^^^^^^^^^^^^^^^^^^^^^^^^^^
  File "/home/pipohkr01/xcobs2/venv/lib/python3.11/site-packages/flask/app.py", line 917, in full_dispatch_request
    rv = self.dispatch_request()
         ^^^^^^^^^^^^^^^^^^^^^^^
  File "/home/pipohkr01/xcobs2/venv/lib/python3.11/site-packages/flask/app.py", line 902, in dispatch_request
    return self.ensure_sync(self.view_functions[rule.endpoint])(**view_args)  # type: ignore[no-any-return]
           ^^^^^^^^^^^^^^^^^^^^^^^^^^^^^^^^^^^^^^^^^^^^^^^^^^^^^^^^^^^^^^^^^
  File "/home/pipohkr01/xcobs2/dmg_clc/app.py", line 571, in index
    cusor.execute("SELECT attacker FROM type_chart")
    ^^^^^
NameError: name 'cusor' is not defined
[2025-08-02 15:26:03,002] ERROR in app: Exception on / [POST]
Traceback (most recent call last):
  File "/home/pipohkr01/xcobs2/venv/lib/python3.11/site-packages/flask/app.py", line 1511, in wsgi_app
    response = self.full_dispatch_request()
               ^^^^^^^^^^^^^^^^^^^^^^^^^^^^
  File "/home/pipohkr01/xcobs2/venv/lib/python3.11/site-packages/flask/app.py", line 919, in full_dispatch_request
    rv = self.handle_user_exception(e)
         ^^^^^^^^^^^^^^^^^^^^^^^^^^^^^
  File "/home/pipohkr01/xcobs2/venv/lib/python3.11/site-packages/flask/app.py", line 917, in full_dispatch_request
    rv = self.dispatch_request()
         ^^^^^^^^^^^^^^^^^^^^^^^
  File "/home/pipohkr01/xcobs2/venv/lib/python3.11/site-packages/flask/app.py", line 902, in dispatch_request
    return self.ensure_sync(self.view_functions[rule.endpoint])(**view_args)  # type: ignore[no-any-return]
           ^^^^^^^^^^^^^^^^^^^^^^^^^^^^^^^^^^^^^^^^^^^^^^^^^^^^^^^^^^^^^^^^^
  File "/home/pipohkr01/xcobs2/dmg_clc/app.py", line 571, in index
    cusor.execute("SELECT attacker FROM type_chart")
    ^^^^^
NameError: name 'cusor' is not defined
[2025-08-02 15:26:06,115] ERROR in app: Exception on / [POST]
Traceback (most recent call last):
  File "/home/pipohkr01/xcobs2/venv/lib/python3.11/site-packages/flask/app.py", line 1511, in wsgi_app
    response = self.full_dispatch_request()
               ^^^^^^^^^^^^^^^^^^^^^^^^^^^^
  File "/home/pipohkr01/xcobs2/venv/lib/python3.11/site-packages/flask/app.py", line 919, in full_dispatch_request
    rv = self.handle_user_exception(e)
         ^^^^^^^^^^^^^^^^^^^^^^^^^^^^^
  File "/home/pipohkr01/xcobs2/venv/lib/python3.11/site-packages/flask/app.py", line 917, in full_dispatch_request
    rv = self.dispatch_request()
         ^^^^^^^^^^^^^^^^^^^^^^^
  File "/home/pipohkr01/xcobs2/venv/lib/python3.11/site-packages/flask/app.py", line 902, in dispatch_request
    return self.ensure_sync(self.view_functions[rule.endpoint])(**view_args)  # type: ignore[no-any-return]
           ^^^^^^^^^^^^^^^^^^^^^^^^^^^^^^^^^^^^^^^^^^^^^^^^^^^^^^^^^^^^^^^^^
  File "/home/pipohkr01/xcobs2/dmg_clc/app.py", line 571, in index
    cusor.execute("SELECT attacker FROM type_chart")
    ^^^^^
NameError: name 'cusor' is not defined
[2025-08-02 15:26:08,322] ERROR in app: Exception on / [POST]
Traceback (most recent call last):
  File "/home/pipohkr01/xcobs2/venv/lib/python3.11/site-packages/flask/app.py", line 1511, in wsgi_app
    response = self.full_dispatch_request()
               ^^^^^^^^^^^^^^^^^^^^^^^^^^^^
  File "/home/pipohkr01/xcobs2/venv/lib/python3.11/site-packages/flask/app.py", line 919, in full_dispatch_request
    rv = self.handle_user_exception(e)
         ^^^^^^^^^^^^^^^^^^^^^^^^^^^^^
  File "/home/pipohkr01/xcobs2/venv/lib/python3.11/site-packages/flask/app.py", line 917, in full_dispatch_request
    rv = self.dispatch_request()
         ^^^^^^^^^^^^^^^^^^^^^^^
  File "/home/pipohkr01/xcobs2/venv/lib/python3.11/site-packages/flask/app.py", line 902, in dispatch_request
    return self.ensure_sync(self.view_functions[rule.endpoint])(**view_args)  # type: ignore[no-any-return]
           ^^^^^^^^^^^^^^^^^^^^^^^^^^^^^^^^^^^^^^^^^^^^^^^^^^^^^^^^^^^^^^^^^
  File "/home/pipohkr01/xcobs2/dmg_clc/app.py", line 571, in index
    cusor.execute("SELECT attacker FROM type_chart")
    ^^^^^
NameError: name 'cusor' is not defined
[2025-08-02 15:27:21 +0000] [214346] [INFO] Handling signal: term
[2025-08-02 15:27:21 +0000] [214347] [INFO] Worker exiting (pid: 214347)
[2025-08-02 15:27:21 +0000] [214348] [INFO] Worker exiting (pid: 214348)
100 31 252 0 0 さみしがり
155 125 31 252 0 0 さみしがり
みず みず None あく じめん
False False
ノーマル ノーマル
1.1 1.0 0.9 1.0
10 5.5 5.0 4.5 5.0
2
130
フィールド補正:1.0
130
攻撃補正
防御補正
天候補正:1
タイプ一致
タイプ一致1.5
ここにはいる？
('ノーマル', 1.0, 1.0)
タイプ相性補正: 2.0
基本ダメージ
2 130 5 4
あれ
24
ダメ計終了
10 5.5 5.0 4.5 5.0
155
100 31 252 0 0 さみしがり
155 125 31 252 0 0 さみしがり
ノーマル みず None あく じめん
False True
ノーマル じめん
1.1 1.0 0.9 1.0
10 5.5 5.0 4.5 5.0
2
130
フィールド補正:1.0
130
攻撃補正
防御補正
天候補正:1
タイプ一致1.0
ここにはいる？
('ノーマル', 1.0, 1.0)
防御側テラス
100 31 252 0 0 さみしがり
155 125 31 252 0 0 さみしがり
みず みず None あく じめん
False False
ノーマル ノーマル
1.1 1.0 0.9 1.0
10 5.5 5.0 4.5 5.0
2
130
フィールド補正:1.0
130
攻撃補正
防御補正
天候補正:1
タイプ一致
タイプ一致1.5
ここにはいる？
('ノーマル', 1.0, 1.0)
タイプ相性補正: 2.0
基本ダメージ
2 130 5 4
あれ
24
ダメ計終了
10 5.5 5.0 4.5 5.0
155
100 31 252 0 0 さみしがり
155 125 31 252 0 0 さみしがり
ノーマル みず None あく じめん
False True
ノーマル ゴースト
1.1 1.0 0.9 1.0
10 5.5 5.0 4.5 5.0
2
130
フィールド補正:1.0
130
攻撃補正
防御補正
天候補正:1
タイプ一致1.0
ここにはいる？
('ノーマル', 1.0, 1.0)
防御側テラス
100 31 252 0 0 さみしがり
155 125 31 252 0 0 さみしがり
むし みず None あく じめん
False True
ノーマル ノーマル
1.1 1.0 0.9 1.0
10 5.5 5.0 4.5 5.0
2
130
フィールド補正:1.0
130
攻撃補正
防御補正
天候補正:1
タイプ一致1.0
ここにはいる？
('ノーマル', 1.0, 1.0)
防御側テラス
100 31 252 0 0 さみしがり
155 125 31 252 0 0 さみしがり
むし みず None あく じめん
False True
ノーマル ノーマル
1.1 1.0 0.9 1.0
10 5.5 5.0 4.5 5.0
2
0
フィールド補正:1.0
0
攻撃補正
防御補正
天候補正:1
タイプ一致1.0
ここにはいる？
('ノーマル', 1.0, 1.0)
防御側テラス
100 31 252 0 0 さみしがり
155 125 31 252 0 0 さみしがり
むし みず None あく じめん
False True
ノーマル ノーマル
1.1 1.0 0.9 1.0
10 5.5 5.0 4.5 5.0
2
0
フィールド補正:1.0
0
攻撃補正
防御補正
天候補正:1
タイプ一致1.0
ここにはいる？
('ノーマル', 1.0, 1.0)
防御側テラス
100 31 252 0 0 さみしがり
155 125 31 252 0 0 さみしがり
むし みず None あく じめん
False True
ノーマル ノーマル
1.1 1.0 0.9 1.0
10 5.5 5.0 4.5 5.0
2
0
フィールド補正:1.0
0
攻撃補正
防御補正
天候補正:1
タイプ一致1.0
ここにはいる？
('ノーマル', 1.0, 1.0)
防御側テラス
[2025-08-02 15:27:21 +0000] [214349] [INFO] Worker exiting (pid: 214349)
100 31 252 0 0 さみしがり
155 125 31 252 0 0 さみしがり
むし みず None あく じめん
False False
こおり ノーマル
1.1 1.0 0.9 1.0
10 5.5 5.0 4.5 5.0
2
0
フィールド補正:1.0
0
攻撃補正
防御補正
天候補正:1
タイプ一致1.0
ここにはいる？
('ノーマル', 1.0, 1.0)
タイプ相性補正: 2.0
基本ダメージ
2 0 5 4
あれ
4
ダメ計終了
10 5.5 5.0 4.5 5.0
155
100 31 252 50 70 さみしがり
155 125 31 252 50 70 さみしがり
みず みず None あく じめん
False False
ノーマル ノーマル
1.1 1.0 0.9 1.0
362 231.00000000000003 280.0 220.5 182.0
22
130
フィールド補正:1.0
130
攻撃補正
防御補正
天候補正:1
タイプ一致
タイプ一致1.5
ここにはいる？
('ノーマル', 1.0, 1.0)
タイプ相性補正: 2.0
基本ダメージ
22 130 280.0 182.0
ん？
270
ダメ計終了
362 231.00000000000003 280.0 220.5 182.0
155
100 31 252 0 0 さみしがり
155 125 31 252 0 0 さみしがり
ノーマル みず None あく じめん
False True
ノーマル ゴースト
1.1 1.0 0.9 1.0
10 5.5 5.0 4.5 5.0
2
130
フィールド補正:1.0
130
攻撃補正
防御補正
天候補正:1
タイプ一致1.0
ここにはいる？
('ノーマル', 1.0, 1.0)
防御側テラス
100 31 252 0 0 さみしがり
155 125 31 252 0 0 さみしがり
ノーマル みず None あく じめん
False True
ノーマル ノーマル
1.1 1.0 0.9 1.0
10 5.5 5.0 4.5 5.0
2
130
フィールド補正:1.0
130
攻撃補正
防御補正
天候補正:1
タイプ一致1.0
ここにはいる？
('ノーマル', 1.0, 1.0)
防御側テラス
100 31 252 0 0 さみしがり
155 125 31 252 0 0 さみしがり
はがね みず None あく じめん
False True
ノーマル ノーマル
1.1 1.0 0.9 1.0
10 5.5 5.0 4.5 5.0
2
130
フィールド補正:1.0
130
攻撃補正
防御補正
天候補正:1
タイプ一致1.0
ここにはいる？
('ノーマル', 1.0, 1.0)
防御側テラス
[2025-08-02 15:27:21 +0000] [214350] [INFO] Worker exiting (pid: 214350)
100 31 252 0 0 さみしがり
155 125 31 252 0 0 さみしがり
どく みず None あく じめん
False False
ノーマル ノーマル
1.1 1.0 0.9 1.0
10 5.5 5.0 4.5 5.0
2
130
フィールド補正:1.0
130
攻撃補正
防御補正
天候補正:1
タイプ一致1.0
ここにはいる？
('ノーマル', 1.0, 1.0)
タイプ相性補正: 0.5
基本ダメージ
2 130 5.0 5.0
ん？
3
ダメ計終了
10 5.5 5.0 4.5 5.0
155
100 31 252 0 0 さみしがり
155 125 31 252 0 0 さみしがり
ノーマル みず None あく じめん
False False
ノーマル ノーマル
1.1 1.0 0.9 1.0
10 5.5 5.0 4.5 5.0
2
130
フィールド補正:1.0
130
攻撃補正
防御補正
天候補正:1
タイプ一致1.0
ここにはいる？
('ノーマル', 1.0, 1.0)
タイプ相性補正: 1.0
基本ダメージ
2 130 5.0 5.0
ん？
7
ダメ計終了
10 5.5 5.0 4.5 5.0
155
100 31 252 0 0 さみしがり
155 125 31 252 0 0 さみしがり
ノーマル みず None あく じめん
False True
ノーマル ゴースト
1.1 1.0 0.9 1.0
10 5.5 5.0 4.5 5.0
2
130
フィールド補正:1.0
130
攻撃補正
防御補正
天候補正:1
タイプ一致1.0
ここにはいる？
('ノーマル', 1.0, 1.0)
防御側テラス
100 31 252 0 0 さみしがり
155 125 31 252 0 0 さみしがり
はがね みず None あく じめん
False True
ノーマル ノーマル
1.1 1.0 0.9 1.0
10 5.5 5.0 4.5 5.0
2
130
フィールド補正:1.0
130
攻撃補正
防御補正
天候補正:1
タイプ一致1.0
ここにはいる？
('ノーマル', 1.0, 1.0)
防御側テラス
[2025-08-02 15:27:22 +0000] [214346] [INFO] Shutting down: Master
[2025-08-02 15:32:55 +0000] [215914] [INFO] Starting gunicorn 23.0.0
[2025-08-02 15:32:55 +0000] [215914] [INFO] Listening at: http://127.0.0.1:8000 (215914)
[2025-08-02 15:32:55 +0000] [215914] [INFO] Using worker: sync
[2025-08-02 15:32:55 +0000] [215915] [INFO] Booting worker with pid: 215915
[2025-08-02 15:32:55 +0000] [215916] [INFO] Booting worker with pid: 215916
[2025-08-02 15:32:55 +0000] [215917] [INFO] Booting worker with pid: 215917
[2025-08-02 15:32:55 +0000] [215918] [INFO] Booting worker with pid: 215918
[2025-08-02 15:43:46 +0000] [215914] [ERROR] Worker (pid:215916) was sent SIGHUP!
[2025-08-02 15:43:46 +0000] [215914] [ERROR] Worker (pid:215915) was sent SIGHUP!
[2025-08-02 15:43:46 +0000] [215914] [ERROR] Worker (pid:215917) was sent SIGHUP!
[2025-08-02 15:43:46 +0000] [216589] [INFO] Booting worker with pid: 216589
[2025-08-02 15:43:46 +0000] [215914] [ERROR] Worker (pid:215918) was sent SIGHUP!
[2025-08-02 15:43:46 +0000] [215914] [INFO] Handling signal: hup
[2025-08-02 15:43:46 +0000] [215914] [INFO] Hang up: Master
[2025-08-02 15:43:46 +0000] [216590] [INFO] Booting worker with pid: 216590
[2025-08-02 15:43:46 +0000] [216591] [INFO] Booting worker with pid: 216591
[2025-08-02 15:43:46 +0000] [216593] [INFO] Booting worker with pid: 216593
[2025-08-02 15:43:46 +0000] [216592] [INFO] Booting worker with pid: 216592
[2025-08-02 15:43:49 +0000] [216589] [INFO] Worker exiting (pid: 216589)
[2025-08-03 08:22:06 +0000] [215914] [INFO] Handling signal: term
[2025-08-03 08:22:06 +0000] [216591] [INFO] Worker exiting (pid: 216591)
[2025-08-03 08:22:06 +0000] [216592] [INFO] Worker exiting (pid: 216592)
130 31 252 50 50 いじっぱり
60 100 31 252 50 50 ようき
はがね ドラゴン じめん いわ ひこう
False False
ノーマル ノーマル
1.1 0.9 1.0 1.0
167 200.20000000000002 118.8 152.0 152.0
22
100
フィールド補正:1.0
100
攻撃補正
防御補正
天候補正:1
タイプ一致1.0
ここにはいる？
('ノーマル', 0.5, 1.0)
タイプ相性補正: 2.0
基本ダメージ
22 100 200 152
あれ
118
ダメ計終了
167 200.20000000000002 118.8 152.0 152.0
60
[2025-08-03 08:22:06 +0000] [216590] [INFO] Worker exiting (pid: 216590)
[2025-08-03 08:22:06 +0000] [216593] [INFO] Worker exiting (pid: 216593)
130 31 252 50 50 ひかえめ
60 100 31 252 50 50 ようき
かくとう ドラゴン じめん いわ ひこう
False False
ノーマル ノーマル
0.9 1.1 1.0 1.0
167 163.8 145.20000000000002 152.0 152.0
22
100
フィールド補正:1.0
100
攻撃補正
防御補正
天候補正:1
タイプ一致1.0
ここにはいる？
('ノーマル', 0.5, 1.0)
タイプ相性補正: 1.0
基本ダメージ
22 100 164 152
あれ
49
ダメ計終了
167 163.8 145.20000000000002 152.0 152.0
60
130 31 252 50 50 わんぱく
60 100 31 252 50 50 ようき
はがね ドラゴン じめん いわ ひこう
False False
ノーマル ノーマル
1.0 0.9 1.0 1.0
167 182.0 118.8 152.0 152.0
22
100
フィールド補正:1.0
100
攻撃補正
防御補正
天候補正:1
タイプ一致1.0
ここにはいる？
('ノーマル', 0.5, 1.0)
タイプ相性補正: 2.0
基本ダメージ
22 100 182 152
あれ
108
ダメ計終了
167 182.0 118.8 152.0 152.0
60
130 31 252 0 0 いじっぱり
60 100 31 252 0 0 ようき
はがね ドラゴン じめん いわ ひこう
False False
ノーマル ノーマル
1.1 0.9 1.0 1.0
10 5.5 4.5 5.0 5.0
2
100
フィールド補正:1.0
100
攻撃補正
防御補正
天候補正:1
タイプ一致1.0
ここにはいる？
('ノーマル', 0.5, 1.0)
タイプ相性補正: 2.0
基本ダメージ
2 100 5 7
あれ
8
ダメ計終了
10 5.5 4.5 7 5.0
60
130 31 252 0 0 さみしがり
60 100 31 252 0 0 さみしがり
はがね ドラゴン じめん いわ ひこう
False False
ノーマル ノーマル
1.1 1.0 0.9 1.0
10 5.5 5.0 4.5 5.0
2
100
フィールド補正:1.0
100
攻撃補正
防御補正
天候補正:1
タイプ一致1.0
ここにはいる？
('ノーマル', 0.5, 1.0)
タイプ相性補正: 2.0
基本ダメージ
2 100 5 4
あれ
14
ダメ計終了
10 5.5 5.0 4.5 5.0
60
130 31 252 50 50 いじっぱり
60 100 31 252 50 50 ようき
はがね ドラゴン じめん いわ ひこう
False False
ノーマル ノーマル
1.1 0.9 1.0 1.0
167 200.20000000000002 118.8 152.0 152.0
22
100
フィールド補正:1.0
100
攻撃補正
防御補正
天候補正:1
タイプ一致1.0
ここにはいる？
('ノーマル', 0.5, 1.0)
タイプ相性補正: 2.0
基本ダメージ
22 100 200 228
あれ
80
ダメ計終了
167 200.20000000000002 118.8 228 152.0
60
130 31 252 50 50 いじっぱり
60 100 31 252 50 50 ようき
はがね ドラゴン じめん いわ ひこう
False False
ノーマル ノーマル
1.1 0.9 1.0 1.0
167 200.20000000000002 118.8 152.0 152.0
22
100
フィールド補正:1.0
100
攻撃補正
防御補正
天候補正:1
タイプ一致1.0
ここにはいる？
('ノーマル', 0.5, 1.0)
タイプ相性補正: 2.0
基本ダメージ
22 100 200 152
あれ
118
ダメ計終了
167 200.20000000000002 118.8 152.0 152.0
60
[2025-08-03 08:22:07 +0000] [215914] [INFO] Shutting down: Master
[2025-08-03 08:22:19 +0000] [284141] [INFO] Starting gunicorn 23.0.0
[2025-08-03 08:22:19 +0000] [284141] [INFO] Listening at: http://127.0.0.1:8000 (284141)
[2025-08-03 08:22:19 +0000] [284141] [INFO] Using worker: sync
[2025-08-03 08:22:19 +0000] [284142] [INFO] Booting worker with pid: 284142
[2025-08-03 08:22:19 +0000] [284143] [INFO] Booting worker with pid: 284143
[2025-08-03 08:22:19 +0000] [284144] [INFO] Booting worker with pid: 284144
[2025-08-03 08:22:19 +0000] [284145] [INFO] Booting worker with pid: 284145
[2025-08-03 08:50:09 +0000] [284141] [INFO] Handling signal: term
[2025-08-03 08:50:09 +0000] [284142] [INFO] Worker exiting (pid: 284142)
[2025-08-03 08:50:09 +0000] [284143] [INFO] Worker exiting (pid: 284143)
[2025-08-03 08:50:09 +0000] [284144] [INFO] Worker exiting (pid: 284144)
[2025-08-03 08:50:09 +0000] [284145] [INFO] Worker exiting (pid: 284145)
130 31 252 50 0 さみしがり
60 100 31 252 50 0 さみしがり
はがね ドラゴン じめん いわ ひこう
False False
ノーマル ノーマル
1.1 1.0 0.9 1.0
10 5.5 5.0 4.5 5.0
22
0
フィールド補正:1.0
0
攻撃補正
防御補正
天候補正:1
タイプ一致1.0
ここにはいる？
('ノーマル', 0.5, 1.0)
タイプ相性補正: 2.0
基本ダメージ
22 0 5 4
あれ
4
ダメ計終了
10 5.5 5.0 4.5 5.0
60
[2025-08-03 08:50:10 +0000] [284141] [INFO] Shutting down: Master
[2025-08-03 08:50:24 +0000] [286150] [INFO] Starting gunicorn 23.0.0
[2025-08-03 08:50:24 +0000] [286150] [INFO] Listening at: http://127.0.0.1:8000 (286150)
[2025-08-03 08:50:24 +0000] [286150] [INFO] Using worker: sync
[2025-08-03 08:50:24 +0000] [286151] [INFO] Booting worker with pid: 286151
[2025-08-03 08:50:24 +0000] [286152] [INFO] Booting worker with pid: 286152
[2025-08-03 08:50:24 +0000] [286153] [INFO] Booting worker with pid: 286153
[2025-08-03 08:50:24 +0000] [286154] [INFO] Booting worker with pid: 286154
[2025-08-03 09:16:00 +0000] [286150] [INFO] Handling signal: term
[2025-08-03 09:16:00 +0000] [286152] [INFO] Worker exiting (pid: 286152)
[2025-08-03 09:16:00 +0000] [286151] [INFO] Worker exiting (pid: 286151)
[2025-08-03 09:16:00 +0000] [286153] [INFO] Worker exiting (pid: 286153)
[2025-08-03 09:16:00 +0000] [286154] [INFO] Worker exiting (pid: 286154)
[2025-08-03 09:16:00 +0000] [286150] [INFO] Shutting down: Master
[2025-08-03 09:16:40 +0000] [287602] [INFO] Starting gunicorn 23.0.0
[2025-08-03 09:16:40 +0000] [287602] [INFO] Listening at: http://127.0.0.1:8000 (287602)
[2025-08-03 09:16:40 +0000] [287602] [INFO] Using worker: sync
[2025-08-03 09:16:40 +0000] [287603] [INFO] Booting worker with pid: 287603
[2025-08-03 09:16:40 +0000] [287604] [INFO] Booting worker with pid: 287604
[2025-08-03 09:16:40 +0000] [287605] [INFO] Booting worker with pid: 287605
[2025-08-03 09:16:40 +0000] [287606] [INFO] Booting worker with pid: 287606
[2025-08-03 09:17:19 +0000] [287602] [INFO] Handling signal: term
[2025-08-03 09:17:19 +0000] [287604] [INFO] Worker exiting (pid: 287604)
[2025-08-03 09:17:19 +0000] [287605] [INFO] Worker exiting (pid: 287605)
[2025-08-03 09:17:19 +0000] [287606] [INFO] Worker exiting (pid: 287606)
[2025-08-03 09:17:19 +0000] [287603] [INFO] Worker exiting (pid: 287603)
[2025-08-03 09:17:20 +0000] [287602] [INFO] Shutting down: Master
